Workbook
Name ______: #REF!
Name ___act2: #REF!
Name ___act3: #REF!
Name ___act4: #REF!
Name ___all22: [1]PLALL!$A$1:$BM$137
Name ___AWEW1212: #REF!
Name ___Col3: [2]Tables!$S$7
Name ___Col6: [2]Tables!$S$12
Name ___CSD3: #REF!
Name ___DAT1: #REF!
Name ___DAT10: #REF!
Name ___DAT11: #REF!
Name ___DAT12: #REF!
Name ___DAT13: #REF!
Name ___DAT14: #REF!
Name ___DAT15: #REF!
Name ___DAT16: #REF!
Name ___DAT17: #REF!
Name ___DAT2: #REF!
Name ___DAT3: #REF!
Name ___DAT4: #REF!
Name ___DAT5: #REF!
Name ___DAT6: #REF!
Name ___DAT7: #REF!
Name ___DAT8: #REF!
Name ___DAT9: #REF!
Name ___Qtr1: #REF!
Name ___wd6: [3]tables!$A$1:$B$29
Name __1211: #REF!
Name __act2: #REF!
Name __act3: #REF!
Name __act31: #REF!
Name __act4: #REF!
Name __all22: [1]PLALL!$A$1:$BM$137
Name __Col3: [2]Tables!$S$7
Name __Col6: [2]Tables!$S$12
Name __CSD3: #REF!
Name __DAT1: #REF!
Name __DAT10: #REF!
Name __DAT11: #REF!
Name __DAT110: #REF!
Name __DAT12: #REF!
Name __DAT13: #REF!
Name __DAT14: #REF!
Name __DAT15: #REF!
Name __DAT16: #REF!
Name __DAT17: #REF!
Name __DAT2: #REF!
Name __DAT3: #REF!
Name __DAT4: #REF!
Name __DAT5: #REF!
Name __DAT6: #REF!
Name __DAT7: #REF!
Name __DAT8: #REF!
Name __DAT9: #REF!
Name __Qtr1: #REF!
Name __wd6: [3]tables!$A$1:$B$29
Name _1、青岛园区布局地图: #REF!
Name _1、青岛园区布局地图1: #REF!
Name _1169渠道: #REF!

Sheet Kangatang

Sheet 3月
A1: 类别 | B1: 整机编码 | C1: 结构 | D1: 内机系列 | E1: 外机型号 | F1: 外机平台 | G1: 冷凝器 | H1: 蒸发器 | I1: 最晚发货需求 | X1: 库存 | AA1: 顺延 | AB1: 2月24日 接单 | AC1: 包销 | AD1: 需排产 | AE1: 周一 | AF1: 周二 | AG1: 周三 | AH1: 周四 | AI1: 周五 | AJ1: 周六 | AK1: 周日 | AL1: 周一 | AM1: 周二 | AN1: 周三 | AO1: 周四 | AP1: 周五 | AQ1: 周六 | AR1: 周日 | AS1: 周一 | AT1: 排产合计 | AU1: 下周 顺延 | AV1: 备注 | AW1: 生产后结余库存
X2: 期初 | Y2: 消化 | Z2: 剩余 | AE2: 46083 | AF2: 46084 | AG2: 46085 | AH2: 46086 | AI2: 46087 | AJ2: 46088 | AK2: 46089 | AL2: 46090 | AM2: 46091 | AN2: 46092 | AO2: 46093 | AP2: 46094 | AQ2: 46095 | AR2: 46096 | AS2: 46097
C3: 挂机 | X3: =SUM(X7:X86) -> 60327 | Y3: =SUM(Y7:Y86) -> 22301 | Z3: =SUM(Z7:Z86) -> 51895 | AA3: 0 | AB3: =SUM(AB7:AB86) -> 52432 | AC3: =SUM(AC7:AC86) -> 13869 | AD3: =SUM(AD7:AD86) -> 44200 | AE3: =SUM(AE7:AE86) -> 0 | AF3: =SUM(AF7:AF86) -> 20 | AG3: =SUM(AG7:AG86) -> 8355 | AH3: =SUM(AH7:AH86) -> 8699 | AI3: =SUM(AI7:AI86) -> 9668 | AJ3: =SUM(AJ7:AJ80) -> 9535 | AK3: =SUM(AK7:AK80) -> 0 | AL3: =SUM(AL7:AL80) -> 7923 | AM3: =SUM(AM7:AM80) -> 0 | AN3: =SUM(AN7:AN80) -> 0 | AO3: =SUM(AO7:AO80) -> 0 | AP3: =SUM(AP7:AP80) -> 0 | AQ3: =SUM(AQ7:AQ80) -> 0 | ... AS3: =SUM(AS7:AS80) -> 0 | AT3: =SUM(AE3:AN3) -> 44200 | AU3: =SUM(AU7:AU80) -> 0
C4: 柜机 | X4: =SUM(X87:X189) -> 39391 | Y4: =SUM(Y87:Y187) -> 12689 | Z4: =SUM(Z87:Z187) -> 47695 | AA4: 0 | AB4: =SUM(AB87:AB187) -> 27306 | AC4: =SUM(AC87:AC187) -> 21383 | AD4: =SUM(AD87:AD187) -> 36000 | AE4: =SUM(AE87:AE186) -> 0 | AF4: =SUM(AF87:AF186) -> 800 | AG4: =SUM(AG87:AG186) -> 7283 | AH4: =SUM(AH87:AH186) -> 7400 | AI4: =SUM(AI87:AI186) -> 5500 | AJ4: =SUM(AJ87:AJ186) -> 7400 | AK4: =SUM(AK87:AK186) -> 0 | AL4: =SUM(AL87:AL186) -> 7617 | AM4: =SUM(AM87:AM186) -> 0 | AN4: =SUM(AN91:AN186) -> 0 | AO4: =SUM(AO91:AO186) -> 0 | AP4: =SUM(AP91:AP186) -> 0 | AQ4: =SUM(AQ91:AQ186) -> 0 | AR4: =SUM(AR91:AR186) -> 0 | AS4: =SUM(AS91:AS186) -> 0 | AT4: =SUM(AE4:AN4) -> 36000 | AU4: =SUM(AU87:AU186) -> 0
C5: 风管机 | X5: =SUM(X263:X427) -> 0 | Y5: =SUM(Y263:Y427) -> 0 | Z5: =SUM(Z263:Z427) -> 195 | AA5: 0 | AB5: =SUM(AB263:AB427) -> 411 | AC5: =SUM(AC263:AC427) -> 195 | AD5: =SUM(AD263:AD427) -> 606 | AE5: =SUM(AE263:AE427) -> 0 | AF5: =SUM(AF263:AF427) -> 200 | AG5: =SUM(AG263:AG427) -> 182 | AH5: =SUM(AH263:AH427) -> 0 | AI5: =SUM(AI263:AI427) -> 224 | ... AS5: =SUM(AS263:AS427) -> 0 | AT5: =SUM(AE5:AN5) -> 606 | AU5: =SUM(AU263:AU427) -> 0
C6: 汇总 | I6: 46083 | J6: 46084 | K6: 46085 | L6: 46086 | M6: 46087 | N6: 46088 | O6: 46089 | P6: 46090 | Q6: 46091 | R6: 46092 | S6: 46093 | T6: 46094 | U6: 46095 | V6: 46096 | W6: 46097 | X6: =SUM(X3:X5) -> 99718 | Y6: =SUM(Y3:Y5) -> 34990 | Z6: =SUM(Z3:Z5) -> 99785 | AA6: 0 | AB6: =SUM(AB3:AB5) -> 80149 | AC6: =SUM(AC3:AC5) -> 35447 | AD6: =SUM(AD3:AD5) -> 80806 | AE6: =SUM(AE3:AE5) -> 0 | AF6: =SUM(AF3:AF5) -> 1020 | AG6: =SUM(AG3:AG5) -> 15820 | AH6: =SUM(AH3:AH5) -> 16099 | AI6: =SUM(AI3:AI5) -> 15392 | ... AL6: =SUM(AL3:AL5) -> 15540 | AM6: =SUM(AM3:AM4) -> 0 | AN6: =SUM(AN3:AN4) -> 0 | AO6: =SUM(AO3:AO4) -> 0 | AP6: =SUM(AP3:AP4) -> 0 | AQ6: =SUM(AQ3:AQ4) -> 0 | AR6: =SUM(AR3:AR4) -> 0 | AS6: =SUM(AS3:AS4) -> 0 | AT6: =SUM(AE6:AN6) -> 80806 | AU6: =SUM(AU3:AU5) -> 0 | AW6: =AE2 -> 46083 | AX6: =AF2 -> 46084 | AY6: =AG2 -> 46085 | AZ6: =AH2 -> 46086 | BA6: =AI2 -> 46087 | BB6: =AJ2 -> 46088 | BC6: =AK2 -> 46089 | BD6: =AL2 -> 46090 | ... BK6: =AS2 -> 46097
A7: 挂机 | B7: AAABTP00M | C7: KFR-35GW/01XCA83TU1套机 | D7: 大J系列 | E7: KFR-35W/0183T室外机总成 | F7: 1P(20款) | G7: φ7（21.65） | H7: φ5 | K7: 0 | L7: 0 | M7: 0 | N7: 0 | O7: 0 | P7: 0 | X7: 0 | Y7: 0 | Z7: =X7-Y7+AC7 -> 0 | AB7: 0 | AC7: 0 | AD7: =AB7-Y7+AA7+AC7 -> 0 | AT7: =SUM(AE7:AR7) -> 0 | AU7: =AD7-AT7 -> 0 | AW7: =AE7+Y7-I7 -> 0 | AX7: =AW7+AF7-J7 -> 0 | AY7: =AX7+AG7-K7 -> 0 | AZ7: =AY7+AH7-L7 -> 0 | BA7: =AZ7+AI7-M7 -> 0 | BB7: =BA7+AJ7-N7 -> 0 | BC7: =BB7+AK7-O7 -> 0 | BD7: =BC7+AL7-P7 -> 0 | BE7: =BD7+AM7-Q7 -> 0 | ... BG7: =BF7+AO7-S7 -> 0 | BH7: =AP7+AJ7-T7 -> 0 | BI7: =AQ7+AK7-U7 -> 0 | BJ7: =AR7+AL7-V7 -> 0 | BK7: =AS7+AM7-W7 -> 0
A8: 挂机 | B8: AAABTQ00M | C8: KFR-35GW/02XCA81TU1套机 | D8: 大J系列 | E8: KFR-35W/0281T室外机总成 | F8: 1P(20款) | G8: φ7（21.65） | H8: φ5 | K8: 0 | L8: 0 | M8: 0 | N8: 0 | O8: 0 | P8: 0 | X8: 0 | Y8: 0 | Z8: =X8-Y8+AC8 -> 0 | AB8: 0 | AC8: 0 | AD8: =AB8-Y8+AA8+AC8 -> 0 | AT8: =SUM(AE8:AR8) -> 0 | AU8: =AD8-AT8 -> 0 | AW8: =AE8+Y8-I8 -> 0 | AX8: =AW8+AF8-J8 -> 0 | AY8: =AX8+AG8-K8 -> 0 | AZ8: =AY8+AH8-L8 -> 0 | BA8: =AZ8+AI8-M8 -> 0 | BB8: =BA8+AJ8-N8 -> 0 | BC8: =BB8+AK8-O8 -> 0 | BD8: =BC8+AL8-P8 -> 0 | BE8: =BD8+AM8-Q8 -> 0 | ... BG8: =BF8+AO8-S8 -> 0 | BH8: =AP8+AJ8-T8 -> 0 | BI8: =AQ8+AK8-U8 -> 0 | BJ8: =AR8+AL8-V8 -> 0 | BK8: =AS8+AM8-W8 -> 0
A9: 挂机 | B9: AAC7H5001 | C9: KFR-35GW/05JTA81TU1套机 | D9: 大J系列 | E9: KFR-35W/0581T室外机总成 | F9: 1P(20款) | G9: φ7（21.65） | H9: φ7 | K9: 0 | L9: 0 | M9: 0 | N9: 0 | O9: 0 | P9: 0 | X9: 0 | Y9: 0 | Z9: =X9-Y9+AC9 -> 0 | AB9: 0 | AC9: 0 | AD9: =AB9-Y9+AA9+AC9 -> 0 | AT9: =SUM(AE9:AR9) -> 0 | AU9: =AD9-AT9 -> 0 | AW9: =AE9+Y9-I9 -> 0 | AX9: =AW9+AF9-J9 -> 0 | AY9: =AX9+AG9-K9 -> 0 | AZ9: =AY9+AH9-L9 -> 0 | BA9: =AZ9+AI9-M9 -> 0 | BB9: =BA9+AJ9-N9 -> 0 | BC9: =BB9+AK9-O9 -> 0 | BD9: =BC9+AL9-P9 -> 0 | BE9: =BD9+AM9-Q9 -> 0 | ... BG9: =BF9+AO9-S9 -> 0 | BH9: =AP9+AJ9-T9 -> 0 | BI9: =AQ9+AK9-U9 -> 0 | BJ9: =AR9+AL9-V9 -> 0 | BK9: =AS9+AM9-W9 -> 0
A10: 挂机 | B10: AAC7X2000 | C10: KFR-26GW/B0MCA81套机 | D10: 大J系列 | E10: KFR-26W/B081室外机总成 | F10: 1P(20款) | G10: φ7（21.65） | H10: φ5 | K10: 0 | L10: 0 | M10: 0 | N10: 0 | O10: 0 | P10: 1500 | X10: 1001 | Y10: 1001 | Z10: =X10-Y10+AC10 -> 0 | AB10: 2100 | AC10: 0 | AD10: =AB10-Y10+AA10+AC10 -> 1099 | AG10: 1099 | AT10: =SUM(AE10:AS10) -> 1099 | AU10: =AD10-AT10 -> 0 | AW10: =AE10+Y10-I10 -> 1001 | AX10: =AW10+AF10-J10 -> 1001 | AY10: =AX10+AG10-K10 -> 2100 | AZ10: =AY10+AH10-L10 -> 2100 | BA10: =AZ10+AI10-M10 -> 2100 | BB10: =BA10+AJ10-N10 -> 2100 | BC10: =BB10+AK10-O10 -> 2100 | BD10: =BC10+AL10-P10 -> 600 | BE10: =BD10+AM10-Q10 -> 600 | ... BK10: =BJ10+AS10-W10 -> 600
A11: 挂机 | B11: AAABTD00K | C11: KFR-35GW/B0MCA81套机 | D11: 大J系列 | E11: KFR-35W/B081室外机总成 | F11: 1P(20款) | G11: φ7（21.65） | H11: φ5 | K11: 0 | L11: 0 | M11: 0 | N11: 0 | O11: 0 | P11: 0 | X11: 1930 | Y11: 1930 | Z11: =X11-Y11+AC11 -> 1131 | AB11: 5600 | AC11: 1131 | AD11: =AB11-Y11+AA11+AC11 -> 4801 | AG11: 1500 | AH11: 2000 | AI11: 1301 | AT11: =SUM(AE11:AS11) -> 4801 | AU11: =AD11-AT11 -> 0 | AW11: =AE11+Y11-I11 -> 1930 | AX11: =AW11+AF11-J11 -> 1930 | AY11: =AX11+AG11-K11 -> 3430 | AZ11: =AY11+AH11-L11 -> 5430 | BA11: =AZ11+AI11-M11 -> 6731 | BB11: =BA11+AJ11-N11 -> 6731 | BC11: =BB11+AK11-O11 -> 6731 | BD11: =BC11+AL11-P11 -> 6731 | BE11: =BD11+AM11-Q11 -> 6731 | ... BK11: =BJ11+AS11-W11 -> 6731
A12: 挂机 | B12: AAC7U9000 | C12: KFR-35GW/A0MCG81UF套机 | D12: 大J系列 | E12: KFR-35W/A081室外机总成 | F12: 1P(20款) | G12: φ7（21.65） | H12: φ7 | K12: 0 | L12: 0 | M12: 0 | N12: 0 | O12: 0 | P12: 0 | X12: 83 | Y12: 0 | Z12: =X12-Y12+AC12 -> 83 | AB12: 400 | AC12: 0 | AD12: =AB12-Y12+AA12+AC12 -> 400 | AG12: 400 | AT12: =SUM(AE12:AR12) -> 400 | AU12: =AD12-AT12 -> 0 | AW12: =AE12+Y12-I12 -> 0 | AX12: =AW12+AF12-J12 -> 0 | AY12: =AX12+AG12-K12 -> 400 | AZ12: =AY12+AH12-L12 -> 400 | BA12: =AZ12+AI12-M12 -> 400 | BB12: =BA12+AJ12-N12 -> 400 | BC12: =BB12+AK12-O12 -> 400 | BD12: =BC12+AL12-P12 -> 400 | BE12: =BD12+AM12-Q12 -> 400 | ... BG12: =BF12+AO12-S12 -> 400 | BH12: =AP12+AJ12-T12 -> 0 | BI12: =AQ12+AK12-U12 -> 0 | BJ12: =AR12+AL12-V12 -> 0 | BK12: =AS12+AM12-W12 -> 0
A13: 挂机 | B13: AAAKYC000 | C13: KFR-35GW/20MCG82UF套机 | D13: 大J系列 | E13: KFR-35W/2082室外机总成 | F13: 1P(20款) | G13: φ7（18.186） | H13: φ7 | K13: 0 | L13: 0 | M13: 0 | N13: 0 | O13: 0 | P13: 0 | X13: 0 | Y13: 0 | Z13: =X13-Y13+AC13 -> 0 | AB13: 0 | AC13: 0 | AD13: =AB13-Y13+AA13+AC13 -> 0 | AT13: =SUM(AE13:AR13) -> 0 | AU13: =AD13-AT13 -> 0 | AW13: =AE13+Y13-I13 -> 0 | AX13: =AW13+AF13-J13 -> 0 | AY13: =AX13+AG13-K13 -> 0 | AZ13: =AY13+AH13-L13 -> 0 | BA13: =AZ13+AI13-M13 -> 0 | BB13: =BA13+AJ13-N13 -> 0 | BC13: =BB13+AK13-O13 -> 0 | BD13: =BC13+AL13-P13 -> 0 | BE13: =BD13+AM13-Q13 -> 0 | ... BG13: =BF13+AO13-S13 -> 0 | BH13: =AP13+AJ13-T13 -> 0 | BI13: =AQ13+AK13-U13 -> 0 | BJ13: =AR13+AL13-V13 -> 0 | BK13: =AS13+AM13-W13 -> 0
A14: 挂机 | B14: AACVE0Q00 | C14: KFR-35GW/A0X1A181套机 | D14: 大J系列 | E14: KFR-35W/A081室外机总成 | F14: 1P(20款) | G14: φ7（21.65） | H14: φ7 | K14: 0 | L14: 0 | M14: 0 | N14: 0 | O14: 0 | P14: 0 | X14: 0 | Y14: 0 | Z14: =X14-Y14+AC14 -> 0 | AB14: 0 | AC14: 0 | AD14: =AB14-Y14+AA14+AC14 -> 0 | AT14: =SUM(AE14:AR14) -> 0 | AU14: =AD14-AT14 -> 0 | AW14: =AE14+Y14-I14 -> 0 | AX14: =AW14+AF14-J14 -> 0 | AY14: =AX14+AG14-K14 -> 0 | AZ14: =AY14+AH14-L14 -> 0 | BA14: =AZ14+AI14-M14 -> 0 | BB14: =BA14+AJ14-N14 -> 0 | BC14: =BB14+AK14-O14 -> 0 | BD14: =BC14+AL14-P14 -> 0 | BE14: =BD14+AM14-Q14 -> 0 | ... BG14: =BF14+AO14-S14 -> 0 | BH14: =AP14+AJ14-T14 -> 0 | BI14: =AQ14+AK14-U14 -> 0 | BJ14: =AR14+AL14-V14 -> 0 | BK14: =AS14+AM14-W14 -> 0
A15: 挂机 | B15: AAAKYG000 | C15: KFR-35GW/20MCA82套机 | D15: 大J系列 | E15: KFR-35W/2082室外机总成 | F15: 1P(20款) | G15: φ7（18.186） | H15: φ7 | K15: 0 | L15: 0 | M15: 0 | N15: 0 | O15: 0 | P15: 0 | X15: 0 | Y15: 0 | Z15: =X15-Y15+AC15 -> 0 | AB15: 0 | AC15: 0 | AD15: =AB15-Y15+AA15+AC15 -> 0 | AT15: =SUM(AE15:AR15) -> 0 | AU15: =AD15-AT15 -> 0 | AW15: =AE15+Y15-I15 -> 0 | AX15: =AW15+AF15-J15 -> 0 | AY15: =AX15+AG15-K15 -> 0 | AZ15: =AY15+AH15-L15 -> 0 | BA15: =AZ15+AI15-M15 -> 0 | BB15: =BA15+AJ15-N15 -> 0 | BC15: =BB15+AK15-O15 -> 0 | BD15: =BC15+AL15-P15 -> 0 | BE15: =BD15+AM15-Q15 -> 0 | ... BG15: =BF15+AO15-S15 -> 0 | BH15: =AP15+AJ15-T15 -> 0 | BI15: =AQ15+AK15-U15 -> 0 | BJ15: =AR15+AL15-V15 -> 0 | BK15: =AS15+AM15-W15 -> 0
A16: 挂机 | B16: AA000N000 | C16: KFR-35GW/A0MCC82套机 | D16: 大J系列 | E16: KFR-35W/A082室外机总成 | F16: 1P(20款) | G16: φ7（21.65） | H16: φ5 | K16: 0 | L16: 0 | M16: 0 | N16: 0 | O16: 0 | P16: 0 | X16: 1765 | Y16: 0 | Z16: =X16-Y16+AC16 -> 1765 | AB16: 0 | AC16: 0 | AD16: =AB16-Y16+AA16+AC16 -> 0 | AT16: =SUM(AE16:AS16) -> 0 | AU16: =AD16-AT16 -> 0 | AW16: =AE16+Y16-I16 -> 0 | AX16: =AW16+AF16-J16 -> 0 | AY16: =AX16+AG16-K16 -> 0 | AZ16: =AY16+AH16-L16 -> 0 | BA16: =AZ16+AI16-M16 -> 0 | BB16: =BA16+AJ16-N16 -> 0 | BC16: =BB16+AK16-O16 -> 0 | BD16: =BC16+AL16-P16 -> 0 | BE16: =BD16+AM16-Q16 -> 0 | ... BK16: =BJ16+AS16-W16 -> 0
A17: 挂机 | B17: AAC3B0000 | C17: KFR-26GW/A1MCD81U1套机 | D17: 大J系列 | E17: KFR-26W/A181室外机总成 | F17: 1P(20款) | G17: φ7（21.65） | H17: φ5 | K17: 0 | L17: 0 | M17: 0 | N17: 0 | O17: 0 | P17: 0 | X17: 0 | Y17: 0 | Z17: =X17-Y17+AC17 -> 0 | AB17: 0 | AC17: 0 | AD17: =AB17-Y17+AA17+AC17 -> 0 | AT17: =SUM(AE17:AR17) -> 0 | AU17: =AD17-AT17 -> 0 | AW17: =AE17+Y17-I17 -> 0 | AX17: =AW17+AF17-J17 -> 0 | AY17: =AX17+AG17-K17 -> 0 | AZ17: =AY17+AH17-L17 -> 0 | BA17: =AZ17+AI17-M17 -> 0 | BB17: =BA17+AJ17-N17 -> 0 | BC17: =BB17+AK17-O17 -> 0 | BD17: =BC17+AL17-P17 -> 0 | BE17: =BD17+AM17-Q17 -> 0 | ... BG17: =BF17+AO17-S17 -> 0 | BH17: =AP17+AJ17-T17 -> 0 | BI17: =AQ17+AK17-U17 -> 0 | BJ17: =AR17+AL17-V17 -> 0 | BK17: =AS17+AM17-W17 -> 0
A18: 挂机 | B18: AAABTB002 | C18: KFR-26GW/20MCB81U1套机 | D18: 大J系列 | E18: KFR-26W/2081室外机总成 | F18: 1P(19款) | G18: φ7（21.65） | H18: φ5 | K18: 0 | L18: 0 | M18: 0 | N18: 0 | O18: 0 | P18: 0 | X18: 0 | Y18: 0 | Z18: =X18-Y18+AC18 -> 0 | AB18: 0 | AC18: 0 | AD18: =AB18-Y18+AA18+AC18 -> 0 | AT18: =SUM(AE18:AR18) -> 0 | AU18: =AD18-AT18 -> 0 | AW18: =AE18+Y18-I18 -> 0 | AX18: =AW18+AF18-J18 -> 0 | AY18: =AX18+AG18-K18 -> 0 | AZ18: =AY18+AH18-L18 -> 0 | BA18: =AZ18+AI18-M18 -> 0 | BB18: =BA18+AJ18-N18 -> 0 | BC18: =BB18+AK18-O18 -> 0 | BD18: =BC18+AL18-P18 -> 0 | BE18: =BD18+AM18-Q18 -> 0 | ... BG18: =BF18+AO18-S18 -> 0 | BH18: =AP18+AJ18-T18 -> 0 | BI18: =AQ18+AK18-U18 -> 0 | BJ18: =AR18+AL18-V18 -> 0 | BK18: =AS18+AM18-W18 -> 0
A19: 挂机 | B19: AAABTG002 | C19: KFR-35GW/20MCB81U1套机 | D19: 大J系列 | E19: KFR-35W/2081室外机总成 | F19: 1P(20款) | G19: φ7（18.186） | H19: φ5 | K19: 0 | L19: 0 | M19: 0 | N19: 0 | O19: 0 | P19: 0 | X19: 0 | Y19: 0 | Z19: =X19-Y19+AC19 -> 0 | AB19: 0 | AC19: 0 | AD19: =AB19-Y19+AA19+AC19 -> 0 | AT19: =SUM(AE19:AR19) -> 0 | AU19: =AD19-AT19 -> 0 | AW19: =AE19+Y19-I19 -> 0 | AX19: =AW19+AF19-J19 -> 0 | AY19: =AX19+AG19-K19 -> 0 | AZ19: =AY19+AH19-L19 -> 0 | BA19: =AZ19+AI19-M19 -> 0 | BB19: =BA19+AJ19-N19 -> 0 | BC19: =BB19+AK19-O19 -> 0 | BD19: =BC19+AL19-P19 -> 0 | BE19: =BD19+AM19-Q19 -> 0 | ... BG19: =BF19+AO19-S19 -> 0 | BH19: =AP19+AJ19-T19 -> 0 | BI19: =AQ19+AK19-U19 -> 0 | BJ19: =AR19+AL19-V19 -> 0 | BK19: =AS19+AM19-W19 -> 0
A20: 挂机 | B20: AAABTH00E | C20: KFR-35GW/20MCC83套机 | D20: 大J系列 | E20: KFR-35W/20C83室外机总成 | F20: 1P(20款) | G20: φ7（21.65） | H20: φ5 | K20: 0 | L20: 0 | M20: 0 | N20: 0 | O20: 277 | P20: 200 | X20: 479 | Y20: 477 | Z20: =X20-Y20+AC20 -> 2 | AB20: 477 | AC20: 0 | AD20: =AB20-Y20+AA20+AC20 -> 0 | AT20: =SUM(AE20:AR20) -> 0 | AU20: =AD20-AT20 -> 0 | AW20: =AE20+Y20-I20 -> 477 | AX20: =AW20+AF20-J20 -> 477 | AY20: =AX20+AG20-K20 -> 477 | AZ20: =AY20+AH20-L20 -> 477 | BA20: =AZ20+AI20-M20 -> 477 | BB20: =BA20+AJ20-N20 -> 477 | BC20: =BB20+AK20-O20 -> 200 | BD20: =BC20+AL20-P20 -> 0 | BE20: =BD20+AM20-Q20 -> 0 | ... BG20: =BF20+AO20-S20 -> 0 | BH20: =AP20+AJ20-T20 -> 0 | BI20: =AQ20+AK20-U20 -> 0 | BJ20: =AR20+AL20-V20 -> 0 | BK20: =AS20+AM20-W20 -> 0
A21: 挂机 | B21: AAABTX00E | C21: KFR-35GW/83@T-Xc套机 | D21: 大J系列 | E21: KFR-35W/0183T室外机总成 | F21: 1P(20款) | G21: φ7（21.65） | H21: φ5 | K21: 0 | L21: 0 | M21: 0 | N21: 0 | O21: 0 | P21: 0 | X21: 0 | Y21: 0 | Z21: =X21-Y21+AC21 -> 0 | AB21: 0 | AC21: 0 | AD21: =AB21-Y21+AA21+AC21 -> 0 | AT21: =SUM(AE21:AR21) -> 0 | AU21: =AD21-AT21 -> 0 | AW21: =AE21+Y21-I21 -> 0 | AX21: =AW21+AF21-J21 -> 0 | AY21: =AX21+AG21-K21 -> 0 | AZ21: =AY21+AH21-L21 -> 0 | BA21: =AZ21+AI21-M21 -> 0 | BB21: =BA21+AJ21-N21 -> 0 | BC21: =BB21+AK21-O21 -> 0 | BD21: =BC21+AL21-P21 -> 0 | BE21: =BD21+AM21-Q21 -> 0 | ... BG21: =BF21+AO21-S21 -> 0 | BH21: =AP21+AJ21-T21 -> 0 | BI21: =AQ21+AK21-U21 -> 0 | BJ21: =AR21+AL21-V21 -> 0 | BK21: =AS21+AM21-W21 -> 0
A22: 挂机 | B22: AAABTJ00M | C22: KFR-35GW/02FCC81XU1套机 | D22: 大J系列 | E22: KFR-35W/0281X室外机总成 | F22: 1P(20款) | G22: φ7（21.65） | H22: φ5 | K22: 0 | L22: 0 | M22: 0 | N22: 0 | O22: 0 | P22: 0 | X22: 0 | Y22: 0 | Z22: =X22-Y22+AC22 -> 0 | AB22: 0 | AC22: 0 | AD22: =AB22-Y22+AA22+AC22 -> 0 | AT22: =SUM(AE22:AR22) -> 0 | AU22: =AD22-AT22 -> 0 | AW22: =AE22+Y22-I22 -> 0 | AX22: =AW22+AF22-J22 -> 0 | AY22: =AX22+AG22-K22 -> 0 | AZ22: =AY22+AH22-L22 -> 0 | BA22: =AZ22+AI22-M22 -> 0 | BB22: =BA22+AJ22-N22 -> 0 | BC22: =BB22+AK22-O22 -> 0 | BD22: =BC22+AL22-P22 -> 0 | BE22: =BD22+AM22-Q22 -> 0 | ... BG22: =BF22+AO22-S22 -> 0 | BH22: =AP22+AJ22-T22 -> 0 | BI22: =AQ22+AK22-U22 -> 0 | BJ22: =AR22+AL22-V22 -> 0 | BK22: =AS22+AM22-W22 -> 0
A23: 挂机 | B23: AAC7H8000 | C23: KFR-35GW/B1GPA81U1(白)套机 | D23: 大J系列 | E23: KFR-35W/B181室外机总成 | F23: 1P(20款) | G23: φ7（21.65） | H23: φ5 | K23: 0 | L23: 0 | M23: 0 | N23: 0 | O23: 0 | P23: 0 | X23: 0 | Y23: 0 | Z23: =X23-Y23+AC23 -> 0 | AB23: 0 | AC23: 0 | AD23: =AB23-Y23+AA23+AC23 -> 0 | AT23: =SUM(AE23:AR23) -> 0 | AU23: =AD23-AT23 -> 0 | AW23: =AE23+Y23-I23 -> 0 | AX23: =AW23+AF23-J23 -> 0 | AY23: =AX23+AG23-K23 -> 0 | AZ23: =AY23+AH23-L23 -> 0 | BA23: =AZ23+AI23-M23 -> 0 | BB23: =BA23+AJ23-N23 -> 0 | BC23: =BB23+AK23-O23 -> 0 | BD23: =BC23+AL23-P23 -> 0 | BE23: =BD23+AM23-Q23 -> 0 | ... BG23: =BF23+AO23-S23 -> 0 | BH23: =AP23+AJ23-T23 -> 0 | BI23: =AQ23+AK23-U23 -> 0 | BJ23: =AR23+AL23-V23 -> 0 | BK23: =AS23+AM23-W23 -> 0
A24: 挂机 | B24: AAC3E8000 | C24: KFR-32GW/02XCA81TU1套机 | D24: 大J系列 | E24: KFR-32W/0281T室外机总成 | F24: 1P(20款) | G24: φ7（21.65） | H24: φ5 | K24: 0 | L24: 0 | M24: 0 | N24: 0 | O24: 0 | P24: 0 | X24: 0 | Y24: 0 | Z24: =X24-Y24+AC24 -> 0 | AB24: 0 | AC24: 0 | AD24: =AB24-Y24+AA24+AC24 -> 0 | AT24: =SUM(AE24:AR24) -> 0 | AU24: =AD24-AT24 -> 0 | AW24: =AE24+Y24-I24 -> 0 | AX24: =AW24+AF24-J24 -> 0 | AY24: =AX24+AG24-K24 -> 0 | AZ24: =AY24+AH24-L24 -> 0 | BA24: =AZ24+AI24-M24 -> 0 | BB24: =BA24+AJ24-N24 -> 0 | BC24: =BB24+AK24-O24 -> 0 | BD24: =BC24+AL24-P24 -> 0 | BE24: =BD24+AM24-Q24 -> 0 | ... BG24: =BF24+AO24-S24 -> 0 | BH24: =AP24+AJ24-T24 -> 0 | BI24: =AQ24+AK24-U24 -> 0 | BJ24: =AR24+AL24-V24 -> 0 | BK24: =AS24+AM24-W24 -> 0
A25: 挂机 | B25: AACEM2000 | C25: KFR-35GW/LXCA-1Pro套机 | D25: 大J系列 | E25: KFR-35W/34-1L | F25: 1P(20款) | K25: 0 | L25: 0 | M25: 0 | N25: 0 | O25: 0 | P25: 0 | X25: 2919 | Y25: 2919 | Z25: =X25-Y25+AC25 -> 0 | AB25: 5700 | AC25: 0 | AD25: =AB25-Y25+AA25+AC25 -> 2781 | AI25: 1500 | AJ25: 1281 | AT25: =SUM(AE25:AS25) -> 2781 | AU25: =AD25-AT25 -> 0 | AW25: =AE25+Y25-I25 -> 2919 | AX25: =AW25+AF25-J25 -> 2919 | AY25: =AX25+AG25-K25 -> 2919 | AZ25: =AY25+AH25-L25 -> 2919 | BA25: =AZ25+AI25-M25 -> 4419 | BB25: =BA25+AJ25-N25 -> 5700 | BC25: =BB25+AK25-O25 -> 5700 | BD25: =BC25+AL25-P25 -> 5700 | BE25: =BD25+AM25-Q25 -> 5700 | ... BK25: =BJ25+AS25-W25 -> 5700
A26: 挂机 | B26: AACEMA000 | C26: KFR-35GW/LCD1-1套机 | D26: 大J系列 | E26: KFR-35W/C1-1L | F26: 1P(20款) | K26: 0 | L26: 0 | M26: 0 | N26: 0 | O26: 0 | P26: 0 | X26: 355 | Y26: 0 | Z26: =X26-Y26+AC26 -> 355 | AB26: 0 | AC26: 0 | AD26: =AB26-Y26+AA26+AC26 -> 0 | AT26: =SUM(AE26:AS26) -> 0 | AU26: =AD26-AT26 -> 0 | AW26: =AE26+Y26-I26 -> 0 | AX26: =AW26+AF26-J26 -> 0 | AY26: =AX26+AG26-K26 -> 0 | AZ26: =AY26+AH26-L26 -> 0 | BA26: =AZ26+AI26-M26 -> 0 | BB26: =BA26+AJ26-N26 -> 0 | BC26: =BB26+AK26-O26 -> 0 | BD26: =BC26+AL26-P26 -> 0 | BE26: =BD26+AM26-Q26 -> 0 | ... BK26: =BJ26+AS26-W26 -> 0
A27: 挂机 | B27: AACEMB000 | C27: KFR-35GW/LCC1-1套机 | D27: 大J系列 | E27: KFR-35W/C1-1L | F27: 1P(20款) | K27: 0 | L27: 0 | M27: 0 | N27: 0 | O27: 205 | P27: 179 | X27: 1000 | Y27: 804 | Z27: =X27-Y27+AC27 -> 196 | AB27: 804 | AC27: 0 | AD27: =AB27-Y27+AA27+AC27 -> 0 | AT27: =SUM(AE27:AS27) -> 0 | AU27: =AD27-AT27 -> 0 | AW27: =AE27+Y27-I27 -> 804 | AX27: =AW27+AF27-J27 -> 804 | AY27: =AX27+AG27-K27 -> 804 | AZ27: =AY27+AH27-L27 -> 804 | BA27: =AZ27+AI27-M27 -> 804 | BB27: =BA27+AJ27-N27 -> 804 | BC27: =BB27+AK27-O27 -> 599 | BD27: =BC27+AL27-P27 -> 420 | BE27: =BD27+AM27-Q27 -> 420 | ... BK27: =BJ27+AS27-W27 -> 420
A28: 挂机 | B28: AACEMG000 | C28: KFR-35GW/LJD1-1套机 | D28: 大J系列 | E28: KFR-35W/J1-1L | F28: 1P(20款) | K28: 0 | L28: 0 | M28: 0 | N28: 150 | O28: 150 | P28: 300 | X28: 4425 | Y28: 3150 | Z28: =X28-Y28+AC28 -> 1275 | AB28: 3150 | AC28: 0 | AD28: =AB28-Y28+AA28+AC28 -> 0 | AT28: =SUM(AE28:AS28) -> 0 | AU28: =AD28-AT28 -> 0 | AW28: =AE28+Y28-I28 -> 3150 | AX28: =AW28+AF28-J28 -> 3150 | AY28: =AX28+AG28-K28 -> 3150 | AZ28: =AY28+AH28-L28 -> 3150 | BA28: =AZ28+AI28-M28 -> 3150 | BB28: =BA28+AJ28-N28 -> 3000 | BC28: =BB28+AK28-O28 -> 2850 | BD28: =BC28+AL28-P28 -> 2550 | BE28: =BD28+AM28-Q28 -> 2550 | ... BK28: =BJ28+AS28-W28 -> 2550
A29: 挂机 | B29: AACEMCQ00 | C29: KFR-35GW/LGB1-1套机 | D29: 大J系列 | E29: KFR-35W/J1-1L | F29: 1P(20款) | K29: 0 | L29: 65 | M29: 0 | N29: 0 | O29: 0 | P29: 0 | X29: 980 | Y29: 65 | Z29: =X29-Y29+AC29 -> 915 | AB29: 65 | AC29: 0 | AD29: =AB29-Y29+AA29+AC29 -> 0 | AT29: =SUM(AE29:AS29) -> 0 | AU29: =AD29-AT29 -> 0 | AW29: =AE29+Y29-I29 -> 65 | AX29: =AW29+AF29-J29 -> 65 | AY29: =AX29+AG29-K29 -> 65 | AZ29: =AY29+AH29-L29 -> 0 | BA29: =AZ29+AI29-M29 -> 0 | BB29: =BA29+AJ29-N29 -> 0 | BC29: =BB29+AK29-O29 -> 0 | BD29: =BC29+AL29-P29 -> 0 | BE29: =BD29+AM29-Q29 -> 0 | ... BK29: =BJ29+AS29-W29 -> 0
A30: 挂机 | B30: AAC8U0000 | C30: KFR-32GW/02FCC81XU1套机 | D30: B系列 | E30: KFR-32W/0281X室外机总成 | F30: 1P(20款) | G30: φ7（21.65） | H30: φ5 | K30: 0 | L30: 0 | M30: 0 | N30: 0 | O30: 0 | P30: 0 | X30: 0 | Y30: 0 | Z30: =X30-Y30+AC30 -> 0 | AB30: 0 | AC30: 0 | AD30: =AB30-Y30+AA30+AC30 -> 0 | AT30: =SUM(AE30:AR30) -> 0 | AU30: =AD30-AT30 -> 0 | AW30: =AE30+Y30-I30 -> 0 | AX30: =AW30+AF30-J30 -> 0 | AY30: =AX30+AG30-K30 -> 0 | AZ30: =AY30+AH30-L30 -> 0 | BA30: =AZ30+AI30-M30 -> 0 | BB30: =BA30+AJ30-N30 -> 0 | BC30: =BB30+AK30-O30 -> 0 | BD30: =BC30+AL30-P30 -> 0 | BE30: =BD30+AM30-Q30 -> 0 | ... BG30: =BF30+AO30-S30 -> 0 | BH30: =AP30+AJ30-T30 -> 0 | BI30: =AQ30+AK30-U30 -> 0 | BJ30: =AR30+AL30-V30 -> 0 | BK30: =AS30+AM30-W30 -> 0
A31: 挂机 | B31: AAABTG00P | C31: KFR-35GW/02KJA83U1套机 | D31: K系列 | E31: KFR-35W/0283室外机总成 | F31: 1P(20款) | G31: φ7（21.65） | H31: φ5 | K31: 0 | L31: 0 | M31: 0 | N31: 0 | O31: 0 | P31: 0 | X31: 0 | Y31: 0 | Z31: =X31-Y31+AC31 -> 0 | AB31: 0 | AC31: 0 | AD31: =AB31-Y31+AA31+AC31 -> 0 | AT31: =SUM(AE31:AR31) -> 0 | AU31: =AD31-AT31 -> 0 | AW31: =AE31+Y31-I31 -> 0 | AX31: =AW31+AF31-J31 -> 0 | AY31: =AX31+AG31-K31 -> 0 | AZ31: =AY31+AH31-L31 -> 0 | BA31: =AZ31+AI31-M31 -> 0 | BB31: =BA31+AJ31-N31 -> 0 | BC31: =BB31+AK31-O31 -> 0 | BD31: =BC31+AL31-P31 -> 0 | BE31: =BD31+AM31-Q31 -> 0 | ... BG31: =BF31+AO31-S31 -> 0 | BH31: =AP31+AJ31-T31 -> 0 | BI31: =AQ31+AK31-U31 -> 0 | BJ31: =AR31+AL31-V31 -> 0 | BK31: =AS31+AM31-W31 -> 0
A32: 挂机 | B32: AAC7H1000 | C32: KFR-35GW/B1KWA81U1套机 | D32: K系列 | E32: KFR-35W/B181室外机总成 | F32: 1P(20款) | G32: φ7（21.65） | H32: φ5 | K32: 40 | L32: 0 | M32: 0 | N32: 20 | O32: 1096 | P32: 0 | X32: 0 | Y32: 0 | Z32: =X32-Y32+AC32 -> 0 | AB32: 1156 | AC32: 0 | AD32: =AB32-Y32+AA32+AC32 -> 1156 | AG32: 1156 | AT32: =SUM(AE32:AR32) -> 1156 | AU32: =AD32-AT32 -> 0 | AW32: =AE32+Y32-I32 -> 0 | AX32: =AW32+AF32-J32 -> 0 | AY32: =AX32+AG32-K32 -> 1116 | AZ32: =AY32+AH32-L32 -> 1116 | BA32: =AZ32+AI32-M32 -> 1116 | BB32: =BA32+AJ32-N32 -> 1096 | BC32: =BB32+AK32-O32 -> 0 | BD32: =BC32+AL32-P32 -> 0 | BE32: =BD32+AM32-Q32 -> 0 | ... BG32: =BF32+AO32-S32 -> 0 | BH32: =AP32+AJ32-T32 -> 0 | BI32: =AQ32+AK32-U32 -> 0 | BJ32: =AR32+AL32-V32 -> 0 | BK32: =AS32+AM32-W32 -> 0
A33: 挂机 | B33: AAABTC00H | C33: KFR-35GW/01KBB81U1套机 | D33: K系列 | E33: KFR-35W/01B81室外机总成 | F33: 1P(20款) | G33: φ7（21.65） | H33: φ5 | K33: 0 | L33: 0 | M33: 0 | N33: 0 | O33: 0 | P33: 0 | X33: 0 | Y33: 0 | Z33: =X33-Y33+AC33 -> 0 | AB33: 0 | AC33: 0 | AD33: =AB33-Y33+AA33+AC33 -> 0 | AT33: =SUM(AE33:AR33) -> 0 | AU33: =AD33-AT33 -> 0 | AW33: =AE33+Y33-I33 -> 0 | AX33: =AW33+AF33-J33 -> 0 | AY33: =AX33+AG33-K33 -> 0 | AZ33: =AY33+AH33-L33 -> 0 | BA33: =AZ33+AI33-M33 -> 0 | BB33: =BA33+AJ33-N33 -> 0 | BC33: =BB33+AK33-O33 -> 0 | BD33: =BC33+AL33-P33 -> 0 | BE33: =BD33+AM33-Q33 -> 0 | ... BG33: =BF33+AO33-S33 -> 0 | BH33: =AP33+AJ33-T33 -> 0 | BI33: =AQ33+AK33-U33 -> 0 | BJ33: =AR33+AL33-V33 -> 0 | BK33: =AS33+AM33-W33 -> 0
A34: 挂机 | B34: AAABTA00E | C34: KFR-35GW/02KBB83U1套机 | D34: K系列 | E34: KFR-35W/0283室外机总成 | F34: 1P(20款) | G34: φ7（21.65） | H34: φ5 | K34: 0 | L34: 0 | M34: 0 | N34: 0 | O34: 0 | P34: 0 | X34: 0 | Y34: 0 | Z34: =X34-Y34+AC34 -> 0 | AB34: 0 | AC34: 0 | AD34: =AB34-Y34+AA34+AC34 -> 0 | AT34: =SUM(AE34:AR34) -> 0 | AU34: =AD34-AT34 -> 0 | AW34: =AE34+Y34-I34 -> 0 | AX34: =AW34+AF34-J34 -> 0 | AY34: =AX34+AG34-K34 -> 0 | AZ34: =AY34+AH34-L34 -> 0 | BA34: =AZ34+AI34-M34 -> 0 | BB34: =BA34+AJ34-N34 -> 0 | BC34: =BB34+AK34-O34 -> 0 | BD34: =BC34+AL34-P34 -> 0 | BE34: =BD34+AM34-Q34 -> 0 | ... BG34: =BF34+AO34-S34 -> 0 | BH34: =AP34+AJ34-T34 -> 0 | BI34: =AQ34+AK34-U34 -> 0 | BJ34: =AR34+AL34-V34 -> 0 | BK34: =AS34+AM34-W34 -> 0
A35: 挂机 | B35: AAABTY00J | C35: KFR-35GW/B1KPB81U1套机 | D35: K系列 | E35: KFR-35W/B181室外机总成 | F35: 1P(20款) | G35: φ7（21.65） | H35: φ5 | K35: 0 | L35: 0 | M35: 0 | N35: 0 | O35: 0 | P35: 0 | X35: 8 | Y35: 0 | Z35: =X35-Y35+AC35 -> 8 | AB35: 0 | AC35: 0 | AD35: =AB35-Y35+AA35+AC35 -> 0 | AT35: =SUM(AE35:AR35) -> 0 | AU35: =AD35-AT35 -> 0 | AW35: =AE35+Y35-I35 -> 0 | AX35: =AW35+AF35-J35 -> 0 | AY35: =AX35+AG35-K35 -> 0 | AZ35: =AY35+AH35-L35 -> 0 | BA35: =AZ35+AI35-M35 -> 0 | BB35: =BA35+AJ35-N35 -> 0 | BC35: =BB35+AK35-O35 -> 0 | BD35: =BC35+AL35-P35 -> 0 | BE35: =BD35+AM35-Q35 -> 0 | ... BG35: =BF35+AO35-S35 -> 0 | BH35: =AP35+AJ35-T35 -> 0 | BI35: =AQ35+AK35-U35 -> 0 | BJ35: =AR35+AL35-V35 -> 0 | BK35: =AS35+AM35-W35 -> 0
A36: 挂机 | B36: AAABTU00M | C36: KFR-26GW/B1KPB81U1套机 | D36: K系列 | E36: KFR-26W/B181室外机总成 | F36: 1P(20款) | G36: φ7（21.65） | H36: φ5 | K36: 0 | L36: 0 | M36: 0 | N36: 0 | O36: 0 | P36: 0 | X36: 0 | Y36: 0 | Z36: =X36-Y36+AC36 -> 0 | AB36: 0 | AC36: 0 | AD36: =AB36-Y36+AA36+AC36 -> 0 | AT36: =SUM(AE36:AR36) -> 0 | AU36: =AD36-AT36 -> 0 | AW36: =AE36+Y36-I36 -> 0 | AX36: =AW36+AF36-J36 -> 0 | AY36: =AX36+AG36-K36 -> 0 | AZ36: =AY36+AH36-L36 -> 0 | BA36: =AZ36+AI36-M36 -> 0 | BB36: =BA36+AJ36-N36 -> 0 | BC36: =BB36+AK36-O36 -> 0 | BD36: =BC36+AL36-P36 -> 0 | BE36: =BD36+AM36-Q36 -> 0 | ... BG36: =BF36+AO36-S36 -> 0 | BH36: =AP36+AJ36-T36 -> 0 | BI36: =AQ36+AK36-U36 -> 0 | BJ36: =AR36+AL36-V36 -> 0 | BK36: =AS36+AM36-W36 -> 0
A37: 挂机 | B37: AAABT800F | C37: KFR-35GW/12CAA81U1套机 | D37: K系列 | E37: KFR-35W/1281室外机总成 | F37: 1P(20款) | G37: φ7（18.186） | H37: φ5 | K37: 0 | L37: 0 | M37: 0 | N37: 0 | O37: 0 | P37: 0 | X37: 0 | Y37: 0 | Z37: =X37-Y37+AC37 -> 0 | AB37: 0 | AC37: 0 | AD37: =AB37-Y37+AA37+AC37 -> 0 | AT37: =SUM(AE37:AR37) -> 0 | AU37: =AD37-AT37 -> 0 | AW37: =AE37+Y37-I37 -> 0 | AX37: =AW37+AF37-J37 -> 0 | AY37: =AX37+AG37-K37 -> 0 | AZ37: =AY37+AH37-L37 -> 0 | BA37: =AZ37+AI37-M37 -> 0 | BB37: =BA37+AJ37-N37 -> 0 | BC37: =BB37+AK37-O37 -> 0 | BD37: =BC37+AL37-P37 -> 0 | BE37: =BD37+AM37-Q37 -> 0 | ... BG37: =BF37+AO37-S37 -> 0 | BH37: =AP37+AJ37-T37 -> 0 | BI37: =AQ37+AK37-U37 -> 0 | BJ37: =AR37+AL37-V37 -> 0 | BK37: =AS37+AM37-W37 -> 0
A38: 挂机 | B38: AAC7U1000 | C38: KFR-35GW/A2CAA81VU1套机 | D38: K系列 | E38: KFR-35W/A281室外机总成 | F38: 1P(20款) | G38: φ7（18.186） | H38: φ7 | K38: 0 | L38: 0 | M38: 0 | N38: 0 | O38: 0 | P38: 0 | X38: 0 | Y38: 0 | Z38: =X38-Y38+AC38 -> 0 | AB38: 0 | AC38: 0 | AD38: =AB38-Y38+AA38+AC38 -> 0 | AT38: =SUM(AE38:AR38) -> 0 | AU38: =AD38-AT38 -> 0 | AW38: =AE38+Y38-I38 -> 0 | AX38: =AW38+AF38-J38 -> 0 | AY38: =AX38+AG38-K38 -> 0 | AZ38: =AY38+AH38-L38 -> 0 | BA38: =AZ38+AI38-M38 -> 0 | BB38: =BA38+AJ38-N38 -> 0 | BC38: =BB38+AK38-O38 -> 0 | BD38: =BC38+AL38-P38 -> 0 | BE38: =BD38+AM38-Q38 -> 0 | ... BG38: =BF38+AO38-S38 -> 0 | BH38: =AP38+AJ38-T38 -> 0 | BI38: =AQ38+AK38-U38 -> 0 | BJ38: =AR38+AL38-V38 -> 0 | BK38: =AS38+AM38-W38 -> 0
A39: 挂机 | B39: AAABT500F | C39: KFR-35GW/16CAB81U1套机 | D39: K系列 | E39: KFR-35W/1681室外机总成 | F39: 1P(20款) | G39: φ7（21.65） | H39: φ7 | K39: 0 | L39: 0 | M39: 0 | N39: 0 | O39: 0 | P39: 0 | X39: 0 | Y39: 0 | Z39: =X39-Y39+AC39 -> 0 | AB39: 0 | AC39: 0 | AD39: =AB39-Y39+AA39+AC39 -> 0 | AT39: =SUM(AE39:AR39) -> 0 | AU39: =AD39-AT39 -> 0 | AW39: =AE39+Y39-I39 -> 0 | AX39: =AW39+AF39-J39 -> 0 | AY39: =AX39+AG39-K39 -> 0 | AZ39: =AY39+AH39-L39 -> 0 | BA39: =AZ39+AI39-M39 -> 0 | BB39: =BA39+AJ39-N39 -> 0 | BC39: =BB39+AK39-O39 -> 0 | BD39: =BC39+AL39-P39 -> 0 | BE39: =BD39+AM39-Q39 -> 0 | ... BG39: =BF39+AO39-S39 -> 0 | BH39: =AP39+AJ39-T39 -> 0 | BI39: =AQ39+AK39-U39 -> 0 | BJ39: =AR39+AL39-V39 -> 0 | BK39: =AS39+AM39-W39 -> 0
A40: 挂机 | B40: AAABT300F | C40: KFR-26GW/16CAB81U1套机 | D40: K系列 | E40: KFR-26W/1681室外机总成 | F40: 1P(20款) | G40: φ7（21.65） | H40: φ5 | K40: 0 | L40: 0 | M40: 0 | N40: 0 | O40: 0 | P40: 0 | X40: 0 | Y40: 0 | Z40: =X40-Y40+AC40 -> 0 | AB40: 0 | AC40: 0 | AD40: =AB40-Y40+AA40+AC40 -> 0 | AT40: =SUM(AE40:AR40) -> 0 | AU40: =AD40-AT40 -> 0 | AW40: =AE40+Y40-I40 -> 0 | AX40: =AW40+AF40-J40 -> 0 | AY40: =AX40+AG40-K40 -> 0 | AZ40: =AY40+AH40-L40 -> 0 | BA40: =AZ40+AI40-M40 -> 0 | BB40: =BA40+AJ40-N40 -> 0 | BC40: =BB40+AK40-O40 -> 0 | BD40: =BC40+AL40-P40 -> 0 | BE40: =BD40+AM40-Q40 -> 0 | ... BG40: =BF40+AO40-S40 -> 0 | BH40: =AP40+AJ40-T40 -> 0 | BI40: =AQ40+AK40-U40 -> 0 | BJ40: =AR40+AL40-V40 -> 0 | BK40: =AS40+AM40-W40 -> 0
...

Sheet 到线体产能
B1: 4月份线体产能安排
B2: 经营体 | C2: 区域 | D2: 线体 | E2: 结构 | F2: 可新接 | G2: 延单 | H2: 产能 | I2: 45034 | J2: 45035 | K2: 45036 | L2: 45037 | M2: 45038 | N2: 45040 | O2: 备注
I3: 周二 | J3: 周三 | K3: 周四 | L3: 周五 | M3: 周六 | N3: 周一
B4: 班次 | I4: 5 | J4: 5 | K4: 5 | L4: 5 | M4: 5 | N4: 5
B5: 外机经营体 | C5: 一期 | D5: 1#陈 | E5: 风管机 | F5: =H5-G5 -> 15600 | H5: =SUM(I5:N5) -> 15600 | I5: 2600 | J5: 2600 | K5: 2600 | L5: 2600 | M5: 2600 | N5: 2600
D6: 2#刘（白） | E6: 柜机 | F6: =H6-G6 -> 18900 | H6: =SUM(I6:N6) -> 18900 | I6: 3000 | J6: 3000 | K6: 3000 | L6: 3300 | M6: 3300 | N6: 3300
D7: 2#侯（夜） | E7: 柜机 | F7: =H7-G7 -> 15600 | H7: =SUM(I7:N7) -> 15600 | I7: 2600 | J7: 2600 | K7: 2600 | L7: 2600 | M7: 2600 | N7: 2600
C8: 二期 | D8: 3#王 | E8: 分体 | F8: =H8-G8 -> 21000 | H8: =SUM(I8:N8) -> 21000 | I8: 3500 | J8: 3500 | K8: 3500 | L8: 3500 | M8: 3500 | N8: 3500
D9: 5#于 | E9: 分体 | F9: =H9-G9 -> 21000 | H9: =SUM(I9:N9) -> 21000 | I9: 3500 | J9: 3500 | K9: 3500 | L9: 3500 | M9: 3500 | N9: 3500
B10: 内机经营体 | C10: 一期 | D10: 6#贾 | E10: 普柜 | F10: =H10-G10 -> 16800 | H10: =SUM(I10:N10) -> 16800 | I10: 2800 | J10: 2800 | K10: 2800 | L10: 2800 | M10: 2800 | N10: 2800
D11: 7#汤（白） | E11: 风管机 | F11: =H11-G11 -> 13200 | H11: =SUM(I11:N11) -> 13200 | I11: 2200 | J11: 2200 | K11: 2200 | L11: 2200 | M11: 2200 | N11: 2200
D12: 7#黄（夜） | E12: 柜机 | F12: =H12-G12 -> 12200 | G12: 1000 | H12: =SUM(I12:N12) -> 13200 | I12: 2200 | J12: 2200 | K12: 2200 | L12: 2200 | M12: 2200 | N12: 2200
C13: 二期 | D13: 8#朱 | E13: 分体 | F13: =H13-G13 -> 25200 | H13: =SUM(I13:N13) -> 25200 | I13: 4200 | J13: 4200 | K13: 4200 | L13: 4200 | M13: 4200 | N13: 4200
D14: 9#马 | E14: 分体 | F14: =H14-G14 -> 25200 | H14: =SUM(I14:N14) -> 25200 | I14: 4200 | J14: 4200 | K14: 4200 | L14: 4200 | M14: 4200 | N14: 4200
B15: 外机小计 | F15: =H15-G15 -> 92100 | G15: =SUM(G5:G9) -> 0 | H15: =SUM(I15:N15) -> 92100 | I15: =SUM(I5:I9) -> 15200 | J15: =SUM(J5:J9) -> 15200 | K15: =SUM(K5:K9) -> 15200 | L15: =SUM(L5:L9) -> 15500 | M15: =SUM(M5:M9) -> 15500 | N15: =SUM(N5:N9) -> 15500
B16: 内机小计 | F16: =H16-G16 -> 92600 | G16: =SUM(G10:G14) -> 1000 | H16: =SUM(I16:N16) -> 93600 | I16: =SUM(I10:I14) -> 15600 | J16: =SUM(J10:J14) -> 15600 | K16: =SUM(K10:K14) -> 15600 | L16: =SUM(L10:L14) -> 15600 | M16: =SUM(M10:M14) -> 15600 | N16: =SUM(N10:N14) -> 15600
B17: 合计 | F17: =H17-G17 -> 184700 | G17: =G15+G16 -> 1000 | H17: =H15+H16 -> 185700 | I17: =I15+I16 -> 30800 | J17: =J15+J16 -> 30800 | K17: =K15+K16 -> 30800 | L17: =L15+L16 -> 31100 | M17: =M15+M16 -> 31100 | N17: =N15+N16 -> 31100
B18: 配套差异 | F18: =F15-F16 -> -500 | G18: =G15-G16 -> -1000 | H18: =H15-H16 -> -1500 | I18: =I15-I16 -> -400 | J18: =J15-J16 -> -400 | K18: =K15-K16 -> -400 | L18: =L15-L16 -> -100 | M18: =M15-M16 -> -100 | N18: =N15-N16 -> -100
B20: 产品 | D20: 内外机 | E20: 系列 | F20: 延单 | G20: 接单 | H20: 消化 | I20: 包销 | J20: 需排产 | K20: 产能需求 | L20: 差异
B21: 家用 | D21: 内机 | E21: 小计 | F21: =SUM(F22:F24) -> 80 | G21: =SUM(G22:G24) -> 81426 | H21: =SUM(H22:H24) -> 21381 | I21: =SUM(I22:I24) -> 21278 | J21: =G21-H21+I21+F21 -> 81403 | K21: =SUM(K22:K23) -> 80400 | L21: =SUM(L22:L24) -> 1003 | O21: 顺延 | P21: 接单
E22: 挂机 | G22: 58286 | H22: 12726 | I22: 2440 | J22: =G22-H22+I22+F22 -> 48000 | K22: =8400*6 -> 50400 | L22: =J22-K22 -> -2400 | N22: 挂机 | O22: 9 | P22: 135
E23: 柜机 | G23: 22216 | H23: 8655 | I23: 18838 | J23: =G23-H23+I23+F23 -> 32399 | K23: =5000*6 -> 30000 | L23: =J23-K23 -> 2399 | N23: 柜机 | O23: 71 | P23: 789
E24: 壳体 | F24: 80 | G24: 924 | J24: =G24-H24+I24+F24 -> 1004 | L24: =J24-K24 -> 1004 | N24: 风管机 | O24: 0 | P24: 0
D25: 外机 | E25: 小计 | F25: =SUM(F26:F27) -> 0 | G25: =SUM(G26:G27) -> 80502 | H25: =SUM(H26:H27) -> 21381 | I25: =SUM(I26:I27) -> 21278 | J25: =G25-H25+I25+F25 -> 80399 | K25: =SUM(K26:K27) -> 80400 | L25: =J25-K25 -> -1
E26: 挂机 | G26: 58286 | H26: 12726 | I26: 2440 | J26: =G26-H26+I26+F26 -> 48000 | K26: 50400 | L26: =J26-K26 -> -2400
E27: 柜机 | G27: 22216 | H27: 8655 | I27: 18838 | J27: =G27-H27+I27+F27 -> 32399 | K27: 30000 | L27: =J27-K27 -> 2399
B28: 风管机 | D28: 内机 | E28: 小计 | G28: 8539 | H28: 7805 | I28: 8261 | J28: =G28-H28+I28+F28 -> 8995 | K28: =2200*6 -> 13200 | L28: =J28-K28 -> -4205
D29: 外机 | E29: 小计 | G29: 8539 | H29: 7805 | I29: 8261 | J29: =G29-H29+I29+F29 -> 8995 | K29: =2200*6 -> 13200 | L29: =J29-K29 -> -4205
B31: 到系列接单生产明细
B32: 柜/挂 | C32: 系列 | D32: 接单 | E32: 消化 | F32: 延单 | G32: 包销 | H32: 生产
B33: 风管机 | C33: 卡萨帝 | D33: =SUMIFS('3月'!$AB$263:$AB$427,'3月'!$D$263:$D$427,$D$3) -> 0 | E33: =SUMIFS('3月'!$X$287:$X$579,'3月'!$D$263:$D$427,$D$3) -> #VALUE! | F33: =SUMIFS('3月'!$AA$263:$AA$427,'3月'!$D$263:$D$427,$D$3) -> 0 | G33: =SUMIFS('3月'!#REF!,'3月'!$D$263:$D$427,$D$3) -> #REF! | H33: =D33-E33+F33+G33 -> #VALUE!
C34: 风管机 | D34: =SUMIFS('3月'!$AB$263:$AB$427,'3月'!$D$263:$D$427,$D$4) -> 0 | E34: =SUMIFS('3月'!$X$287:X579,'3月'!$D$263:$D$427,$D$4) -> #VALUE! | F34: =SUMIFS('3月'!$AA$263:$AA$427,'3月'!$D$263:$D$427,$D$4) -> 0 | G34: =SUMIFS('3月'!#REF!,'3月'!$D$263:$D$427,$D$4) -> #REF! | H34: =D34-E34+F34+G34 -> #VALUE!
B35: 风管机小计 | D35: =SUM(D33:D34) -> 0 | E35: =SUM(E33:E34) -> #VALUE! | F35: =SUM(F33:F34) -> 0 | G35: =SUM(G33:G34) -> #REF! | H35: =SUM(H33:H34) -> #VALUE!
B36: 挂机 | C36: 星河挂 | D36: =SUMIFS('3月'!$AB$7:$AB$77,'3月'!$D$7:$D$77,C36) -> 0 | E36: =SUMIFS('3月'!$Y$7:$Y$77,'3月'!$D$7:$D$77,C36) -> 0 | F36: =SUMIFS('3月'!$AA$7:$AA$77,'3月'!$D$7:$D$77,C36) -> 0 | G36: =SUMIFS('3月'!$AC$7:$AC$77,'3月'!$D$7:$D$77,C36) -> 0 | H36: =D36-E36+F36+G36 -> 0
C37: G系列 | D37: =SUMIFS('3月'!$AB$7:$AB$77,'3月'!$D$7:$D$77,C37) -> 0 | E37: =SUMIFS('3月'!$Y$7:$Y$77,'3月'!$D$7:$D$77,C37) -> 0 | F37: =SUMIFS('3月'!$AA$7:$AA$77,'3月'!$D$7:$D$77,C37) -> 0 | G37: =SUMIFS('3月'!$AC$7:$AC$77,'3月'!$D$7:$D$77,C37) -> 0 | H37: =D37-E37+F37+G37 -> 0
C38: B系列 | D38: =SUMIFS('3月'!$AB$7:$AB$77,'3月'!$D$7:$D$77,C38) -> 0 | E38: =SUMIFS('3月'!$Y$7:$Y$77,'3月'!$D$7:$D$77,C38) -> 0 | F38: =SUMIFS('3月'!$AA$7:$AA$77,'3月'!$D$7:$D$77,C38) -> 0 | G38: =SUMIFS('3月'!$AC$7:$AC$77,'3月'!$D$7:$D$77,C38) -> 0 | H38: =D38-E38+F38+G38 -> 0
C39: K系列 | D39: =SUMIFS('3月'!$AB$7:$AB$77,'3月'!$D$7:$D$77,C39) -> 11663 | E39: =SUMIFS('3月'!$Y$7:$Y$77,'3月'!$D$7:$D$77,C39) -> 37 | F39: =SUMIFS('3月'!$AA$7:$AA$77,'3月'!$D$7:$D$77,C39) -> 0 | G39: =SUMIFS('3月'!$AC$7:$AC$77,'3月'!$D$7:$D$77,C39) -> 560 | H39: =D39-E39+F39+G39 -> 12186
C40: T系列 | D40: =SUMIFS('3月'!$AB$7:$AB$77,'3月'!$D$7:$D$77,C40) -> 0 | E40: =SUMIFS('3月'!$Y$7:$Y$77,'3月'!$D$7:$D$77,C40) -> 0 | F40: =SUMIFS('3月'!$AA$7:$AA$77,'3月'!$D$7:$D$77,C40) -> 0 | G40: =SUMIFS('3月'!$AC$7:$AC$77,'3月'!$D$7:$D$77,C40) -> 0 | H40: =D40-E40+F40+G40 -> 0
C41: 大J系列 | D41: =SUMIFS('3月'!$AB$7:$AB$77,'3月'!$D$7:$D$77,C41) -> 18296 | E41: =SUMIFS('3月'!$Y$7:$Y$77,'3月'!$D$7:$D$77,C41) -> 10346 | F41: =SUMIFS('3月'!$AA$7:$AA$77,'3月'!$D$7:$D$77,C41) -> 0 | G41: =SUMIFS('3月'!$AC$7:$AC$77,'3月'!$D$7:$D$77,C41) -> 1131 | H41: =D41-E41+F41+G41 -> 9081
B42: 挂机小计 | D42: =SUM(D36:D41) -> 29959 | E42: =SUM(E36:E41) -> 10383 | F42: =SUM(F36:F41) -> 0 | G42: =SUM(G36:G41) -> 1691 | H42: =SUM(H36:H41) -> 21267
...

Sheet 大盘规划
A1: 23年目标自然台 | R1: 23年目标标准台
A2: 工厂 | B2: 年累计 | C2: 1月 | D2: 2月 | E2: 3月 | F2: 4月 | G2: 5月 | H2: 6月 | I2: 7月 | J2: 8月 | K2: 9月 | L2: 10月 | M2: 11月 | N2: 12月 | R2: 工厂 | S2: 年累计 | T2: 1月 | U2: 2月 | V2: 3月 | W2: 4月 | X2: 5月 | Y2: 6月 | Z2: 7月 | AA2: 8月 | AB2: 9月 | AC2: 10月 | AD2: 11月 | AE2: 12月
B3: 29166854 | C3: 1334000 | D3: 2581000 | E3: 3468200 | F3: 3279200 | G3: 2820700 | H3: 2464800 | I3: 2244250 | J3: 2008500 | K3: 1850000 | L3: 1871090 | M3: 2411250 | N3: 2833864 | S3: 81880202 | T3: 3821583 | U3: 7391654.5 | V3: 9806009.8 | W3: 9226250.6 | X3: 7885161.9 | Y3: 6968733.8 | Z3: 6250482.1 | AA3: 5603932.9 | AB3: 5135681.8 | AC3: 5244773.1 | AD3: 6722014.4 | AE3: 7823923.8
A4: 合肥 | B4: 5522000 | C4: 300000 | D4: 480000 | E4: 680000 | F4: 680000 | G4: 572000 | H4: 532000 | I4: 408000 | J4: 380000 | K4: 300000 | L4: 300000 | M4: 390000 | N4: 500000 | R4: 合肥 | S4: 19597224 | T4: 1064680.7 | U4: 1703489.2 | V4: 2413276.4 | W4: 2413276.4 | X4: 2029991.3 | Y4: 1888033.9 | Z4: 1447965.8 | AA4: 1348595.6 | AB4: 1064680.7 | AC4: 1064680.7 | AD4: 1384085 | AE4: 1774467.9
A5: 武汉 | B5: 2914500 | C5: 100000 | D5: 260000 | E5: 323200 | F5: 320000 | G5: 303600 | H5: 227700 | I5: 240000 | J5: 220000 | K5: 200000 | L5: 180000 | M5: 220000 | N5: 320000 | R5: 武汉 | S5: 6144153.6 | T5: 210813.3 | U5: 548114.58 | V5: 681349 | W5: 674603 | X5: 640029.18 | Y5: 480021.89 | Z5: 505951.92 | AA5: 463789 | AB5: 421626 | AC5: 379463.94 | AD5: 463789.26 | AE5: 674602.56
A6: 重庆 | B6: 5005364 | C6: 180000 | D6: 420000 | E6: 660000 | F6: 700000 | G6: 540000 | H6: 420000 | I6: 420000 | J6: 320000 | K6: 260000 | L6: 260000 | M6: 360000 | N6: 465364 | R6: 重庆 | S6: 13514483 | T6: 486000 | U6: 1134000 | V6: 1782000 | W6: 1890000 | X6: 1458000 | Y6: 1134000 | Z6: 1134000 | AA6: 864000 | AB6: 702000 | AC6: 702000 | AD6: 972000 | AE6: 1256482.8
A7: 胶州 | B7: 7769600 | C7: 420000 | D7: 720000 | E7: 820000 | F7: 680000 | G7: 660000 | H7: 609600 | I7: 520000 | J7: 540000 | K7: 620000 | L7: 660000 | M7: 760000 | N7: 760000 | R7: 胶州 | S7: 21937995 | T7: 1190424.9 | U7: 2131252.2 | V7: 2363494.5 | W7: 2013332.6 | X7: 1872708.3 | Y7: 1724452.2 | Z7: 1481841.5 | AA7: 1503222.8 | AB7: 1695779.9 | AC7: 1836065.4 | AD7: 2081424.1 | AE7: 2043997.1
A8: 大连 | B8: 816000 | C8: 82000 | D8: 143000 | E8: 156000 | F8: 32000 | G8: 35000 | H8: 43000 | I8: 55000 | J8: 0 | K8: 30000 | L8: 40000 | M8: 100000 | N8: 100000 | R8: 大连 | S8: 2625000 | T8: 230000 | U8: 480000 | V8: 530000 | W8: 115000 | X8: 115000 | Y8: 145000 | Z8: 145000 | AB8: 80000 | AC8: 120000 | AD8: 330000 | AE8: 335000
A9: 郑州 | B9: 5160000 | C9: 180000 | D9: 420000 | E9: 660000 | F9: 700000 | G9: 540000 | H9: 460000 | I9: 420000 | J9: 360000 | K9: 260000 | L9: 260000 | M9: 400000 | N9: 500000 | R9: 郑州 | S9: 11611766 | T9: 405061.6 | U9: 945143.74 | V9: 1485225.9 | W9: 1575239.6 | X9: 1215184.8 | Y9: 1035157.4 | Z9: 945143.74 | AA9: 810123.21 | AB9: 585088.98 | AC9: 585088.98 | AD9: 900136.9 | AE9: 1125171.1
A10: 合肥家中机 | B10: 1979390 | C10: 72000 | D10: 138000 | E10: 169000 | F10: 167200 | G10: 170100 | H10: 172500 | I10: 181250 | J10: 188500 | K10: 180000 | L10: 171090 | M10: 181250 | N10: 188500 | R10: 合肥家中机 | S10: 6449580.3 | T10: 234602.47 | U10: 449654.73 | V10: 550664.13 | W10: 544799.06 | X10: 554248.33 | Y10: 562068.41 | Z10: 590579.13 | AA10: 614202.29 | AB10: 586506.17 | AC10: 557474.11 | AD10: 590579.13 | AE10: 614202.29
A12: 23年合肥目标自然台
A13: 工厂 | B13: 年累计 | C13: 1月 | D13: 2月 | E13: 3月 | F13: 4月 | G13: 5月 | H13: 6月 | I13: 7月 | J13: 8月 | K13: 9月 | L13: 10月 | M13: 11月 | N13: 12月
A14: 计划生产 | B14: 5522000 | C14: 300000 | D14: 480000 | E14: 680000 | F14: 680000 | G14: 572000 | H14: 532000 | I14: 408000 | J14: 380000 | K14: 300000 | L14: 300000 | M14: 390000 | N14: 500000
A15: 实际生产 | B15: =SUM(C15:N15) -> 2868382 | C15: 281133 | D15: 544432 | E15: 741829 | F15: 651929 | G15: 649059
A16: 完成率 | B16: =B15/B14 -> 0.51944622 | C16: =C15/C14 -> 0.93711 | D16: =D15/D14 -> 1.1342333 | E16: =E15/E14 -> 1.090925 | F16: =F15/F14 -> 0.95871912 | G16: =G15/G14 -> 1.1347185

Sheet 两器短板能力
A1: 5MM柜机蒸发器
A2: 两器规格 | B2: 类别 | C2: 总计 | D2: 45106 | E2: 45107 | F2: 45108 | G2: 45109 | H2: 45110 | I2: 45111 | J2: 45112 | K2: 45113 | L2: 45114 | M2: 45115 | N2: 45116 | O2: 45117 | P2: 45118 | Q2: 45119 | R2: 45120 | S2: 45121 | T2: 45122 | U2: 45123 | V2: 45124 | W2: 45125 | X2: 45126 | Y2: 45127 | Z2: 45128 | AA2: 45129 | AB2: 45130 | AC2: 45131 | AD2: 45132 | AE2: 45133 | AF2: 45134 | AG2: 45135 | AH2: 45136 | AI2: 45137 | AJ2: 45138 | AK2: 45139 | AL2: 45140 | AM2: 45141 | AN2: 45142 | AO2: 45143 | AP2: 45144 | AQ2: 45145
A3: φ5柜机 | B3: 计划 | C3: =SUM(F3:O3) -> 38842 | F3: 5407 | G3: 1074 | H3: 5072 | I3: 4958 | J3: 2815 | K3: 5246 | L3: 5083 | M3: 3904 | O3: 5283 | P3: 2643 | Q3: 4045 | R3: 6223 | S3: 6526 | T3: 4655 | U3: 2200 | V3: 5582 | W3: 3187 | X3: 6864 | Y3: 6938 | Z3: 4630 | AA3: 2281 | AB3: 0 | AC3: 4069 | AD3: 4400 | AE3: 2900 | AF3: 5072 | AG3: 6634 | AH3: 4576 | AI3: 5568 | AJ3: 0 | AK3: 5071 | AL3: 2800 | AM3: 5340 | AN3: 5347 | AO3: 3607 | AP3: 0 | AQ3: 3306
B4: 产能 | C4: =SUM(F4:O4) -> 41300 | E4: 2100 | F4: 4400 | G4: 4200 | H4: 4200 | I4: 4200 | J4: 4200 | K4: 4200 | L4: 4200 | M4: 3900 | N4: 3900 | O4: 3900 | P4: 4500 | Q4: 4500 | R4: 4500 | S4: 4500 | T4: 4500 | U4: 4500 | V4: 4500 | W4: 4500 | X4: 4500 | Y4: 4500 | Z4: 4500 | AA4: 4500 | AB4: 4500 | AC4: 4500 | AD4: 4500 | AE4: 4500 | AF4: 4500 | AG4: 4500 | AH4: 4500 | AI4: 4500 | AK4: 4500 | AL4: 4500 | AM4: 4500 | AN4: 4500 | AO4: 4500 | AP4: 4500 | AQ4: 4500
B5: 库存 | C5: =SUM(F5:O5) -> 61735 | D5: 2900 | E5: =D5-E3+E4 -> 5000 | F5: =E5-F3+F4 -> 3993 | G5: =F5-G3+G4 -> 7119 | H5: =G5-H3+H4 -> 6247 | I5: =H5-I3+I4 -> 5489 | J5: =I5-J3+J4 -> 6874 | K5: =J5-K3+K4 -> 5828 | L5: =K5-L3+L4 -> 4945 | ... AQ5: =AP5-AQ3+AQ4 -> 14494
B6: T-1天缺口 | C6: =SUM(F6:O6) -> 20435 | D6: 2900 | E6: 5000 | F6: =E5-F3 -> -407 | G6: =F5-G3 -> 2919 | H6: =G5-H3 -> 2047 | I6: =H5-I3 -> 1289 | J6: =I5-J3 -> 2674 | K6: =J5-K3 -> 1628 | L6: =K5-L3 -> 745 | M6: =L5-M3 -> 1041 | ... AQ6: =AP5-AQ3 -> 9994
A7: 5MM挂机蒸发器
A8: 两器规格 | B8: 类别 | C8: 总计 | D8: 45106 | E8: 45107 | F8: 45108 | G8: 45109 | H8: 45110 | I8: 45111 | J8: 45112 | K8: 45113 | L8: 45114 | M8: 45115 | N8: 45116 | O8: 45117 | P8: 45118 | Q8: 45119 | R8: 45120 | S8: 45121 | T8: 45122 | U8: 45123 | V8: 45124 | W8: 45125 | X8: 45126 | Y8: 45127 | Z8: 45128 | AA8: 45129 | AB8: 45130 | AC8: 45131 | AD8: 45132 | AE8: 45133 | AF8: 45134 | AG8: 45135 | AH8: 45136 | AI8: 45137 | AJ8: 45138 | AK8: 45139 | AL8: 45140 | AM8: 45141 | AN8: 45142 | AO8: 45143 | AP8: 45144 | AQ8: 45145
A9: φ5挂机 | B9: 计划 | C9: =SUM(F9:O9) -> 50314 | F9: 8085 | H9: 8053 | I9: 5806 | K9: 8156 | L9: 4055 | M9: 8028 | O9: 8131 | P9: 4561 | Q9: 8095 | R9: 3429 | S9: 5746 | T9: 8011 | U9: 0 | V9: 8060 | W9: 5235 | X9: 5643 | Y9: 6702 | Z9: 8185 | AA9: 8046 | AB9: 8000 | AC9: 8300 | AD9: 4135 | AE9: 7650 | AF9: 8085 | AG9: 8400 | AH9: 8400 | AI9: 8456 | AJ9: 0 | AK9: 3876 | AL9: 463 | AM9: 1856 | AN9: 4300 | AO9: 6890 | AP9: 0 | AQ9: 7486
B10: 产能 | C10: =SUM(F10:O10) -> 50000 | E10: 2500 | F10: 5000 | G10: 5000 | H10: 5000 | I10: 5000 | J10: 5000 | K10: 5000 | L10: 5000 | M10: 5000 | N10: 5000 | O10: 5000 | P10: 5000 | Q10: 5000 | R10: 5000 | S10: 5000 | T10: 5000 | U10: 5000 | V10: 5000 | W10: 5000 | X10: 5000 | Y10: 5000 | Z10: 5000 | AA10: 5000 | AB10: 5000 | AC10: 5000 | AD10: 5000 | AE10: 5000 | AF10: 5000 | AG10: 5000 | AH10: 5000 | AI10: 5000 | AK10: 5000 | AL10: 5000 | AM10: 5000 | AN10: 5000 | AO10: 5000 | AP10: 5000 | AQ10: 5000
B11: 调拨补充 | M11: 5000 | P11: 5000 | U11: 5000 | Y11: 5000 | Z11: 5000 | AC11: 3000 | AE11: 5000 | AG11: 2000
B12: 库存 | C12: =SUM(F12:O12) -> 66869 | D12: 2700 | E12: =D12+E10 -> 5200 | F12: =E12-F9+F10+F11 -> 2115 | G12: =F12-G9+G10+G11 -> 7115 | H12: =G12-H9+H10+H11 -> 4062 | I12: =H12-I9+I10+I11 -> 3256 | J12: =I12-J9+J10+J11 -> 8256 | K12: =J12-K9+K10+K11 -> 5100 | L12: =K12-L9+L10+L11 -> 6045 | M12: =L12-M9+M10+M11 -> 8017 | ... AQ12: =AP12-AQ9+AQ10+AQ11 -> 16876
B13: T-1天缺口 | C13: =SUM(F13:O13) -> 11869 | D13: 2700 | E13: 5200 | F13: =E12-F9 -> -2885 | G13: =F12-G9 -> 2115 | H13: =G12-H9 -> -938 | I13: =H12-I9 -> -1744 | J13: =I12-J9 -> 3256 | K13: =J12-K9 -> 100 | L13: =K12-L9 -> 1045 | M13: =L12-M9 -> -1983 | ... AQ13: =AP12-AQ9 -> 11876
A14: 21.65冷凝器
A15: 两器规格 | B15: 类别 | C15: 总计 | D15: 45106 | E15: 45107 | F15: 45108 | G15: 45109 | H15: 45110 | I15: 45111 | J15: 45112 | K15: 45113 | L15: 45114 | M15: 45115 | N15: 45116 | O15: 45117 | P15: 45118 | Q15: 45119 | R15: 45120 | S15: 45121 | T15: 45122 | U15: 45123 | V15: 45124 | W15: 45125 | X15: 45126 | Y15: 45127 | Z15: 45128 | AA15: 45129 | AB15: 45130 | AC15: 45131 | AD15: 45132 | AE15: 45133 | AF15: 45134 | AG15: 45135 | AH15: 45136 | AI15: 45137 | AJ15: 45138 | AK15: 45139 | AL15: 45140 | AM15: 45141 | AN15: 45142 | AO15: 45143 | AP15: 45144 | AQ15: 45145
A16: 21.65 | B16: 26风管机 | C16: =SUM(F16:O16) -> 148 | D16: 0 | E16: 0 | F16: 48 | G16: 0 | H16: 0 | I16: 0 | J16: 0 | K16: 0 | L16: 0 | M16: 0 | N16: 0 | O16: 100 | W16: 58 | AD16: 50 | AE16: 0 | AF16: 0 | AG16: 0 | AH16: 0 | AI16: 0 | AJ16: 0 | AK16: 0 | AL16: 0 | AM16: 0 | AN16: 0 | AO16: 0 | AP16: 0 | AQ16: 0
B17: 35风管机 | C17: =SUM(F17:O17) -> 4400 | D17: 0 | E17: 0 | F17: 0 | G17: 1700 | H17: 0 | I17: 0 | J17: 0 | K17: 0 | L17: 500 | M17: 0 | N17: 0 | O17: 2200 | Q17: 1700 | AA17: 1000 | AC17: 800 | AD17: 0 | AE17: 1300 | AF17: 400 | AG17: 0 | AH17: 0 | AI17: 0 | AJ17: 0 | AK17: 0 | AL17: 0 | AM17: 100 | AN17: 100 | AO17: 600 | AP17: 0 | AQ17: 0
B18: 50风管机 | C18: =SUM(F18:O18) -> 2110 | D18: 0 | E18: 0 | F18: 1000 | G18: 300 | H18: 0 | I18: 0 | J18: 610 | K18: 0 | L18: 200 | M18: 0 | N18: 0 | O18: 0 | P18: 104 | Q18: 10 | W18: 1200 | AA18: 50 | AD18: 710 | AE18: 0 | AF18: 0 | AG18: 0 | AH18: 0 | AI18: 0 | AJ18: 0 | AK18: 0 | AL18: 0 | AM18: 400 | AN18: 400 | AO18: 0 | AP18: 0 | AQ18: 0
B19: 挂机 | C19: =SUM(F19:O19) -> 58836 | D19: 0 | E19: 0 | F19: 7685 | G19: 1156 | H19: 8053 | I19: 5822 | J19: 7000 | K19: 7058 | L19: 7552 | M19: 8028 | N19: 0 | O19: 6482 | P19: 5768 | Q19: 4936 | R19: 5429 | S19: 7530 | T19: 12261 | U19: 0 | V19: 8760 | W19: 1735 | X19: 5643 | Y19: 6902 | Z19: 3210 | AA19: 3749 | AB19: 0 | AC19: 4173 | AD19: 0 | AE19: 5850 | AF19: 8085 | AG19: 8400 | AH19: 8400 | AI19: 6456 | AJ19: 0 | AK19: 2976 | AL19: 463 | AM19: 1856 | AN19: 4300 | AO19: 5600 | AP19: 0 | AQ19: 7486
B20: 柜机 | C20: =SUM(F20:O20) -> 6233 | D20: 0 | E20: 0 | F20: 0 | G20: 1074 | H20: 0 | I20: 0 | J20: 0 | K20: 1318 | L20: 2386 | M20: 1455 | N20: 0 | O20: 0 | P20: 286 | Q20: 293 | R20: 404 | S20: 259 | T20: 0 | U20: 0 | V20: 400 | W20: 1187 | X20: 964 | Y20: 971 | Z20: 95 | AA20: 624 | AB20: 0 | AC20: 300 | AD20: 1331 | AE20: 200 | AF20: 744 | AG20: 1514 | AH20: 0 | AI20: 0 | AJ20: 0 | AK20: 0 | AL20: 253 | AM20: 400 | AN20: 0 | AO20: 709 | AP20: 0 | AQ20: 0
B21: 计划小计 | C21: =SUM(F21:O21) -> 80070 | D21: 0 | E21: 0 | F21: =F16+F17+F18*2+F19+F20*2 -> 9733 | G21: =G16+G17+G18*2+G19+G20*2 -> 5604 | H21: =H16+H17+H18*2+H19+H20*2 -> 8053 | I21: =I16+I17+I18*2+I19+I20*2 -> 5822 | J21: =J16+J17+J18*2+J19+J20*2 -> 8220 | K21: =K16+K17+K18*2+K19+K20*2 -> 9694 | L21: =L16+L17+L18*2+L19+L20*2 -> 13224 | M21: =M16+M17+M18*2+M19+M20*2 -> 10938 | ... AQ21: =AQ16+AQ17+AQ18*2+AQ19+AQ20*2 -> 7486
B22: 产能 | C22: =SUM(F22:O22) -> 70000 | D22: 0 | E22: 3500 | F22: 7000 | G22: 7000 | H22: 7000 | I22: 7000 | J22: 7000 | K22: 7000 | L22: 7000 | M22: 7000 | N22: 7000 | O22: 7000 | P22: 7000 | Q22: 7000 | R22: 7000 | S22: 7000 | T22: 7000 | U22: 7000 | V22: 7000 | W22: 7000 | X22: 7000 | Y22: 7000 | Z22: 7000 | AA22: 7000 | AB22: 7000 | AC22: 7000 | AD22: 7000 | AE22: 7000 | AF22: 7000 | AG22: 7000 | AH22: 7000 | AI22: 7000 | AJ22: 7000 | AK22: 7000 | AL22: 7000 | AM22: 7000 | AN22: 7000 | AO22: 7000 | AP22: 7000 | AQ22: 7000
B23: 调拨补充 | D23: 0 | E23: 0 | F23: 0 | G23: 3360 | H23: 3360 | J23: 3360 | L23: 3360
B24: 库存 | C24: =SUM(F24:O24) -> 132494 | D24: =9700+1000*2 -> 11700 | E24: 10200 | F24: =E24-F21+F22 -> 7467 | G24: =F24-G21+G22+G23 -> 12223 | H24: =G24-H21+H22+H23 -> 14530 | I24: =H24-I21+I22+I23 -> 15708 | J24: =I24-J21+J22+J23 -> 17848 | K24: =J24-K21+K22+K23 -> 15154 | L24: =K24-L21+L22+L23 -> 12290 | M24: =L24-M21+M22+M23 -> 8352 | N24: =M24-N21+N22+N23 -> 15352 | ... AQ24: =AP24-AQ21+AQ22+AQ23 -> 45878
B25: T-1天缺口 | C25: =SUM(F25:O25) -> 49054 | D25: 11700 | E25: 10200 | F25: =E24-F21 -> 467 | G25: =F24-G21 -> 1863 | H25: =G24-H21 -> 4170 | I25: =H24-I21 -> 8708 | J25: =I24-J21 -> 7488 | K25: =J24-K21 -> 8154 | L25: =K24-L21 -> 1930 | M25: =L24-M21 -> 1352 | ... AQ25: =AP24-AQ21 -> 38878
A26: 18.186柜机冷凝器
A27: 两器规格 | B27: 类别 | C27: 总计 | D27: 45106 | E27: 45107 | F27: 45108 | G27: 45109 | H27: 45110 | I27: 45111 | J27: 45112 | K27: 45113 | L27: 45114 | M27: 45115 | N27: 45116 | O27: 45117 | P27: 45118 | Q27: 45119 | R27: 45120 | S27: 45121 | T27: 45122 | U27: 45123 | V27: 45124 | W27: 45125 | X27: 45126 | Y27: 45127 | Z27: 45128 | AA27: 45129 | AB27: 45130 | AC27: 45131 | AD27: 45132 | AE27: 45133 | AF27: 45134 | AG27: 45135 | AH27: 45136 | AI27: 45137 | AJ27: 45138 | AK27: 45139 | AL27: 45140 | AM27: 45141 | AN27: 45142 | AO27: 45143 | AP27: 45144 | AQ27: 45145 | AR27: 45146 | AS27: 45147 | AT27: 45148 | AU27: 45149 | AV27: 45150 | AW27: 45151 | AX27: 45152
A28: 18.186 | B28: 柜机 | C28: =SUM(F28:O28) -> 49614 | F28: 6406 | G28: 3261 | H28: 4252 | I28: 5738 | J28: 6766 | K28: 7556 | L28: 4498 | M28: 5862 | O28: 5275 | P28: 7680 | Q28: 5893 | R28: 5044 | S28: 4867 | T28: 2362 | U28: 0 | V28: 6552 | W28: 5107 | X28: 3377 | Y28: 5967 | Z28: 5470 | AA28: 4660 | AB28: 0 | AC28: 5076 | AD28: 5391 | AE28: 6407 | AF28: 6228 | AG28: 5120 | AH28: 6076 | AI28: 5568 | AK28: 5071 | AL28: 6947 | AM28: 6540 | AN28: 7147 | AO28: 4098 | AQ28: 5006 | AR28: 3802 | AS28: 5110 | AT28: 4460 | AU28: 5550 | AV28: 0 | AX28: 6420
B29: 产能 | C29: =SUM(F29:O29) -> 52000 | E29: 2600 | F29: 5200 | G29: 5200 | H29: 5200 | I29: 5200 | J29: 5200 | K29: 5200 | L29: 5200 | M29: 5200 | N29: 5200 | O29: 5200 | P29: 5200 | Q29: 5200 | R29: 5200 | S29: 5200 | T29: 5200 | U29: 5200 | V29: 5200 | W29: 5200 | X29: 5200 | Y29: 5200 | Z29: 5200 | AA29: 5200 | AB29: 5200 | AC29: 5200 | AD29: 5200 | AE29: 5200 | AF29: 5200 | AG29: 5200 | AH29: 5200 | AI29: 5200 | AK29: 5200 | AL29: 5200 | AM29: 5200 | AN29: 5200 | AO29: 5200 | AP29: 5200 | AQ29: 5200 | AR29: 5200 | AS29: 5200 | AT29: 5200 | AU29: 5200 | AV29: 5200 | AW29: 5200 | AX29: 5200
B30: 库存 | C30: =SUM(F30:O30) -> 40480 | D30: 1530 | E30: =D30+E29 -> 4130 | F30: =E30-F28+F29 -> 2924 | G30: =F30-G28+G29 -> 4863 | H30: =G30-H28+H29 -> 5811 | I30: =H30-I28+I29 -> 5273 | J30: =I30-J28+J29 -> 3707 | K30: =J30-K28+K29 -> 1351 | L30: =K30-L28+L29 -> 2053 | M30: =L30-M28+M29 -> 1391 | ... AI30: =AH30-AI28+AI29 -> 13671 | AJ30: 3000 | AK30: =AJ30-AK28+AK29 -> 3129 | AL30: =AK30-AL28+AL29 -> 1382 | AM30: =AL30-AM28+AM29 -> 42 | AN30: =AM30-AN28+AN29 -> -1905 | AO30: =AN30-AO28+AO29 -> -803 | AP30: =AO30-AP28+AP29 -> 4397 | AQ30: =AP30-AQ28+AQ29 -> 4591 | AR30: =AQ30-AR28+AR29 -> 5989 | ... AX30: =AW30-AX28+AX29 -> 15649
B31: T-1天缺口 | C31: =SUM(F31:O31) -> -11520 | D31: 1530 | E31: 4130 | F31: =E30-F28 -> -2276 | G31: =F30-G28 -> -337 | H31: =G30-H28 -> 611 | I31: =H30-I28 -> 73 | J31: =I30-J28 -> -1493 | K31: =J30-K28 -> -3849 | L31: =K30-L28 -> -3147 | M31: =L30-M28 -> -3809 | ... AI31: =AH30-AI28 -> 8471 | AK31: =AJ30-AK28 -> -2071 | AL31: =AK30-AL28 -> -3818 | AM31: =AL30-AM28 -> -5158 | AN31: =AM30-AN28 -> -7105 | AO31: =AN30-AO28 -> -6003 | AP31: =AO30-AP28 -> -803 | AQ31: =AP30-AQ28 -> -609 | AR31: =AQ30-AR28 -> 789 | ... AX31: =AW30-AX28 -> 10449
A33: 两器规格 | B33: 类别 | AH33: 两器规格 | AI33: 类别 | AJ33: 45138 | AK33: 45139 | AL33: 45140 | AM33: 45141 | AN33: 45142 | AO33: 45143 | AP33: 45144 | AQ33: 45145 | AR33: 45146 | AS33: 45147 | AT33: 45148 | AU33: 45149 | AV33: 45150 | AW33: 45151 | AX33: 45152
A34: 18.186 | B34: 挂机 | AH34: 18.186 | AI34: 挂机 | AL34: 3828 | AM34: 1771 | AN34: 0 | AO34: 1290 | AQ34: 906 | AR34: 3802 | AS34: 5110 | AT34: 6460 | AU34: 5550 | AV34: 2300 | AW34: 8320
B35: 产能 | AI35: 产能 | AJ35: 1500 | AK35: 1000 | AL35: 1000 | AM35: 1000 | AN35: 1000 | AO35: 1000 | AP35: 1000 | AQ35: 1000 | AR35: 1000 | AS35: 1000 | AT35: 1000 | AU35: 1000 | AV35: 1000
B36: 库存 | AI36: 库存 | AJ36: 1500 | AK36: =AJ36-AK34+AK35 -> 2500 | AL36: =AK36-AL34+AL35 -> -328 | AM36: =AL36-AM34+AM35 -> -1099 | AN36: =AM36-AN34+AN35 -> -99 | AO36: =AN36-AO34+AO35 -> -389 | AP36: =AO36-AP34+AP35 -> 611 | AQ36: =AP36-AQ34+AQ35 -> 705 | AR36: =AQ36-AR34+AR35 -> -2097 | ... AV36: =AU36-AV34+AV35 -> -17517
B37: T-1天缺口 | AI37: T-1天缺口

Sheet 两器到机台产能匹配
A1: 5MM柜机蒸发器
A2: 两器规格 | B2: 类别 | C2: 总计 | D2: 45137 | E2: 45138 | F2: 45139 | G2: 45140 | H2: 45141 | I2: 45142 | J2: 45143 | K2: 45144 | L2: 45145 | M2: 45146 | N2: 45147 | O2: 45148 | P2: 45149 | Q2: 45150 | R2: 45151 | S2: 45152 | T2: 45153 | U2: 45154 | V2: 45155 | W2: 45156 | X2: 45157 | Y2: 45158 | Z2: 45159
A3: φ5柜机 | B3: 计划 | C3: =SUM(D3:D3) -> 3000 | D3: 3000 | E3: 0 | G3: 5279 | H3: 4302 | I3: 3667 | J3: 5600 | L3: 3826 | M3: 3802 | N3: 5110 | O3: 2200 | P3: 3000 | Q3: 400 | R3: 0 | S3: 3300 | T3: 5051 | U3: 3400 | V3: 3932 | W3: 4400 | Z3: 3822
B4: 产能 | C4: =SUM(D4:D4) -> 4500 | D4: 4500 | E4: 2300 | F4: 4500 | G4: 4500 | H4: 4500 | I4: 4500 | J4: 4500 | K4: 4500 | L4: 4500 | M4: 4500 | N4: 4500 | O4: 4500 | P4: 4500 | Q4: 4500 | R4: 4500 | S4: 4500 | T4: 4500 | U4: 4500 | V4: 4500 | W4: 4500 | X4: 4500 | Y4: 4500 | Z4: 4500
B5: 库存 | C5: 0 | D5: 0 | E5: =D5-E3+E4 -> 2300 | F5: =E5-F3+F4 -> 6800 | G5: =F5-G3+G4 -> 6021 | H5: =G5-H3+H4 -> 6219 | I5: =H5-I3+I4 -> 7052 | J5: =I5-J3+J4 -> 5952 | K5: =J5-K3+K4 -> 10452 | L5: =K5-L3+L4 -> 11126 | ... Z5: =Y5-Z3+Z4 -> 35709
B6: T-1天缺口 | C6: 0 | D6: 0 | E6: =D5-E3 -> 0 | F6: =E5-F3 -> 2300 | G6: =F5-G3 -> 1521 | H6: =G5-H3 -> 1719 | I6: =H5-I3 -> 2552 | J6: =I5-J3 -> 1452 | K6: =J5-K3 -> 5952 | L6: =K5-L3 -> 6626 | ... Z6: =Y5-Z3 -> 31209
A7: 5MM挂机蒸发器
A8: 两器规格 | B8: 类别 | C8: 总计 | D8: 45137 | E8: 45138 | F8: 45139 | G8: 45140 | H8: 45141 | I8: 45142 | J8: 45143 | K8: 45144 | L8: 45145 | M8: 45146 | N8: 45147 | O8: 45148 | P8: 45149 | Q8: 45150 | R8: 45151 | S8: 45152 | T8: 45153 | U8: 45154 | V8: 45155 | W8: 45156 | X8: 45157 | Y8: 45158 | Z8: 45159
A9: φ5挂机 | B9: 计划 | C9: =SUM(D9:E9) -> 7200 | D9: 7200 | E9: 0 | F9: 6743 | G9: 1000 | H9: 4300 | I9: 1290 | J9: 7300 | K9: 0 | L9: 8105 | M9: 3217 | N9: 2400 | O9: 0 | P9: 4228 | Q9: 3194 | R9: 0 | S9: 950 | T9: 2400 | U9: 0 | V9: 4323 | W9: 0 | X9: 0 | Y9: 0 | Z9: 3244
B10: 产能 | C10: =SUM(D10:E10) -> 7500 | D10: 5000 | E10: 2500 | F10: 5000 | G10: 5000 | H10: 5000 | I10: 5000 | J10: 5000 | K10: 5000 | L10: 5000 | M10: 5000 | N10: 5000 | O10: 5000 | P10: 5000 | Q10: 5000 | R10: 5000 | S10: 5000 | T10: 5000 | U10: 5000 | V10: 5000 | W10: 5000 | X10: 5000 | Y10: 5000 | Z10: 5000
B11: 库存 | C11: =SUM(D11:E11) -> 8500 | D11: 3000 | E11: =D11-E9+E10 -> 5500 | F11: =E11-F9+F10 -> 3757 | G11: =F11-G9+G10 -> 7757 | H11: =G11-H9+H10 -> 8457 | I11: =H11-I9+I10 -> 12167 | J11: =I11-J9+J10 -> 9867 | K11: =J11-K9+K10 -> 14867 | L11: =K11-L9+L10 -> 11762 | ... Z11: =Y11-Z9+Z10 -> 57806
B12: T-1天缺口 | C12: =SUM(D12:E12) -> 3000 | D12: 0 | E12: =D11-E9 -> 3000 | F12: =E11-F9 -> -1243 | G12: =F11-G9 -> 2757 | H12: =G11-H9 -> 3457 | I12: =H11-I9 -> 7167 | J12: =I11-J9 -> 4867 | K12: =J11-K9 -> 9867 | L12: =K11-L9 -> 6762 | ... Z12: =Y11-Z9 -> 52806
A13: 21.65冷凝器
A14: 两器规格 | B14: 类别 | C14: 总计 | D14: 45137 | E14: 45138 | F14: 45139 | G14: 45140 | H14: 45141 | I14: 45142 | J14: 45143 | K14: 45144 | L14: 45145 | M14: 45146 | N14: 45147 | O14: 45148 | P14: 45149 | Q14: 45150 | R14: 45151 | S14: 45152 | T14: 45153 | U14: 45154 | V14: 45155 | W14: 45156 | X14: 45157 | Y14: 45158 | Z14: 45159
A15: 21.65冷凝器 | B15: 计划小计 | C15: =SUM(D15:E15) -> 3064 | D15: 3064 | E15: 0 | F15: 5958 | G15: 4305 | H15: 5100 | I15: 3482 | J15: 5262 | K15: 0 | L15: 7605 | M15: 3417 | N15: 2400 | O15: 3005 | P15: 3095 | Q15: 3434 | R15: 0 | S15: 950 | T15: 1041 | U15: 3405 | V15: 6946 | W15: 0 | X15: 0 | Y15: 0 | Z15: 3244
B16: 产能 | C16: =SUM(D16:E16) -> 9500 | D16: 6500 | E16: 3000 | F16: 6500 | G16: 6500 | H16: 6500 | I16: 6500 | J16: 6500 | K16: 6500 | L16: 6500 | M16: 6500 | N16: 6500 | O16: 6500 | P16: 6500 | Q16: 6500 | R16: 6500 | S16: 6500 | T16: 6500 | U16: 6500 | V16: 6500 | W16: 6500 | X16: 6500 | Y16: 6500 | Z16: 6500
B17: 库存 | C17: 0 | D17: 6000 | E17: =D17-E15+E16 -> 9000 | F17: =E17-F15+F16 -> 9542 | G17: =F17-G15+G16 -> 11737 | H17: =G17-H15+H16 -> 13137 | I17: =H17-I15+I16 -> 16155 | J17: =I17-J15+J16 -> 17393 | K17: =J17-K15+K16 -> 23893 | L17: =K17-L15+L16 -> 22788 | ... Z17: =Y17-Z15+Z16 -> 82851
B18: T-1天缺口 | C18: 0 | D18: 0 | E18: =D17-E15 -> 6000 | F18: =E17-F15 -> 3042 | G18: =F17-G15 -> 5237 | H18: =G17-H15 -> 6637 | I18: =H17-I15 -> 9655 | J18: =I17-J15 -> 10893 | K18: =J17-K15 -> 17393 | L18: =K17-L15 -> 16288 | ... Z18: =Y17-Z15 -> 76351
A19: 18.186柜机冷凝器
A20: 两器规格 | B20: 类别 | C20: 总计 | D20: 45137 | E20: 45138 | F20: 45139 | G20: 45140 | H20: 45141 | I20: 45142 | J20: 45143 | K20: 45144 | L20: 45145 | M20: 45146 | N20: 45147 | O20: 45148 | P20: 45149 | Q20: 45150 | R20: 45151 | S20: 45152 | T20: 45153 | U20: 45154 | V20: 45155 | W20: 45156 | X20: 45157 | Y20: 45158 | Z20: 45159
A21: 18.186 | B21: 柜机 | C21: =SUM(D21:E21) -> 7572 | D21: 7572 | E21: 0 | F21: 4992 | G21: 2544 | H21: 5834 | I21: 5111 | J21: 5418 | K21: 0 | L21: 5711 | M21: 3802 | N21: 5110 | O21: 2300 | P21: 5300 | Q21: 6404 | R21: 0 | S21: =6626+487 -> 7113 | T21: 6060 | U21: 3400 | V21: 4240 | W21: 7896 | Z21: 5798
B22: 产能 | C22: =SUM(D22:E22) -> 7700 | D22: 5200 | E22: 2500 | F22: 5200 | G22: 4200 | H22: 5200 | I22: 5200 | J22: 5200 | K22: 5200 | L22: 4000 | M22: 4000 | N22: 4000 | O22: 5200 | P22: 5200 | Q22: 5200 | R22: 5200 | S22: 4000 | T22: 4000 | U22: 5200 | V22: 5200 | W22: 5200 | X22: 5200 | Y22: 5200 | Z22: 5200
B23: 库存 | C23: 0 | D23: 0 | E23: =D23-E21+E22 -> 2500 | F23: =E23-F21+F22 -> 2708 | G23: =F23-G21+G22 -> 4364 | H23: =G23-H21+H22 -> 3730 | I23: =H23-I21+I22 -> 3819 | J23: =I23-J21+J22 -> 3601 | K23: =J23-K21+K22 -> 8801 | L23: =K23-L21+L22 -> 7090 | ... Z23: =Y23-Z21+Z22 -> 17667
B24: T-1天缺口 | C24: 0 | D24: 0 | E24: =D23-E21 -> 0 | F24: =E23-F21 -> -2492 | G24: =F23-G21 -> 164 | H24: =G23-H21 -> -1470 | I24: =H23-I21 -> -1381 | J24: =I23-J21 -> -1599 | K24: =J23-K21 -> 3601 | L24: =K23-L21 -> 3090 | ... Z24: =Y23-Z21 -> 12467
A25: 18.186挂机冷凝器
A26: 两器规格 | B26: 类别 | C26: 总计 | D26: 45137 | E26: 45138 | F26: 45139 | G26: 45140 | H26: 45141 | I26: 45142 | J26: 45143 | K26: 45144 | L26: 45145 | M26: 45146 | N26: 45147 | O26: 45148 | P26: 45149 | Q26: 45150 | R26: 45151 | S26: 45152 | T26: 45153 | U26: 45154 | V26: 45155 | W26: 45156 | X26: 45157 | Y26: 45158 | Z26: 45159
A27: 18.186 | B27: 挂机 | C27: =SUM(D27:L27) -> 7796 | D27: 0 | E27: 0 | F27: 0 | G27: 2300 | H27: 400 | I27: 2662 | J27: 1000 | K27: 0 | L27: 1434 | M27: 2141 | N27: 953 | O27: 2157 | P27: 1133 | Q27: 0 | R27: 0 | S27: =3155+1000 -> 4155 | T27: 3314 | U27: 3402
B28: 产能 | C28: =SUM(D28:L28) -> 10500 | D28: 1000 | E28: 500 | F28: 1000 | G28: 1000 | H28: 1000 | I28: 1000 | J28: 1000 | K28: 1000 | L28: 3000 | M28: 3000 | N28: 3000 | O28: 1000 | P28: 1000 | Q28: 1000 | R28: 1000 | S28: 3000 | T28: 3000 | U28: 1000 | V28: 1000 | W28: 1000 | X28: 1000 | Y28: 1000 | Z28: 1000
B29: 库存 | C29: 0 | D29: 500 | E29: =D29-E27+E28 -> 1000 | F29: =E29-F27+F28 -> 2000 | G29: =F29-G27+G28 -> 700 | H29: =G29-H27+H28 -> 1300 | I29: =H29-I27+I28 -> -362 | J29: =I29-J27+J28 -> -362 | K29: =J29-K27+K28 -> 638 | L29: =K29-L27+L28 -> 2204 | ... Z29: =Y29-Z27+Z28 -> 6949
B30: T-1天缺口 | C30: 0 | D30: 0 | E30: =D29-E27 -> 500 | F30: =E29-F27 -> 1000 | G30: =F29-G27 -> -300 | H30: =G29-H27 -> 300 | I30: =H29-I27 -> -1362 | J30: =I29-J27 -> -1362 | K30: =J29-K27 -> -362 | L30: =K29-L27 -> -796 | ... Z30: =Y29-Z27 -> 5949

Sheet 小单型号分析
A1: 合肥空调12月到周排产小单型号分析
A2: 结构 | B2: 分类 | C2: W49周 | G2: W50周 | K2: W51周 | O2: W52周 | S2: W53周 | W2: W1周 | AA2: W2周 | AE2: W3周 | AI2: W4周 | AM2: W5周 | AQ2: W6周 | AU2: W9周 | AY2: W10周 | BC2: W11周
