Workbook

Sheet Sheet1
A1: W11周生产计划2.27下发
A2: 工厂 | B2: 物料号 | C2: 1088编码 | D2: 配额 | E2: 物料描述 | F2: 供应商 | G2: 不良 | H2: 工厂 | I2: 代理 | J2: 合计 | K2: 在制 | L2: 备注 | M2: 周缺口 | N2: 周合计 | O2: 合计 | P2: 2026.02.26 | Q2: 2026.02.28 | R2: 2026.03.01 | S2: 2026.03.02 | T2: 2026.03.03 | U2: 2026.03.04 | V2: 2026.03.05 | W2: 2026.03.06 | X2: 2026.03.08 | Y2: 2026.03.09 | Z2: 2026.03.10 | AA2: 2026.03.11 | AB2: T+2前一天
A3: 一厂 | B3: 0011800387D | C3: 10880029033 | D3: 30 | G3: =VLOOKUP(C3,[1]Data!$A:$K,11,FALSE) -> 106 | H3: =VLOOKUP(C3,'[1]Data (2)'!$A:$K,11,FALSE) -> 6354 | I3: =VLOOKUP(B3,'[2]2月份'!$A:$F,6,FALSE) -> 1590 | J3: =I3+H3 -> 7944 | K3: =VLOOKUP(C3,[3]保留到5!$A:$B,2,FALSE) -> 22162 | L3: 待排产2W，2/10，2/11入库 | M3: =K3+J3-N3 -> -68239 | N3: =SUM(P3:AA3) -> 98345 | O3: =SUM(P3:AB3) -> 125321 | P3: 6166 | Q3: 5125 | R3: 10846 | S3: 14433 | T3: 6387 | U3: 18389 | V3: 11708 | W3: 3468 | X3: 5115 | Y3: 4883 | Z3: 11335 | AA3: 490 | AB3: 26976
A4: 一厂 | B4: 0011800537C | C4: =VLOOKUP(B4,'[4]项目编码 '!$B$1:$C$65536,2,FALSE) -> 10880017949 | D4: =VLOOKUP(B4,[5]sheet!$C$1:$H$65536,6,FALSE) -> 70 | E4: =VLOOKUP(B:B,[6]配额0227!$A:$B,2,0) -> 室内电脑板-CEM-1 | F4: =VLOOKUP(B:B,'[7]厂家配额 (新)'!$A$1:$C$65536,3,0) -> 和而泰/领智// | G4: =VLOOKUP(C4,[1]Data!$A:$K,11,FALSE) -> 6 | I4: =VLOOKUP(B4,'[2]2月份'!$A:$F,6,FALSE) -> 1409 | J4: =I4+H4 -> 1409 | K4: =VLOOKUP(C4,[3]保留到5!$A:$B,2,FALSE) -> 9011 | L4: 待排产1.5W，9/10/11入5K | M4: =K4+J4-N4 -> -3891 | N4: =SUM(P4:AA4) -> 14311 | O4: =SUM(P4:AB4) -> 32658 | P4: 2402 | Q4: 2254 | R4: 1130 | S4: 0 | T4: 3634 | U4: 942 | V4: 699 | W4: 371 | X4: 1600 | Y4: 0 | Z4: 1279 | AA4: 0 | AB4: 18347
A5: 一厂 | B5: 0011800630J | C5: =VLOOKUP(B5,'[4]项目编码 '!$B$1:$C$65536,2,FALSE) -> 10880017527 | D5: =VLOOKUP(B5,[5]sheet!$C$1:$H$65536,6,FALSE) -> 70 | E5: =VLOOKUP(B:B,[6]配额0227!$A:$B,2,0) -> 室内电脑板-CEM-1室内电脑板俄罗斯07/09/12P系列室内电脑板 | F5: =VLOOKUP(B:B,'[7]厂家配额 (新)'!$A$1:$C$65536,3,0) -> 和而泰/领智// | G5: =VLOOKUP(C5,[1]Data!$A:$K,11,FALSE) -> 1 | I5: =VLOOKUP(B5,'[2]2月份'!$A:$F,6,FALSE) -> 898 | J5: =I5+H5 -> 898 | K5: =VLOOKUP(C5,[3]保留到5!$A:$B,2,FALSE) -> 3200 | M5: =K5+J5-N5 -> 3289 | N5: =SUM(P5:AA5) -> 809 | O5: =SUM(P5:AB5) -> 5855 | P5: 0 | Q5: 230 | R5: 579 | S5: 0 | T5: 0 | U5: 0 | V5: 0 | W5: 0 | X5: 0 | Y5: 0 | Z5: 0 | AA5: 0 | AB5: 5046
A6: 一厂 | B6: 0011800630K | C6: =VLOOKUP(B6,'[4]项目编码 '!$B$1:$C$65536,2,FALSE) -> 10880017516 | D6: =VLOOKUP(B6,[5]sheet!$C$1:$H$65536,6,FALSE) -> 70 | E6: =VLOOKUP(B:B,[6]配额0227!$A:$B,2,0) -> 室内电脑板-CEM-1室内电脑板 | F6: =VLOOKUP(B:B,'[7]厂家配额 (新)'!$A$1:$C$65536,3,0) -> 和而泰/领智// | G6: =VLOOKUP(C6,[1]Data!$A:$K,11,FALSE) -> 315 | H6: =VLOOKUP(C6,'[1]Data (2)'!$A:$K,11,FALSE) -> 4 | I6: =VLOOKUP(B6,'[2]2月份'!$A:$F,6,FALSE) -> 1264 | J6: =I6+H6 -> 1268 | K6: =VLOOKUP(C6,[3]保留到5!$A:$B,2,FALSE) -> 1000 | M6: =K6+J6-N6 -> 1028 | N6: =SUM(P6:AA6) -> 1240 | O6: =SUM(P6:AB6) -> 1990 | P6: 0 | Q6: 660 | R6: 0 | S6: 0 | T6: 0 | U6: 0 | V6: 580 | W6: 0 | X6: 0 | Y6: 0 | Z6: 0 | AA6: 0 | AB6: 750
A7: 一厂 | B7: 0011800630L | C7: =VLOOKUP(B7,'[4]项目编码 '!$B$1:$C$65536,2,FALSE) -> 10880017525 | D7: =VLOOKUP(B7,[5]sheet!$C$1:$H$65536,6,FALSE) -> 70 | E7: =VLOOKUP(B:B,[6]配额0227!$A:$B,2,0) -> 室内电脑板-CEM-1室内电脑板泰国09/12P系列定频室内电脑板 | F7: =VLOOKUP(B:B,'[7]厂家配额 (新)'!$A$1:$C$65536,3,0) -> 和而泰/领智// | I7: =VLOOKUP(B7,'[2]2月份'!$A:$F,6,FALSE) -> 893 | J7: =I7+H7 -> 893 | K7: =VLOOKUP(C7,[3]保留到5!$A:$B,2,FALSE) -> 1000 | L7: 在制3/1入库 | M7: =K7+J7-N7 -> -198 | N7: =SUM(P7:AA7) -> 2091 | O7: =SUM(P7:AB7) -> 4945 | P7: 0 | Q7: 0 | R7: 0 | S7: 1821 | T7: 0 | U7: 0 | V7: 0 | W7: 270 | X7: 0 | Y7: 0 | Z7: 0 | AA7: 0 | AB7: 2854
A8: 一厂 | B8: 0011800630M | C8: =VLOOKUP(B8,'[4]项目编码 '!$B$1:$C$65536,2,FALSE) -> 10880017524 | D8: =VLOOKUP(B8,[5]sheet!$C$1:$H$65536,6,FALSE) -> 70 | E8: =VLOOKUP(B:B,[6]配额0227!$A:$B,2,0) -> 室内电脑板-CEM-1室内电脑板俄罗斯07/09/12P系列室内电脑板 | F8: =VLOOKUP(B:B,'[7]厂家配额 (新)'!$A$1:$C$65536,3,0) -> 和而泰/领智// | I8: =VLOOKUP(B8,'[2]2月份'!$A:$F,6,FALSE) -> 885 | J8: =I8+H8 -> 885 | K8: =VLOOKUP(C8,[3]保留到5!$A:$B,2,FALSE) -> 900 | L8: 待排产4500，3/11入库 | M8: =K8+J8-N8 -> 340 | N8: =SUM(P8:AA8) -> 1445 | O8: =SUM(P8:AB8) -> 6470 | P8: 100 | Q8: 382 | R8: 0 | S8: 0 | T8: 115 | U8: 0 | V8: 0 | W8: 848 | X8: 0 | Y8: 0 | Z8: 0 | AA8: 0 | AB8: 5025
A9: 二厂 | B9: 0011800630P | C9: =VLOOKUP(B9,'[4]项目编码 '!$B$1:$C$65536,2,FALSE) -> 10880017526 | D9: =VLOOKUP(B9,[5]sheet!$C$1:$H$65536,6,FALSE) -> 70 | E9: =VLOOKUP(B:B,[6]配额0227!$A:$B,2,0) -> 室内电脑板-CEM-1室内电脑板(压敏、保险和继电器防爆)印尼290项目室内电脑 | F9: =VLOOKUP(B:B,'[7]厂家配额 (新)'!$A$1:$C$65536,3,0) -> 和而泰/领智// | I9: =VLOOKUP(B9,'[2]2月份'!$A:$F,6,FALSE) -> 1008 | J9: =I9+H9 -> 1008 | M9: =K9+J9-N9 -> 838 | N9: =SUM(P9:AA9) -> 170 | O9: =SUM(P9:AB9) -> 170 | P9: 0 | Q9: 0 | R9: 0 | S9: 0 | T9: 170 | U9: 0 | V9: 0 | W9: 0 | X9: 0 | Y9: 0 | Z9: 0 | AA9: 0 | AB9: 0
A10: 二厂 | B10: 0011800630S | C10: =VLOOKUP(B10,'[4]项目编码 '!$B$1:$C$65536,2,FALSE) -> 10880020222 | D10: =VLOOKUP(B10,[5]sheet!$C$1:$H$65536,6,FALSE) -> 30 | E10: =VLOOKUP(B:B,[6]配额0227!$A:$B,2,0) -> 室内电脑板-/ | F10: =VLOOKUP(B:B,'[7]厂家配额 (新)'!$A$1:$C$65536,3,0) -> 航嘉/和而泰// | G10: =VLOOKUP(C10,[1]Data!$A:$K,11,FALSE) -> 1 | I10: =VLOOKUP(B10,'[2]2月份'!$A:$F,6,FALSE) -> 1117 | J10: =I10+H10 -> 1117 | M10: =K10+J10-N10 -> 891 | N10: =SUM(P10:AA10) -> 226 | O10: =SUM(P10:AB10) -> 226 | P10: 0 | Q10: 0 | R10: 0 | S10: 0 | T10: 226 | U10: 0 | V10: 0 | W10: 0 | X10: 0 | Y10: 0 | Z10: 0 | AA10: 0 | AB10: 0
A11: 一厂 | B11: 0011800646A | C11: =VLOOKUP(B11,'[4]项目编码 '!$B$1:$C$65536,2,FALSE) -> 10880017530 | D11: =VLOOKUP(B11,[5]sheet!$C$1:$H$65536,6,FALSE) -> 70 | E11: =VLOOKUP(B:B,[6]配额0227!$A:$B,2,0) -> 室内电脑板-FR-4 | F11: =VLOOKUP(B:B,'[7]厂家配额 (新)'!$A$1:$C$65536,3,0) -> 和而泰/领智// | H11: =VLOOKUP(C11,'[1]Data (2)'!$A:$K,11,FALSE) -> 23 | I11: =VLOOKUP(B11,'[2]2月份'!$A:$F,6,FALSE) -> 16 | J11: =I11+H11 -> 39 | M11: =K11+J11-N11 -> 9 | N11: =SUM(P11:AA11) -> 30 | O11: =SUM(P11:AB11) -> 30 | P11: 0 | Q11: 0 | R11: 0 | S11: 0 | T11: 0 | U11: 0 | V11: 0 | W11: 30 | X11: 0 | Y11: 0 | Z11: 0 | AA11: 0 | AB11: 0

Sheet Sheet1 (3)
A1: W11周生产计划2.27下发
A2: 工厂 | B2: 物料号 | C2: 1088编码 | D2: 配额 | E2: 物料描述 | F2: 供应商 | J2: 不良 | K2: 工厂 | L2: 代理 | M2: 合计 | N2: 在制 | O2: 备注 | P2: 周缺口 | Q2: 周合计 | R2: 合计 | S2: 2026.02.26 | T2: 2026.02.28 | U2: 2026.03.01 | V2: 2026.03.02 | W2: 2026.03.03 | X2: 2026.03.04 | Y2: 2026.03.05 | Z2: 2026.03.06 | AA2: 2026.03.08 | AB2: 2026.03.09 | AC2: 2026.03.10 | AD2: 2026.03.11 | AE2: T+2前一天
A3: 一厂 | B3: 0011800387D | C3: 10880029033 | D3: 30 | G3: =VLOOKUP(B3,[8]物料价格查询导出!$B:$I,8,FALSE) -> 4.50 | H3: =I3*G3 -> 6918.75 | I3: =Q3*D3/100 -> 1537.5 | J3: =VLOOKUP(C3,[1]Data!$A:$K,11,FALSE) -> 106 | K3: =VLOOKUP(C3,'[1]Data (2)'!$A:$K,11,FALSE) -> 6354 | L3: =VLOOKUP(B3,'[2]2月份'!$A:$F,6,FALSE) -> 1590 | M3: =L3+K3 -> 7944 | N3: =VLOOKUP(C3,[3]保留到5!$A:$B,2,FALSE) -> 22162 | O3: 待排产2W，2/10，2/11入库 | P3: =N3+M3-Q3 -> 24981 | Q3: =SUM(T3) -> 5125 | R3: =SUM(S3:AE3) -> 125321 | S3: 6166 | T3: 5125 | U3: 10846 | V3: 14433 | W3: 6387 | X3: 18389 | Y3: 11708 | Z3: 3468 | AA3: 5115 | AB3: 4883 | AC3: 11335 | AD3: 490 | AE3: 26976
A4: 一厂 | B4: 0011800537C | C4: =VLOOKUP(B4,'[4]项目编码 '!$B$1:$C$65536,2,FALSE) -> 10880017949 | D4: =VLOOKUP(B4,[5]sheet!$C$1:$H$65536,6,FALSE) -> 70 | E4: =VLOOKUP(B:B,[6]配额0227!$A:$B,2,0) -> 室内电脑板-CEM-1 | F4: =VLOOKUP(B:B,'[7]厂家配额 (新)'!$A$1:$C$65536,3,0) -> 和而泰/领智// | G4: =VLOOKUP(B4,[8]物料价格查询导出!$B:$I,8,FALSE) -> 19.28 | H4: =I4*G4 -> 30419.984 | I4: =Q4*D4/100 -> 1577.8 | J4: =VLOOKUP(C4,[1]Data!$A:$K,11,FALSE) -> 6 | L4: =VLOOKUP(B4,'[2]2月份'!$A:$F,6,FALSE) -> 1409 | M4: =L4+K4 -> 1409 | N4: =VLOOKUP(C4,[3]保留到5!$A:$B,2,FALSE) -> 9011 | O4: 待排产1.5W，9/10/11入5K | P4: =N4+M4-Q4 -> 8166 | Q4: =SUM(T4) -> 2254 | R4: =SUM(S4:AE4) -> 32658 | S4: 2402 | T4: 2254 | U4: 1130 | V4: 0 | W4: 3634 | X4: 942 | Y4: 699 | Z4: 371 | AA4: 1600 | AB4: 0 | AC4: 1279 | AD4: 0 | AE4: 18347
A5: 一厂 | B5: 0011800630J | C5: =VLOOKUP(B5,'[4]项目编码 '!$B$1:$C$65536,2,FALSE) -> 10880017527 | D5: =VLOOKUP(B5,[5]sheet!$C$1:$H$65536,6,FALSE) -> 70 | E5: =VLOOKUP(B:B,[6]配额0227!$A:$B,2,0) -> 室内电脑板-CEM-1室内电脑板俄罗斯07/09/12P系列室内电脑板 | F5: =VLOOKUP(B:B,'[7]厂家配额 (新)'!$A$1:$C$65536,3,0) -> 和而泰/领智// | G5: =VLOOKUP(B5,[8]物料价格查询导出!$B:$I,8,FALSE) -> 27.66 | H5: =I5*G5 -> 4453.26 | I5: =Q5*D5/100 -> 161 | J5: =VLOOKUP(C5,[1]Data!$A:$K,11,FALSE) -> 1 | L5: =VLOOKUP(B5,'[2]2月份'!$A:$F,6,FALSE) -> 898 | M5: =L5+K5 -> 898 | N5: =VLOOKUP(C5,[3]保留到5!$A:$B,2,FALSE) -> 3200 | P5: =N5+M5-Q5 -> 3868 | Q5: =SUM(T5) -> 230 | R5: =SUM(S5:AE5) -> 5855 | S5: 0 | T5: 230 | U5: 579 | V5: 0 | W5: 0 | X5: 0 | Y5: 0 | Z5: 0 | AA5: 0 | AB5: 0 | AC5: 0 | AD5: 0 | AE5: 5046
A6: 一厂 | B6: 0011800630K | C6: =VLOOKUP(B6,'[4]项目编码 '!$B$1:$C$65536,2,FALSE) -> 10880017516 | D6: =VLOOKUP(B6,[5]sheet!$C$1:$H$65536,6,FALSE) -> 70 | E6: =VLOOKUP(B:B,[6]配额0227!$A:$B,2,0) -> 室内电脑板-CEM-1室内电脑板 | F6: =VLOOKUP(B:B,'[7]厂家配额 (新)'!$A$1:$C$65536,3,0) -> 和而泰/领智// | G6: =VLOOKUP(B6,[8]物料价格查询导出!$B:$I,8,FALSE) -> 25.65 | H6: =I6*G6 -> 11850.3 | I6: =Q6*D6/100 -> 462 | J6: =VLOOKUP(C6,[1]Data!$A:$K,11,FALSE) -> 315 | K6: =VLOOKUP(C6,'[1]Data (2)'!$A:$K,11,FALSE) -> 4 | L6: =VLOOKUP(B6,'[2]2月份'!$A:$F,6,FALSE) -> 1264 | M6: =L6+K6 -> 1268 | N6: =VLOOKUP(C6,[3]保留到5!$A:$B,2,FALSE) -> 1000 | P6: =N6+M6-Q6 -> 1608 | Q6: =SUM(T6) -> 660 | R6: =SUM(S6:AE6) -> 1990 | S6: 0 | T6: 660 | U6: 0 | V6: 0 | W6: 0 | X6: 0 | Y6: 580 | Z6: 0 | AA6: 0 | AB6: 0 | AC6: 0 | AD6: 0 | AE6: 750
A7: 一厂 | B7: 0011800630L | C7: =VLOOKUP(B7,'[4]项目编码 '!$B$1:$C$65536,2,FALSE) -> 10880017525 | D7: =VLOOKUP(B7,[5]sheet!$C$1:$H$65536,6,FALSE) -> 70 | E7: =VLOOKUP(B:B,[6]配额0227!$A:$B,2,0) -> 室内电脑板-CEM-1室内电脑板泰国09/12P系列定频室内电脑板 | F7: =VLOOKUP(B:B,'[7]厂家配额 (新)'!$A$1:$C$65536,3,0) -> 和而泰/领智// | G7: =VLOOKUP(B7,[8]物料价格查询导出!$B:$I,8,FALSE) -> 23.85 | H7: =I7*G7 -> 0 | I7: =Q7*D7/100 -> 0 | L7: =VLOOKUP(B7,'[2]2月份'!$A:$F,6,FALSE) -> 893 | M7: =L7+K7 -> 893 | N7: =VLOOKUP(C7,[3]保留到5!$A:$B,2,FALSE) -> 1000 | O7: 在制3/1入库 | P7: =N7+M7-Q7 -> 1893 | Q7: =SUM(T7) -> 0 | R7: =SUM(S7:AE7) -> 4945 | S7: 0 | T7: 0 | U7: 0 | V7: 1821 | W7: 0 | X7: 0 | Y7: 0 | Z7: 270 | AA7: 0 | AB7: 0 | AC7: 0 | AD7: 0 | AE7: 2854
A8: 一厂 | B8: 0011800630M | C8: =VLOOKUP(B8,'[4]项目编码 '!$B$1:$C$65536,2,FALSE) -> 10880017524 | D8: =VLOOKUP(B8,[5]sheet!$C$1:$H$65536,6,FALSE) -> 70 | E8: =VLOOKUP(B:B,[6]配额0227!$A:$B,2,0) -> 室内电脑板-CEM-1室内电脑板俄罗斯07/09/12P系列室内电脑板 | F8: =VLOOKUP(B:B,'[7]厂家配额 (新)'!$A$1:$C$65536,3,0) -> 和而泰/领智// | G8: =VLOOKUP(B8,[8]物料价格查询导出!$B:$I,8,FALSE) -> 27.69 | H8: =I8*G8 -> 7404.306 | I8: =Q8*D8/100 -> 267.4 | L8: =VLOOKUP(B8,'[2]2月份'!$A:$F,6,FALSE) -> 885 | M8: =L8+K8 -> 885 | N8: =VLOOKUP(C8,[3]保留到5!$A:$B,2,FALSE) -> 900 | O8: 待排产4500，3/11入库 | P8: =N8+M8-Q8 -> 1403 | Q8: =SUM(T8) -> 382 | R8: =SUM(S8:AE8) -> 6470 | S8: 100 | T8: 382 | U8: 0 | V8: 0 | W8: 115 | X8: 0 | Y8: 0 | Z8: 848 | AA8: 0 | AB8: 0 | AC8: 0 | AD8: 0 | AE8: 5025
A9: 二厂 | B9: 0011800630P | C9: =VLOOKUP(B9,'[4]项目编码 '!$B$1:$C$65536,2,FALSE) -> 10880017526 | D9: =VLOOKUP(B9,[5]sheet!$C$1:$H$65536,6,FALSE) -> 70 | E9: =VLOOKUP(B:B,[6]配额0227!$A:$B,2,0) -> 室内电脑板-CEM-1室内电脑板(压敏、保险和继电器防爆)印尼290项目室内电脑 | F9: =VLOOKUP(B:B,'[7]厂家配额 (新)'!$A$1:$C$65536,3,0) -> 和而泰/领智// | G9: =VLOOKUP(B9,[8]物料价格查询导出!$B:$I,8,FALSE) -> 25.90 | H9: =I9*G9 -> 0 | I9: =Q9*D9/100 -> 0 | L9: =VLOOKUP(B9,'[2]2月份'!$A:$F,6,FALSE) -> 1008 | M9: =L9+K9 -> 1008 | P9: =N9+M9-Q9 -> 1008 | Q9: =SUM(T9) -> 0 | R9: =SUM(S9:AE9) -> 170 | S9: 0 | T9: 0 | U9: 0 | V9: 0 | W9: 170 | X9: 0 | Y9: 0 | Z9: 0 | AA9: 0 | AB9: 0 | AC9: 0 | AD9: 0 | AE9: 0
A10: 二厂 | B10: 0011800630S | C10: =VLOOKUP(B10,'[4]项目编码 '!$B$1:$C$65536,2,FALSE) -> 10880020222 | D10: =VLOOKUP(B10,[5]sheet!$C$1:$H$65536,6,FALSE) -> 30 | E10: =VLOOKUP(B:B,[6]配额0227!$A:$B,2,0) -> 室内电脑板-/ | F10: =VLOOKUP(B:B,'[7]厂家配额 (新)'!$A$1:$C$65536,3,0) -> 航嘉/和而泰// | G10: =VLOOKUP(B10,[8]物料价格查询导出!$B:$I,8,FALSE) -> 29.25 | H10: =I10*G10 -> 0 | I10: =Q10*D10/100 -> 0 | J10: =VLOOKUP(C10,[1]Data!$A:$K,11,FALSE) -> 1 | L10: =VLOOKUP(B10,'[2]2月份'!$A:$F,6,FALSE) -> 1117 | M10: =L10+K10 -> 1117 | P10: =N10+M10-Q10 -> 1117 | Q10: =SUM(T10) -> 0 | R10: =SUM(S10:AE10) -> 226 | S10: 0 | T10: 0 | U10: 0 | V10: 0 | W10: 226 | X10: 0 | Y10: 0 | Z10: 0 | AA10: 0 | AB10: 0 | AC10: 0 | AD10: 0 | AE10: 0
A11: 一厂 | B11: 0011800646A | C11: =VLOOKUP(B11,'[4]项目编码 '!$B$1:$C$65536,2,FALSE) -> 10880017530 | D11: =VLOOKUP(B11,[5]sheet!$C$1:$H$65536,6,FALSE) -> 70 | E11: =VLOOKUP(B:B,[6]配额0227!$A:$B,2,0) -> 室内电脑板-FR-4 | F11: =VLOOKUP(B:B,'[7]厂家配额 (新)'!$A$1:$C$65536,3,0) -> 和而泰/领智// | G11: =VLOOKUP(B11,[8]物料价格查询导出!$B:$I,8,FALSE) -> 40.69 | H11: =I11*G11 -> 0 | I11: =Q11*D11/100 -> 0 | K11: =VLOOKUP(C11,'[1]Data (2)'!$A:$K,11,FALSE) -> 23 | L11: =VLOOKUP(B11,'[2]2月份'!$A:$F,6,FALSE) -> 16 | M11: =L11+K11 -> 39 | P11: =N11+M11-Q11 -> 39 | Q11: =SUM(T11) -> 0 | R11: =SUM(S11:AE11) -> 30 | S11: 0 | T11: 0 | U11: 0 | V11: 0 | W11: 0 | X11: 0 | Y11: 0 | Z11: 30 | AA11: 0 | AB11: 0 | AC11: 0 | AD11: 0 | AE11: 0
A12: 一厂 | B12: 0011800646D | C12: =VLOOKUP(B12,'[4]项目编码 '!$B$1:$C$65536,2,FALSE) -> 10880017531 | D12: =VLOOKUP(B12,[5]sheet!$C$1:$H$65536,6,FALSE) -> 70 | E12: =VLOOKUP(B:B,[6]配额0227!$A:$B,2,0) -> 室内电脑板-FR-4--- | F12: =VLOOKUP(B:B,'[7]厂家配额 (新)'!$A$1:$C$65536,3,0) -> 和而泰/领智// | G12: =VLOOKUP(B12,[8]物料价格查询导出!$B:$I,8,FALSE) -> 40.97 | H12: =I12*G12 -> 0 | I12: =Q12*D12/100 -> 0 | J12: =VLOOKUP(C12,[1]Data!$A:$K,11,FALSE) -> 1 | L12: =VLOOKUP(B12,'[2]2月份'!$A:$F,6,FALSE) -> 9 | M12: =L12+K12 -> 9 | O12: 李灿库存758 | P12: =N12+M12-Q12 -> 9 | Q12: =SUM(T12) -> 0 | R12: =SUM(S12:AE12) -> 10 | S12: 0 | T12: 0 | U12: 0 | V12: 0 | W12: 0 | X12: 0 | Y12: 0 | Z12: 0 | AA12: 0 | AB12: 0 | AC12: 10 | AD12: 0 | AE12: 0
A13: 一厂 | B13: 0011800646L | C13: =VLOOKUP(B13,'[4]项目编码 '!$B$1:$C$65536,2,FALSE) -> 10880017536 | D13: =VLOOKUP(B13,[5]sheet!$C$1:$H$65536,6,FALSE) -> 70 | E13: =VLOOKUP(B:B,[6]配额0227!$A:$B,2,0) -> 室内电脑板-FR-4/ | F13: =VLOOKUP(B:B,'[7]厂家配额 (新)'!$A$1:$C$65536,3,0) -> 和而泰/领智// | G13: =VLOOKUP(B13,[8]物料价格查询导出!$B:$I,8,FALSE) -> 40.97 | H13: =I13*G13 -> 0 | I13: =Q13*D13/100 -> 0 | J13: =VLOOKUP(C13,[1]Data!$A:$K,11,FALSE) -> 70 | K13: =VLOOKUP(C13,'[1]Data (2)'!$A:$K,11,FALSE) -> 202 | L13: =VLOOKUP(B13,'[2]2月份'!$A:$F,6,FALSE) -> 16 | M13: =L13+K13 -> 218 | N13: =VLOOKUP(C13,[3]保留到5!$A:$B,2,FALSE) -> 1800 | O13: 李灿库存1704 | P13: =N13+M13-Q13 -> 2018 | Q13: =SUM(T13) -> 0 | R13: =SUM(S13:AE13) -> 3405 | S13: 0 | T13: 0 | U13: 0 | V13: 1650 | W13: 0 | X13: 1650 | Y13: 0 | Z13: 0 | AA13: 5 | AB13: 0 | AC13: 0 | AD13: 0 | AE13: 100
A14: 一厂 | B14: 0011800697AC | C14: =VLOOKUP(B14,'[4]项目编码 '!$B$1:$C$65536,2,FALSE) -> 10880034629 | D14: =VLOOKUP(B14,[5]sheet!$C$1:$H$65536,6,FALSE) -> 30 | E14: =VLOOKUP(B:B,[6]配额0227!$A:$B,2,0) -> 室内电脑板-CEM-1 | F14: =VLOOKUP(B:B,'[7]厂家配额 (新)'!$A$1:$C$65536,3,0) -> 领智/和而泰// | G14: =VLOOKUP(B14,[8]物料价格查询导出!$B:$I,8,FALSE) -> 36.99 | H14: =I14*G14 -> 0 | I14: =Q14*D14/100 -> 0 | L14: =VLOOKUP(B14,'[2]2月份'!$A:$F,6,FALSE) -> 48 | M14: =L14+K14 -> 48 | P14: =N14+M14-Q14 -> 48 | Q14: =SUM(T14) -> 0 | R14: =SUM(S14:AE14) -> 3 | S14: 0 | T14: 0 | U14: 3 | V14: 0 | W14: 0 | X14: 0 | Y14: 0 | Z14: 0 | AA14: 0 | AB14: 0 | AC14: 0 | AD14: 0 | AE14: 0
A15: 一厂 | B15: 0011800722GCH | C15: =VLOOKUP(B15,'[4]项目编码 '!$B$1:$C$65536,2,FALSE) -> 10880036513 | D15: =VLOOKUP(B15,[5]sheet!$C$1:$H$65536,6,FALSE) -> 70 | E15: =VLOOKUP(B:B,[6]配额0227!$A:$B,2,0) -> 室内电脑板-CEM-1 | F15: =VLOOKUP(B:B,'[7]厂家配额 (新)'!$A$1:$C$65536,3,0) -> 和而泰/康美特// | G15: =VLOOKUP(B15,[8]物料价格查询导出!$B:$I,8,FALSE) -> 21.47 | H15: =I15*G15 -> 0 | I15: =Q15*D15/100 -> 0 | M15: =L15+K15 -> 0 | O15: 按配额交付满足 | P15: =N15+M15-Q15 -> 0 | Q15: =SUM(T15) -> 0 | R15: =SUM(S15:AE15) -> 1319 | S15: 1319 | T15: 0 | U15: 0 | V15: 0 | W15: 0 | X15: 0 | Y15: 0 | Z15: 0 | AA15: 0 | AB15: 0 | AC15: 0 | AD15: 0 | AE15: 0
A16: 一厂 | B16: 0011800722GCHA | C16: =VLOOKUP(B16,'[4]项目编码 '!$B$1:$C$65536,2,FALSE) -> 10880036514 | D16: =VLOOKUP(B16,[5]sheet!$C$1:$H$65536,6,FALSE) -> 70 | E16: =VLOOKUP(B:B,[6]配额0227!$A:$B,2,0) -> 室内电脑板-CEM-1 | F16: =VLOOKUP(B:B,'[7]厂家配额 (新)'!$A$1:$C$65536,3,0) -> 和而泰/康美特// | G16: =VLOOKUP(B16,[8]物料价格查询导出!$B:$I,8,FALSE) -> 21.95 | H16: =I16*G16 -> 0 | I16: =Q16*D16/100 -> 0 | L16: =VLOOKUP(B16,'[2]2月份'!$A:$F,6,FALSE) -> 149 | M16: =L16+K16 -> 149 | O16: 按配额交付满足 | P16: =N16+M16-Q16 -> 149 | Q16: =SUM(T16) -> 0 | R16: =SUM(S16:AE16) -> 1979 | S16: 1979 | T16: 0 | U16: 0 | V16: 0 | W16: 0 | X16: 0 | Y16: 0 | Z16: 0 | AA16: 0 | AB16: 0 | AC16: 0 | AD16: 0 | AE16: 0
A17: 一厂 | B17: 0011800807 | C17: =VLOOKUP(B17,'[4]项目编码 '!$B$1:$C$65536,2,FALSE) -> 10880018093 | D17: =VLOOKUP(B17,[5]sheet!$C$1:$H$65536,6,FALSE) -> 70 | E17: =VLOOKUP(B:B,[6]配额0227!$A:$B,2,0) -> 室内电脑板-FR-4 | F17: =VLOOKUP(B:B,'[7]厂家配额 (新)'!$A$1:$C$65536,3,0) -> 和而泰/领智// | G17: =VLOOKUP(B17,[8]物料价格查询导出!$B:$I,8,FALSE) -> 41.75 | H17: =I17*G17 -> 0 | I17: =Q17*D17/100 -> 0 | J17: =VLOOKUP(C17,[1]Data!$A:$K,11,FALSE) -> 6 | L17: =VLOOKUP(B17,'[2]2月份'!$A:$F,6,FALSE) -> 2398 | M17: =L17+K17 -> 2398 | P17: =N17+M17-Q17 -> 2398 | Q17: =SUM(T17) -> 0 | R17: =SUM(S17:AE17) -> 180 | S17: 0 | T17: 0 | U17: 0 | V17: 0 | W17: 0 | X17: 0 | Y17: 0 | Z17: 30 | AA17: 0 | AB17: 0 | AC17: 0 | AD17: 0 | AE17: 150
A18: 二厂 | B18: 0011800977AA | C18: =VLOOKUP(B18,'[4]项目编码 '!$B$1:$C$65536,2,FALSE) -> 10880034093 | D18: =VLOOKUP(B18,[5]sheet!$C$1:$H$65536,6,FALSE) -> 30 | E18: =VLOOKUP(B:B,[6]配额0227!$A:$B,2,0) -> 室内电脑板-FR-4 | F18: =VLOOKUP(B:B,'[7]厂家配额 (新)'!$A$1:$C$65536,3,0) -> 领智/和而泰// | G18: =VLOOKUP(B18,[8]物料价格查询导出!$B:$I,8,FALSE) -> 29.30 | H18: =I18*G18 -> 15470.4 | I18: =Q18*D18/100 -> 528 | L18: =VLOOKUP(B18,'[2]2月份'!$A:$F,6,FALSE) -> 27 | M18: =L18+K18 -> 27 | O18: 李灿全交 | P18: =N18+M18-Q18 -> -1733 | Q18: =SUM(T18) -> 1760 | R18: =SUM(S18:AE18) -> 1760 | S18: 0 | T18: 1760 | U18: 0 | V18: 0 | W18: 0 | X18: 0 | Y18: 0 | Z18: 0 | AA18: 0 | AB18: 0 | AC18: 0 | AD18: 0 | AE18: 0
A19: 一厂 | B19: 0011800977K | C19: =VLOOKUP(B19,'[4]项目编码 '!$B$1:$C$65536,2,FALSE) -> 10880020031 | D19: =VLOOKUP(B19,[5]sheet!$C$1:$H$65536,6,FALSE) -> 100 | E19: =VLOOKUP(B:B,[6]配额0227!$A:$B,2,0) -> 室内电脑板-CEM-1/ | F19: =VLOOKUP(B:B,'[7]厂家配额 (新)'!$A$1:$C$65536,3,0) -> 和而泰 | G19: =VLOOKUP(B19,[8]物料价格查询导出!$B:$I,8,FALSE) -> 28.53 | H19: =I19*G19 -> 855.9 | I19: =Q19*D19/100 -> 30 | L19: =VLOOKUP(B19,'[2]2月份'!$A:$F,6,FALSE) -> 687 | M19: =L19+K19 -> 687 | P19: =N19+M19-Q19 -> 657 | Q19: =SUM(T19) -> 30 | R19: =SUM(S19:AE19) -> 603 | S19: 0 | T19: 30 | U19: 36 | V19: 0 | W19: 0 | X19: 2 | Y19: 0 | Z19: 0 | AA19: 0 | AB19: 0 | AC19: 0 | AD19: 0 | AE19: 535
A20: 一厂 | B20: 0011800977P | C20: =VLOOKUP(B20,'[4]项目编码 '!$B$1:$C$65536,2,FALSE) -> 10880027924 | D20: =VLOOKUP(B20,[5]sheet!$C$1:$H$65536,6,FALSE) -> 100 | E20: =VLOOKUP(B:B,[6]配额0227!$A:$B,2,0) -> 室内电脑板-CEM-1/ | F20: =VLOOKUP(B:B,'[7]厂家配额 (新)'!$A$1:$C$65536,3,0) -> 和而泰 | G20: =VLOOKUP(B20,[8]物料价格查询导出!$B:$I,8,FALSE) -> 27.96 | H20: =I20*G20 -> 27680.4 | I20: =Q20*D20/100 -> 990 | J20: =VLOOKUP(C20,[1]Data!$A:$K,11,FALSE) -> 1 | L20: 2029 | M20: =L20+K20 -> 2029 | P20: =N20+M20-Q20 -> 1039 | Q20: =SUM(T20) -> 990 | R20: =SUM(S20:AE20) -> 1320 | S20: 0 | T20: 990 | U20: 0 | V20: 0 | W20: 0 | X20: 0 | Y20: 0 | Z20: 0 | AA20: 0 | AB20: 0 | AC20: 0 | AD20: 0 | AE20: 330
A21: 一厂 | B21: 0011800977T | C21: =VLOOKUP(B21,'[4]项目编码 '!$B$1:$C$65536,2,FALSE) -> 10880030203 | D21: =VLOOKUP(B21,[5]sheet!$C$1:$H$65536,6,FALSE) -> 100 | E21: =VLOOKUP(B:B,[6]配额0227!$A:$B,2,0) -> 室内电脑板-CEM-1/ | F21: =VLOOKUP(B:B,'[7]厂家配额 (新)'!$A$1:$C$65536,3,0) -> 和而泰 | G21: =VLOOKUP(B21,[8]物料价格查询导出!$B:$I,8,FALSE) -> 28.41 | H21: =I21*G21 -> 1420.5 | I21: =Q21*D21/100 -> 50 | J21: =VLOOKUP(C21,[1]Data!$A:$K,11,FALSE) -> 1 | L21: =VLOOKUP(B21,'[2]2月份'!$A:$F,6,FALSE) -> 320 | M21: =L21+K21 -> 320 | N21: =VLOOKUP(C21,[3]保留到5!$A:$B,2,FALSE) -> 2000 | P21: =N21+M21-Q21 -> 2270 | Q21: =SUM(T21) -> 50 | R21: =SUM(S21:AE21) -> 2256 | S21: 108 | T21: 50 | U21: 30 | V21: 0 | W21: 0 | X21: 0 | Y21: 0 | Z21: 0 | AA21: 0 | AB21: 0 | AC21: 0 | AD21: 0 | AE21: 2068
A22: 一厂 | B22: 0011800980E | C22: =VLOOKUP(B22,'[4]项目编码 '!$B$1:$C$65536,2,FALSE) -> 10880029054 | D22: =VLOOKUP(B22,[5]sheet!$C$1:$H$65536,6,FALSE) -> 30 | E22: =VLOOKUP(B:B,[6]配额0227!$A:$B,2,0) -> 室内电脑板-FR-4P平台内机板 | F22: =VLOOKUP(B:B,'[7]厂家配额 (新)'!$A$1:$C$65536,3,0) -> 领智/和而泰// | G22: =VLOOKUP(B22,[8]物料价格查询导出!$B:$I,8,FALSE) -> 56.52 | H22: =I22*G22 -> 0 | I22: =Q22*D22/100 -> 0 | L22: =VLOOKUP(B22,'[2]2月份'!$A:$F,6,FALSE) -> 34 | M22: =L22+K22 -> 34 | N22: =VLOOKUP(C22,[3]保留到5!$A:$B,2,FALSE) -> 600 | P22: =N22+M22-Q22 -> 634 | Q22: =SUM(T22) -> 0 | R22: =SUM(S22:AE22) -> 163 | S22: 0 | T22: 0 | U22: 51 | V22: 0 | W22: 0 | X22: 0 | Y22: 0 | Z22: 0 | AA22: 0 | AB22: 0 | AC22: 0 | AD22: 0 | AE22: 112
A23: 一厂 | B23: 0011800980F | C23: =VLOOKUP(B23,'[4]项目编码 '!$B$1:$C$65536,2,FALSE) -> 10880029055 | D23: =VLOOKUP(B23,[5]sheet!$C$1:$H$65536,6,FALSE) -> 30 | E23: =VLOOKUP(B:B,[6]配额0227!$A:$B,2,0) -> 室内电脑板-FR-4P平台内机板 | F23: =VLOOKUP(B:B,'[7]厂家配额 (新)'!$A$1:$C$65536,3,0) -> 领智/和而泰// | G23: =VLOOKUP(B23,[8]物料价格查询导出!$B:$I,8,FALSE) -> 59.22 | H23: =I23*G23 -> 0 | I23: =Q23*D23/100 -> 0 | M23: =L23+K23 -> 0 | O23: 李灿全交 | P23: =N23+M23-Q23 -> 0 | Q23: =SUM(T23) -> 0 | R23: =SUM(S23:AE23) -> 314 | S23: 0 | T23: 0 | U23: 0 | V23: 0 | W23: 0 | X23: 0 | Y23: 0 | Z23: 0 | AA23: 127 | AB23: 0 | AC23: 0 | AD23: 0 | AE23: 187
A24: 一厂 | B24: 0011800980J | C24: =VLOOKUP(B24,'[4]项目编码 '!$B$1:$C$65536,2,FALSE) -> 10880020556 | D24: =VLOOKUP(B24,[5]sheet!$C$1:$H$65536,6,FALSE) -> 100 | E24: =VLOOKUP(B:B,[6]配额0227!$A:$B,2,0) -> 室内电脑板-FR-4P平台内机板 | F24: =VLOOKUP(B:B,'[7]厂家配额 (新)'!$A$1:$C$65536,3,0) -> 和而泰 | G24: =VLOOKUP(B24,[8]物料价格查询导出!$B:$I,8,FALSE) -> 63.54 | H24: =I24*G24 -> 0 | I24: =Q24*D24/100 -> 0 | J24: =VLOOKUP(C24,[1]Data!$A:$K,11,FALSE) -> 49 | L24: =VLOOKUP(B24,'[2]2月份'!$A:$F,6,FALSE) -> 109 | M24: =L24+K24 -> 109 | N24: =VLOOKUP(C24,[3]保留到5!$A:$B,2,FALSE) -> 700 | P24: =N24+M24-Q24 -> 809 | Q24: =SUM(T24) -> 0 | R24: =SUM(S24:AE24) -> 870 | S24: 0 | T24: 0 | U24: 0 | V24: 0 | W24: 0 | X24: 0 | Y24: 0 | Z24: 0 | AA24: 50 | AB24: 50 | AC24: 720 | AD24: 0 | AE24: 50
A25: 一厂 | B25: 0011800980K | C25: =VLOOKUP(B25,'[4]项目编码 '!$B$1:$C$65536,2,FALSE) -> 10880028881 | D25: =VLOOKUP(B25,[5]sheet!$C$1:$H$65536,6,FALSE) -> 100 | E25: =VLOOKUP(B:B,[6]配额0227!$A:$B,2,0) -> 室内电脑板-FR-4P平台内机板 | F25: =VLOOKUP(B:B,'[7]厂家配额 (新)'!$A$1:$C$65536,3,0) -> 和而泰 | G25: =VLOOKUP(B25,[8]物料价格查询导出!$B:$I,8,FALSE) -> 62.53 | H25: =I25*G25 -> 0 | I25: =Q25*D25/100 -> 0 | L25: =VLOOKUP(B25,'[2]2月份'!$A:$F,6,FALSE) -> 93 | M25: =L25+K25 -> 93 | N25: =VLOOKUP(C25,[3]保留到5!$A:$B,2,FALSE) -> 1000 | P25: =N25+M25-Q25 -> 1093 | Q25: =SUM(T25) -> 0 | R25: =SUM(S25:AE25) -> 940 | S25: 0 | T25: 0 | U25: 0 | V25: 0 | W25: 0 | X25: 0 | Y25: 0 | Z25: 0 | AA25: 522 | AB25: 0 | AC25: 0 | AD25: 0 | AE25: 418
A26: 一厂 | B26: 0011801039AM | C26: =VLOOKUP(B26,'[4]项目编码 '!$B$1:$C$65536,2,FALSE) -> 10880031242 | D26: =VLOOKUP(B26,[5]sheet!$C$1:$H$65536,6,FALSE) -> 50 | E26: =VLOOKUP(B:B,[6]配额0227!$A:$B,2,0) -> 变频外电脑板-FR-4/ | F26: =VLOOKUP(B:B,'[7]厂家配额 (新)'!$A$1:$C$65536,3,0) -> 和而泰/中家智康// | G26: =VLOOKUP(B26,[8]物料价格查询导出!$B:$I,8,FALSE) -> 173.03 | H26: =I26*G26 -> 39710.385 | I26: =Q26*D26/100 -> 229.5 | J26: =VLOOKUP(C26,[1]Data!$A:$K,11,FALSE) -> 3 | K26: =VLOOKUP(C26,'[1]Data (2)'!$A:$K,11,FALSE) -> 12 | L26: =VLOOKUP(B26,'[2]2月份'!$A:$F,6,FALSE) -> 525 | M26: =L26+K26 -> 537 | O26: 待排产300,3/11入库 | P26: =N26+M26-Q26 -> 78 | Q26: =SUM(T26) -> 459 | R26: =SUM(S26:AE26) -> 1264 | S26: 0 | T26: 459 | U26: 165 | V26: 0 | W26: 0 | X26: 100 | Y26: 0 | Z26: 0 | AA26: 0 | AB26: 0 | AC26: 120 | AD26: 0 | AE26: 420
A27: 一厂 | B27: 0011801039AN | C27: =VLOOKUP(B27,'[4]项目编码 '!$B$1:$C$65536,2,FALSE) -> 10880031243 | D27: =VLOOKUP(B27,[5]sheet!$C$1:$H$65536,6,FALSE) -> 50 | E27: =VLOOKUP(B:B,[6]配额0227!$A:$B,2,0) -> 变频外电脑板-FR-4/ | F27: =VLOOKUP(B:B,'[7]厂家配额 (新)'!$A$1:$C$65536,3,0) -> 和而泰/中家智康// | G27: =VLOOKUP(B27,[8]物料价格查询导出!$B:$I,8,FALSE) -> 179.50 | H27: =I27*G27 -> 0 | I27: =Q27*D27/100 -> 0 | J27: =VLOOKUP(C27,[1]Data!$A:$K,11,FALSE) -> 3 | L27: =VLOOKUP(B27,'[2]2月份'!$A:$F,6,FALSE) -> 801 | M27: =L27+K27 -> 801 | P27: =N27+M27-Q27 -> 801 | Q27: =SUM(T27) -> 0 | R27: =SUM(S27:AE27) -> 872 | S27: 0 | T27: 0 | U27: 0 | V27: 380 | W27: 312 | X27: 0 | Y27: 0 | Z27: 0 | AA27: 0 | AB27: 0 | AC27: 80 | AD27: 0 | AE27: 100
A28: 二厂 | B28: 0011801039AU | D28: =VLOOKUP(B28,[5]sheet!$C$1:$H$65536,6,FALSE) -> 50 | E28: =VLOOKUP(B:B,[6]配额0227!$A:$B,2,0) -> 变频外电脑板-FR-4 | F28: =VLOOKUP(B:B,'[7]厂家配额 (新)'!$A$1:$C$65536,3,0) -> 和而泰/中家智康// | G28: =VLOOKUP(B28,[8]物料价格查询导出!$B:$I,8,FALSE) -> 179.19 | H28: =I28*G28 -> 0 | I28: =Q28*D28/100 -> 0 | M28: =L28+K28 -> 0 | O28: 刘培建交付 | P28: =N28+M28-Q28 -> 0 | Q28: =SUM(T28) -> 0 | R28: =SUM(S28:AE28) -> 6 | S28: 0 | T28: 0 | U28: 0 | V28: 6 | W28: 0 | X28: 0 | Y28: 0 | Z28: 0 | AA28: 0 | AB28: 0 | AC28: 0 | AD28: 0 | AE28: 0
A29: 二厂 | B29: 0011801039AV | D29: =VLOOKUP(B29,[5]sheet!$C$1:$H$65536,6,FALSE) -> 50 | E29: =VLOOKUP(B:B,[6]配额0227!$A:$B,2,0) -> 变频外电脑板-FR-4 | F29: =VLOOKUP(B:B,'[7]厂家配额 (新)'!$A$1:$C$65536,3,0) -> 中家/和而泰// | G29: =VLOOKUP(B29,[8]物料价格查询导出!$B:$I,8,FALSE) -> 202.60 | H29: =I29*G29 -> 0 | I29: =Q29*D29/100 -> 0 | M29: =L29+K29 -> 0 | O29: 刘培建交付 | P29: =N29+M29-Q29 -> 0 | Q29: =SUM(T29) -> 0 | R29: =SUM(S29:AE29) -> 6 | S29: 0 | T29: 0 | U29: 0 | V29: 6 | W29: 0 | X29: 0 | Y29: 0 | Z29: 0 | AA29: 0 | AB29: 0 | AC29: 0 | AD29: 0 | AE29: 0
A30: 一厂 | B30: 0011801048AE | C30: =VLOOKUP(B30,'[4]项目编码 '!$B$1:$C$65536,2,FALSE) -> 10880030607 | D30: =VLOOKUP(B30,[5]sheet!$C$1:$H$65536,6,FALSE) -> 70 | E30: =VLOOKUP(B:B,[6]配额0227!$A:$B,2,0) -> 变频外电脑板-FR-4/ | F30: =VLOOKUP(B:B,'[7]厂家配额 (新)'!$A$1:$C$65536,3,0) -> 和而泰/中家智康// | G30: =VLOOKUP(B30,[8]物料价格查询导出!$B:$I,8,FALSE) -> 131.77 | H30: =I30*G30 -> 0 | I30: =Q30*D30/100 -> 0 | J30: =VLOOKUP(C30,[1]Data!$A:$K,11,FALSE) -> 6 | L30: =VLOOKUP(B30,'[2]2月份'!$A:$F,6,FALSE) -> 380 | M30: =L30+K30 -> 380 | N30: =VLOOKUP(C30,[3]保留到5!$A:$B,2,FALSE) -> 300 | O30: 待排产2K，3/4入库 | P30: =N30+M30-Q30 -> 680 | Q30: =SUM(T30) -> 0 | R30: =SUM(S30:AE30) -> 2677 | S30: 0 | T30: 0 | U30: 580 | V30: 0 | W30: 0 | X30: 0 | Y30: 1517 | Z30: 293 | AA30: 0 | AB30: 0 | AC30: 0 | AD30: 0 | AE30: 287
A31: 一厂 | B31: 0011801048AF | C31: =VLOOKUP(B31,'[4]项目编码 '!$B$1:$C$65536,2,FALSE) -> 10880030608 | D31: =VLOOKUP(B31,[5]sheet!$C$1:$H$65536,6,FALSE) -> 70 | E31: =VLOOKUP(B:B,[6]配额0227!$A:$B,2,0) -> 变频外电脑板-FR-4/ | F31: =VLOOKUP(B:B,'[7]厂家配额 (新)'!$A$1:$C$65536,3,0) -> 和而泰/中家智康// | G31: =VLOOKUP(B31,[8]物料价格查询导出!$B:$I,8,FALSE) -> 132.74 | H31: =I31*G31 -> 0 | I31: =Q31*D31/100 -> 0 | J31: =VLOOKUP(C31,[1]Data!$A:$K,11,FALSE) -> 2 | L31: =VLOOKUP(B31,'[2]2月份'!$A:$F,6,FALSE) -> 1129 | M31: =L31+K31 -> 1129 | O31: 待排产2K，3/4入库 | P31: =N31+M31-Q31 -> 1129 | Q31: =SUM(T31) -> 0 | R31: =SUM(S31:AE31) -> 2485 | S31: 0 | T31: 0 | U31: 580 | V31: 0 | W31: 0 | X31: 0 | Y31: 1015 | Z31: 320 | AA31: 0 | AB31: 0 | AC31: 0 | AD31: 0 | AE31: 570
A32: 二厂 | B32: 0011801048AG | C32: =VLOOKUP(B32,'[4]项目编码 '!$B$1:$C$65536,2,FALSE) -> 10880031138 | D32: =VLOOKUP(B32,[5]sheet!$C$1:$H$65536,6,FALSE) -> 50 | E32: =VLOOKUP(B:B,[6]配额0227!$A:$B,2,0) -> 变频外电脑板-FR-4/ | F32: =VLOOKUP(B:B,'[7]厂家配额 (新)'!$A$1:$C$65536,3,0) -> 和而泰/中家智康// | G32: =VLOOKUP(B32,[8]物料价格查询导出!$B:$I,8,FALSE) -> 134.23 | H32: =I32*G32 -> 0 | I32: =Q32*D32/100 -> 0 | L32: =VLOOKUP(B32,'[2]2月份'!$A:$F,6,FALSE) -> 1 | M32: =L32+K32 -> 1 | N32: =VLOOKUP(C32,[3]保留到5!$A:$B,2,FALSE) -> 7 | O32: 中家全交 | P32: =N32+M32-Q32 -> 8 | Q32: =SUM(T32) -> 0 | R32: =SUM(S32:AE32) -> 9 | S32: 0 | T32: 0 | U32: 0 | V32: 9 | W32: 0 | X32: 0 | Y32: 0 | Z32: 0 | AA32: 0 | AB32: 0 | AC32: 0 | AD32: 0 | AE32: 0
A33: 二厂 | B33: 0011801048AH | C33: =VLOOKUP(B33,'[4]项目编码 '!$B$1:$C$65536,2,FALSE) -> 10880031139 | D33: =VLOOKUP(B33,[5]sheet!$C$1:$H$65536,6,FALSE) -> 50 | E33: =VLOOKUP(B:B,[6]配额0227!$A:$B,2,0) -> 变频外电脑板-FR-4/ | F33: =VLOOKUP(B:B,'[7]厂家配额 (新)'!$A$1:$C$65536,3,0) -> 和而泰/中家智康// | G33: =VLOOKUP(B33,[8]物料价格查询导出!$B:$I,8,FALSE) -> 134.23 | H33: =I33*G33 -> 0 | I33: =Q33*D33/100 -> 0 | L33: =VLOOKUP(B33,'[2]2月份'!$A:$F,6,FALSE) -> 20 | M33: =L33+K33 -> 20 | N33: =VLOOKUP(C33,[3]保留到5!$A:$B,2,FALSE) -> 12 | P33: =N33+M33-Q33 -> 32 | Q33: =SUM(T33) -> 0 | R33: =SUM(S33:AE33) -> 10 | S33: 0 | T33: 0 | U33: 0 | V33: 10 | W33: 0 | X33: 0 | Y33: 0 | Z33: 0 | AA33: 0 | AB33: 0 | AC33: 0 | AD33: 0 | AE33: 0
A34: 二厂 | B34: 0011801048AM | D34: =VLOOKUP(B34,[5]sheet!$C$1:$H$65536,6,FALSE) -> 50 | E34: =VLOOKUP(B:B,[6]配额0227!$A:$B,2,0) -> 变频外电脑板-FR-4 | F34: =VLOOKUP(B:B,'[7]厂家配额 (新)'!$A$1:$C$65536,3,0) -> 和而泰/中家智康// | G34: =VLOOKUP(B34,[8]物料价格查询导出!$B:$I,8,FALSE) -> 138.34 | H34: =I34*G34 -> 0 | I34: =Q34*D34/100 -> 0 | M34: =L34+K34 -> 0 | O34: 刘培建交付 | P34: =N34+M34-Q34 -> 0 | Q34: =SUM(T34) -> 0 | R34: =SUM(S34:AE34) -> 6 | S34: 0 | T34: 0 | U34: 0 | V34: 6 | W34: 0 | X34: 0 | Y34: 0 | Z34: 0 | AA34: 0 | AB34: 0 | AC34: 0 | AD34: 0 | AE34: 0
A35: 二厂 | B35: 0011801048AN | D35: =VLOOKUP(B35,[5]sheet!$C$1:$H$65536,6,FALSE) -> 50 | E35: =VLOOKUP(B:B,[6]配额0227!$A:$B,2,0) -> 变频外电脑板-FR-4 | F35: =VLOOKUP(B:B,'[7]厂家配额 (新)'!$A$1:$C$65536,3,0) -> 中家/和而泰// | G35: =VLOOKUP(B35,[8]物料价格查询导出!$B:$I,8,FALSE) -> 138.34 | H35: =I35*G35 -> 0 | I35: =Q35*D35/100 -> 0 | M35: =L35+K35 -> 0 | O35: 刘培建交付 | P35: =N35+M35-Q35 -> 0 | Q35: =SUM(T35) -> 0 | R35: =SUM(S35:AE35) -> 6 | S35: 0 | T35: 0 | U35: 0 | V35: 6 | W35: 0 | X35: 0 | Y35: 0 | Z35: 0 | AA35: 0 | AB35: 0 | AC35: 0 | AD35: 0 | AE35: 0
A36: 一厂 | B36: 0011801123H | C36: =VLOOKUP(B36,'[4]项目编码 '!$B$1:$C$65536,2,FALSE) -> 10880028306 | D36: =VLOOKUP(B36,[5]sheet!$C$1:$H$65536,6,FALSE) -> 100 | E36: =VLOOKUP(B:B,[6]配额0227!$A:$B,2,0) -> 室内电脑板-FR-4136*165 | F36: =VLOOKUP(B:B,'[7]厂家配额 (新)'!$A$1:$C$65536,3,0) -> 和而泰 | G36: =VLOOKUP(B36,[8]物料价格查询导出!$B:$I,8,FALSE) -> 42.40 | H36: =I36*G36 -> 38584 | I36: =Q36*D36/100 -> 910 | J36: =VLOOKUP(C36,[1]Data!$A:$K,11,FALSE) -> 46 | L36: =VLOOKUP(B36,'[2]2月份'!$A:$F,6,FALSE) -> 1575 | M36: =L36+K36 -> 1575 | O36: 待排产6K，3/3入库2K,3/9入库4K | P36: =N36+M36-Q36 -> 665 | Q36: =SUM(T36) -> 910 | R36: =SUM(S36:AE36) -> 5267 | S36: 0 | T36: 910 | U36: 0 | V36: 360 | W36: 0 | X36: 665 | Y36: 0 | Z36: 140 | AA36: 60 | AB36: 855 | AC36: 1215 | AD36: 0 | AE36: 1062
A37: 一厂 | B37: 0011801123J | C37: =VLOOKUP(B37,'[4]项目编码 '!$B$1:$C$65536,2,FALSE) -> 10880028307 | D37: =VLOOKUP(B37,[5]sheet!$C$1:$H$65536,6,FALSE) -> 100 | E37: =VLOOKUP(B:B,[6]配额0227!$A:$B,2,0) -> 室内电脑板-FR-4136*165 | F37: =VLOOKUP(B:B,'[7]厂家配额 (新)'!$A$1:$C$65536,3,0) -> 和而泰 | G37: =VLOOKUP(B37,[8]物料价格查询导出!$B:$I,8,FALSE) -> 42.40 | H37: =I37*G37 -> 2332 | I37: =Q37*D37/100 -> 55 | L37: =VLOOKUP(B37,'[2]2月份'!$A:$F,6,FALSE) -> 311 | M37: =L37+K37 -> 311 | N37: =VLOOKUP(C37,[3]保留到5!$A:$B,2,FALSE) -> 796 | P37: =N37+M37-Q37 -> 1052 | Q37: =SUM(T37) -> 55 | R37: =SUM(S37:AE37) -> 1558 | S37: 0 | T37: 55 | U37: 0 | V37: 30 | W37: 125 | X37: 0 | Y37: 353 | Z37: 200 | AA37: 50 | AB37: 0 | AC37: 0 | AD37: 0 | AE37: 745
A38: 二厂 | B38: 0011801172BD | C38: =VLOOKUP(B38,'[4]项目编码 '!$B$1:$C$65536,2,FALSE) -> 10880020802 | D38: =VLOOKUP(B38,[5]sheet!$C$1:$H$65536,6,FALSE) -> 70 | E38: =VLOOKUP(B:B,[6]配额0227!$A:$B,2,0) -> 变频外电脑板-FR-4240*180 | F38: =VLOOKUP(B:B,'[7]厂家配额 (新)'!$A$1:$C$65536,3,0) -> 和而泰/航嘉// | G38: =VLOOKUP(B38,[8]物料价格查询导出!$B:$I,8,FALSE) -> 152.05 | H38: =I38*G38 -> 0 | I38: =Q38*D38/100 -> 0 | J38: =VLOOKUP(C38,[1]Data!$A:$K,11,FALSE) -> 6 | K38: =VLOOKUP(C38,'[1]Data (2)'!$A:$K,11,FALSE) -> 2 | M38: =L38+K38 -> 2 | N38: =VLOOKUP(C38,[3]保留到5!$A:$B,2,FALSE) -> 150 | O38: 在制3/1入库 | P38: =N38+M38-Q38 -> 152 | Q38: =SUM(T38) -> 0 | R38: =SUM(S38:AE38) -> 191 | S38: 0 | T38: 0 | U38: 0 | V38: 191 | W38: 0 | X38: 0 | Y38: 0 | Z38: 0 | AA38: 0 | AB38: 0 | AC38: 0 | AD38: 0 | AE38: 0
A39: 二厂 | B39: 0011801172CH | C39: =VLOOKUP(B39,'[4]项目编码 '!$B$1:$C$65536,2,FALSE) -> 10880021476 | D39: =VLOOKUP(B39,[5]sheet!$C$1:$H$65536,6,FALSE) -> 100 | E39: =VLOOKUP(B:B,[6]配额0227!$A:$B,2,0) -> 变频外电脑板-FR-4240*180 | F39: =VLOOKUP(B:B,'[7]厂家配额 (新)'!$A$1:$C$65536,3,0) -> 和而泰 | G39: =VLOOKUP(B39,[8]物料价格查询导出!$B:$I,8,FALSE) -> 172.04 | H39: =I39*G39 -> 0 | I39: =Q39*D39/100 -> 0 | J39: =VLOOKUP(C39,[1]Data!$A:$K,11,FALSE) -> 1 | L39: =VLOOKUP(B39,'[2]2月份'!$A:$F,6,FALSE) -> 13 | M39: =L39+K39 -> 13 | P39: =N39+M39-Q39 -> 13 | Q39: =SUM(T39) -> 0 | R39: =SUM(S39:AE39) -> 10 | S39: 0 | T39: 0 | U39: 0 | V39: 10 | W39: 0 | X39: 0 | Y39: 0 | Z39: 0 | AA39: 0 | AB39: 0 | AC39: 0 | AD39: 0 | AE39: 0
A40: 二厂 | B40: 0011801172DG | C40: 10880034565 | D40: =VLOOKUP(B40,[5]sheet!$C$1:$H$65536,6,FALSE) -> 70 | E40: =VLOOKUP(B:B,[6]配额0227!$A:$B,2,0) -> 变频外电脑板-FR-4 | F40: =VLOOKUP(B:B,'[7]厂家配额 (新)'!$A$1:$C$65536,3,0) -> 和而泰/尚研// | G40: =VLOOKUP(B40,[8]物料价格查询导出!$B:$I,8,FALSE) -> 162.90 | H40: =I40*G40 -> 114.03 | I40: =Q40*D40/100 -> 0.7 | J40: =VLOOKUP(C40,[1]Data!$A:$K,11,FALSE) -> 26 | M40: =L40+K40 -> 0 | N40: =VLOOKUP(C40,[3]保留到5!$A:$B,2,FALSE) -> 200 | O40: 在制3/2入库 | P40: =N40+M40-Q40 -> 199 | Q40: =SUM(T40) -> 1 | R40: =SUM(S40:AE40) -> 185 | S40: 0 | T40: 1 | U40: 0 | V40: 0 | W40: 184 | X40: 0 | Y40: 0 | Z40: 0 | AA40: 0 | AB40: 0 | AC40: 0 | AD40: 0 | AE40: 0
...

Sheet Sheet1 (2)
A1: W11周生产计划2.27下发
A2: 工厂 | B2: 物料号 | C2: 物料描述 | D2: 供应商 | E2: 2026.02.26 | F2: 2026.02.28 | G2: 2026.03.01 | H2: 2026.03.02 | I2: 2026.03.03 | J2: 2026.03.04 | K2: 2026.03.05 | L2: 2026.03.06 | M2: 2026.03.08 | N2: 2026.03.09 | O2: 2026.03.10 | P2: 2026.03.11 | Q2: T+2前一天
A3: 二厂 | B3: 0010400649E | C3: =VLOOKUP(B:B,[6]配额0227!$A:$B,2,0) -> 端子排-塑料/ | D3: =VLOOKUP(B:B,'[7]厂家配额 (新)'!$A$1:$C$65536,3,0) -> 凯都/源峰/华冠// | E3: 355 | F3: 1940 | G3: 918 | H3: 3828 | I3: 3425 | J3: 2265 | K3: 1117 | L3: 4348 | M3: 5486 | N3: 4071 | O3: 5392 | P3: 0 | Q3: 0
A4: 二厂 | B4: 0010400649F | C4: =VLOOKUP(B:B,[6]配额0227!$A:$B,2,0) -> 2.93塑料/ | D4: =VLOOKUP(B:B,'[7]厂家配额 (新)'!$A$1:$C$65536,3,0) -> 凯都 | E4: 0 | F4: 0 | G4: 0 | H4: 0 | I4: 0 | J4: 0 | K4: 145 | L4: 0 | M4: 0 | N4: 0 | O4: 892 | P4: 0 | Q4: 0
A5: 二厂 | B5: 0010400649J | C5: =VLOOKUP(B:B,[6]配额0227!$A:$B,2,0) -> 端子排-/ | D5: =VLOOKUP(B:B,'[7]厂家配额 (新)'!$A$1:$C$65536,3,0) -> 源峰 | E5: 0 | F5: 0 | G5: 2582 | H5: 20 | I5: 0 | J5: 0 | K5: 0 | L5: 0 | M5: 0 | N5: 0 | O5: 0 | P5: 0 | Q5: 0
A6: 二厂 | B6: 0010401715B | C6: =VLOOKUP(B:B,[6]配额0227!$A:$B,2,0) -> 遥控器-塑料 | D6: =VLOOKUP(B:B,'[7]厂家配额 (新)'!$A$1:$C$65536,3,0) -> 合晶 | E6: 0 | F6: 0 | G6: 0 | H6: 0 | I6: 190 | J6: 0 | K6: 0 | L6: 370 | M6: 0 | N6: 2275 | O6: 0 | P6: 0 | Q6: 0
A7: 二厂 | B7: 0010401715DG | C7: =VLOOKUP(B:B,[6]配额0227!$A:$B,2,0) -> 遥控器-塑料 | D7: =VLOOKUP(B:B,'[7]厂家配额 (新)'!$A$1:$C$65536,3,0) -> 合晶 | E7: 221 | F7: 2014 | G7: 159 | H7: 0 | I7: 157 | J7: 0 | K7: 2136 | L7: 407 | M7: 0 | N7: 0 | O7: 0 | P7: 0 | Q7: 0
A8: 二厂 | B8: 0010401715EB | C8: =VLOOKUP(B:B,[6]配额0227!$A:$B,2,0) -> 遥控器-/ | D8: =VLOOKUP(B:B,'[7]厂家配额 (新)'!$A$1:$C$65536,3,0) -> 合晶 | E8: 0 | F8: 0 | G8: 0 | H8: 0 | I8: 0 | J8: 0 | K8: 2 | L8: 0 | M8: 0 | N8: 0 | O8: 0 | P8: 0 | Q8: 0
A9: 二厂 | B9: 0010401715GT | C9: =VLOOKUP(B:B,[6]配额0227!$A:$B,2,0) -> 遥控器-塑料HE | D9: =VLOOKUP(B:B,'[7]厂家配额 (新)'!$A$1:$C$65536,3,0) -> 合晶 | E9: 0 | F9: 1600 | G9: 0 | H9: 0 | I9: 0 | J9: 0 | K9: 0 | L9: 0 | M9: 0 | N9: 0 | O9: 0 | P9: 0 | Q9: 0
A10: 二厂 | B10: 0010401715HL | C10: =VLOOKUP(B:B,[6]配额0227!$A:$B,2,0) -> 遥控器-塑料/ | D10: =VLOOKUP(B:B,'[7]厂家配额 (新)'!$A$1:$C$65536,3,0) -> 合晶 | E10: 0 | F10: 480 | G10: 1520 | H10: 1200 | I10: 885 | J10: 0 | K10: 1366 | L10: 210 | M10: 1320 | N10: 1975 | O10: 1590 | P10: 0 | Q10: 0
A11: 二厂 | B11: 0010401715HQ | C11: =VLOOKUP(B:B,[6]配额0227!$A:$B,2,0) -> 遥控器-塑料 | D11: =VLOOKUP(B:B,'[7]厂家配额 (新)'!$A$1:$C$65536,3,0) -> 合晶 | E11: 0 | F11: 100 | G11: 0 | H11: 1445 | I11: 0 | J11: 375 | K11: 105 | L11: 2015 | M11: 4879 | N11: 990 | O11: 4266 | P11: 0 | Q11: 0
A12: 二厂 | B12: 0010401715HR | C12: =VLOOKUP(B:B,[6]配额0227!$A:$B,2,0) -> 遥控器-塑料 | D12: =VLOOKUP(B:B,'[7]厂家配额 (新)'!$A$1:$C$65536,3,0) -> 合晶 | E12: 1 | F12: 1 | G12: 2 | H12: 479 | I12: 184 | J12: 0 | K12: 790 | L12: 71 | M12: 420 | N12: 335 | O12: 2009 | P12: 0 | Q12: 0
A13: 二厂 | B13: 0010401715HU | C13: =VLOOKUP(B:B,[6]配额0227!$A:$B,2,0) -> 遥控器-塑料 | D13: =VLOOKUP(B:B,'[7]厂家配额 (新)'!$A$1:$C$65536,3,0) -> 合晶 | E13: 0 | F13: 0 | G13: 0 | H13: 4320 | I13: 1650 | J13: 5626 | K13: 2514 | L13: 0 | M13: 0 | N13: 0 | O13: 0 | P13: 0 | Q13: 0
A14: 二厂 | B14: 0010401715HW | C14: =VLOOKUP(B:B,[6]配额0227!$A:$B,2,0) -> 遥控器-塑料 | D14: =VLOOKUP(B:B,'[7]厂家配额 (新)'!$A$1:$C$65536,3,0) -> 合晶 | E14: 0 | F14: 2400 | G14: 4600 | H14: 0 | I14: 0 | J14: 0 | K14: 130 | L14: 140 | M14: 2660 | N14: 0 | O14: 4490 | P14: 0 | Q14: 0
... A172: 二厂 | B172: 0011801490CY | C172: =VLOOKUP(B:B,[6]配额0227!$A:$B,2,0) -> 变频外电脑板-FR-4 | D172: =VLOOKUP(B:B,'[7]厂家配额 (新)'!$A$1:$C$65536,3,0) -> 领智/尚研// | E172: 0 | F172: 0 | G172: 0 | H172: 20 | I172: 0 | J172: 0 | K172: 0 | L172: 0 | M172: 0 | N172: 0 | O172: 0 | P172: 0 | Q172: 0
A173: 二厂 | B173: 0011801490DB | C173: =VLOOKUP(B:B,[6]配额0227!$A:$B,2,0) -> 变频外电脑板-FR-4 | D173: 领智 | E173: 0 | F173: 0 | G173: 0 | H173: 1360 | I173: 0 | J173: 0 | K173: 0 | L173: 0 | M173: 0 | N173: 0 | O173: 0 | P173: 0 | Q173: 0
A174: 二厂 | B174: 0011801490M | C174: =VLOOKUP(B:B,[6]配额0227!$A:$B,2,0) -> 变频外电脑板-FR-4 | D174: =VLOOKUP(B:B,'[7]厂家配额 (新)'!$A$1:$C$65536,3,0) -> 领智/尚研 | E174: 0 | F174: 0 | G174: 0 | H174: 0 | I174: 4320 | J174: 0 | K174: 0 | L174: 0 | M174: 0 | N174: 0 | O174: 0 | P174: 0 | Q174: 0
A175: 二厂 | B175: 0011801490R | C175: =VLOOKUP(B:B,[6]配额0227!$A:$B,2,0) -> 变频外电脑板-FR-4 | D175: =VLOOKUP(B:B,'[7]厂家配额 (新)'!$A$1:$C$65536,3,0) -> 麦格米特/领智// | E175: 0 | F175: 1760 | G175: 0 | H175: 0 | I175: 0 | J175: 0 | K175: 0 | L175: 0 | M175: 0 | N175: 0 | O175: 0 | P175: 0 | Q175: 0
A176: 二厂 | B176: 0011801652 | C176: =VLOOKUP(B:B,[6]配额0227!$A:$B,2,0) -> 室内电脑板-/ | D176: =VLOOKUP(B:B,'[7]厂家配额 (新)'!$A$1:$C$65536,3,0) -> 领智/和而泰// | E176: 0 | F176: 0 | G176: 960 | H176: 0 | I176: 0 | J176: 0 | K176: 0 | L176: 240 | M176: 0 | N176: 0 | O176: 0 | P176: 0 | Q176: 0
A177: 二厂 | B177: 0011801652A | C177: =VLOOKUP(B:B,[6]配额0227!$A:$B,2,0) -> 室内电脑板-/ | D177: =VLOOKUP(B:B,'[7]厂家配额 (新)'!$A$1:$C$65536,3,0) -> 和而泰/领智 | E177: 0 | F177: 0 | G177: 150 | H177: 0 | I177: 0 | J177: 0 | K177: 0 | L177: 0 | M177: 0 | N177: 0 | O177: 0 | P177: 0 | Q177: 0
A178: 二厂 | B178: 0011801656 | C178: =VLOOKUP(B:B,[6]配额0227!$A:$B,2,0) -> 变频外电脑板-/ | D178: =VLOOKUP(B:B,'[7]厂家配额 (新)'!$A$1:$C$65536,3,0) -> 领智/和而泰// | E178: 0 | F178: 0 | G178: 830 | H178: 0 | I178: 0 | J178: 0 | K178: 0 | L178: 0 | M178: 0 | N178: 240 | O178: 0 | P178: 0 | Q178: 0
A179: 二厂 | B179: 0011801656A | C179: =VLOOKUP(B:B,[6]配额0227!$A:$B,2,0) -> 变频外电脑板 | D179: =VLOOKUP(B:B,'[7]厂家配额 (新)'!$A$1:$C$65536,3,0) -> 和而泰/领智 | E179: 0 | F179: 0 | G179: 315 | H179: 0 | I179: 0 | J179: 0 | K179: 0 | L179: 0 | M179: 0 | N179: 0 | O179: 0 | P179: 0 | Q179: 0
A180: 二厂 | B180: 0011801659 | C180: =VLOOKUP(B:B,[6]配额0227!$A:$B,2,0) -> 显示板-LED | D180: =VLOOKUP(B:B,'[7]厂家配额 (新)'!$A$1:$C$65536,3,0) -> 领智/和而泰// | E180: 0 | F180: 4 | G180: 1132 | H180: 0 | I180: 0 | J180: 0 | K180: 0 | L180: 240 | M180: 0 | N180: 0 | O180: 0 | P180: 0 | Q180: 0
A181: 二厂 | B181: 0011801675A | C181: =VLOOKUP(B:B,[6]配额0227!$A:$B,2,0) -> 室内电脑板-CEM-1165*136 | D181: =VLOOKUP(B:B,'[7]厂家配额 (新)'!$A$1:$C$65536,3,0) -> 领智/和而泰// | E181: 234 | F181: 0 | G181: 99 | H181: 0 | I181: 2 | J181: 0 | K181: 0 | L181: 482 | M181: 0 | N181: 0 | O181: 0 | P181: 0 | Q181: 0
A182: 二厂 | B182: 0011801675AB | C182: =VLOOKUP(B:B,[6]配额0227!$A:$B,2,0) -> 室内电脑板-CEM-1 | D182: =VLOOKUP(B:B,'[7]厂家配额 (新)'!$A$1:$C$65536,3,0) -> 领智/和而泰// | E182: 0 | F182: 0 | G182: 0 | H182: 0 | I182: 885 | J182: 0 | K182: 175 | L182: 0 | M182: 2450 | N182: 0 | O182: 0 | P182: 0 | Q182: 0
A183: 二厂 | B183: 0011801675AE | C183: =VLOOKUP(B:B,[6]配额0227!$A:$B,2,0) -> 室内电脑板-CEM-1165*136 | D183: =VLOOKUP(B:B,'[7]厂家配额 (新)'!$A$1:$C$65536,3,0) -> 领智/和而泰// | E183: 0 | F183: 0 | G183: 0 | H183: 0 | I183: 0 | J183: 0 | K183: 0 | L183: 2310 | M183: 0 | N183: 285 | O183: 0 | P183: 0 | Q183: 0
A184: 二厂 | B184: 0011801675AJ | C184: =VLOOKUP(B:B,[6]配额0227!$A:$B,2,0) -> 室内电脑板-155*136 | D184: =VLOOKUP(B:B,'[7]厂家配额 (新)'!$A$1:$C$65536,3,0) -> 领智/康美特 | E184: 0 | F184: 0 | G184: 0 | H184: 0 | I184: 120 | J184: 0 | K184: 0 | L184: 0 | M184: 0 | N184: 0 | O184: 0 | P184: 0 | Q184: 0
A185: 二厂 | B185: 0011801675B | C185: =VLOOKUP(B:B,[6]配额0227!$A:$B,2,0) -> 室内电脑板-CEM-1155*136 | D185: =VLOOKUP(B:B,'[7]厂家配额 (新)'!$A$1:$C$65536,3,0) -> 和而泰/领智// | E185: 0 | F185: 0 | G185: 0 | H185: 0 | I185: 0 | J185: 0 | K185: 0 | L185: 0 | M185: 0 | N185: 2060 | O185: 0 | P185: 0 | Q185: 0
... A539: 一厂 | B539: 0011801490CY | C539: =VLOOKUP(B:B,[6]配额0227!$A:$B,2,0) -> 变频外电脑板-FR-4 | D539: =VLOOKUP(B:B,'[7]厂家配额 (新)'!$A$1:$C$65536,3,0) -> 领智/尚研// | E539: 0 | F539: 0 | G539: 0 | H539: 0 | I539: 0 | J539: 0 | K539: 1785 | L539: 0 | M539: 0 | N539: 0 | O539: 0 | P539: 0 | Q539: 1530
A540: 一厂 | B540: 0011801490DA | C540: =VLOOKUP(B:B,[6]配额0227!$A:$B,2,0) -> 变频外电脑板-FR-4 | D540: 领智 | E540: 0 | F540: 0 | G540: 0 | H540: 0 | I540: 0 | J540: 0 | K540: 0 | L540: 0 | M540: 0 | N540: 3 | O540: 0 | P540: 0 | Q540: 0
A541: 一厂 | B541: 0011801490DB | C541: =VLOOKUP(B:B,[6]配额0227!$A:$B,2,0) -> 变频外电脑板-FR-4 | D541: 领智 | E541: 0 | F541: 0 | G541: 0 | H541: 0 | I541: 2 | J541: 0 | K541: 0 | L541: 0 | M541: 0 | N541: 0 | O541: 0 | P541: 0 | Q541: 0
A542: 一厂 | B542: 0011801490M | C542: =VLOOKUP(B:B,[6]配额0227!$A:$B,2,0) -> 变频外电脑板-FR-4 | D542: =VLOOKUP(B:B,'[7]厂家配额 (新)'!$A$1:$C$65536,3,0) -> 领智/尚研 | E542: 0 | F542: 0 | G542: 0 | H542: 0 | I542: 0 | J542: 0 | K542: 0 | L542: 0 | M542: 0 | N542: 0 | O542: 0 | P542: 0 | Q542: 2160
A543: 一厂 | B543: 0011801516 | C543: =VLOOKUP(B:B,[6]配额0227!$A:$B,2,0) -> 变频外电脑板-FR-4300mm*180mm | D543: =VLOOKUP(B:B,'[7]厂家配额 (新)'!$A$1:$C$65536,3,0) -> 和而泰 | E543: 0 | F543: 100 | G543: 0 | H543: 0 | I543: 0 | J543: 0 | K543: 0 | L543: 0 | M543: 0 | N543: 0 | O543: 0 | P543: 0 | Q543: 120
A544: 一厂 | B544: 0011801516D | C544: =VLOOKUP(B:B,[6]配额0227!$A:$B,2,0) -> 变频外电脑板-FR-4 | D544: =VLOOKUP(B:B,'[7]厂家配额 (新)'!$A$1:$C$65536,3,0) -> 领智/和而泰// | E544: 0 | F544: 50 | G544: 0 | H544: 0 | I544: 0 | J544: 0 | K544: 0 | L544: 0 | M544: 200 | N544: 0 | O544: 0 | P544: 0 | Q544: 345
A545: 一厂 | B545: 0011801516E | C545: =VLOOKUP(B:B,[6]配额0227!$A:$B,2,0) -> 变频外电脑板-FR-4 | D545: =VLOOKUP(B:B,'[7]厂家配额 (新)'!$A$1:$C$65536,3,0) -> 领智/和而泰// | E545: 0 | F545: 0 | G545: 0 | H545: 12 | I545: 0 | J545: 0 | K545: 0 | L545: 0 | M545: 38 | N545: 0 | O545: 0 | P545: 0 | Q545: 270
A546: 一厂 | B546: 0011801593 | C546: =VLOOKUP(B:B,[6]配额0227!$A:$B,2,0) -> 室内电脑板-FR-4136*165 | D546: =VLOOKUP(B:B,'[7]厂家配额 (新)'!$A$1:$C$65536,3,0) -> 和而泰 | E546: 0 | F546: 0 | G546: 0 | H546: 0 | I546: 0 | J546: 0 | K546: 0 | L546: 0 | M546: 0 | N546: 130 | O546: 0 | P546: 0 | Q546: 50
A547: 一厂 | B547: 0011801593A | C547: =VLOOKUP(B:B,[6]配额0227!$A:$B,2,0) -> 室内电脑板-FR-4 | D547: =VLOOKUP(B:B,'[7]厂家配额 (新)'!$A$1:$C$65536,3,0) -> 领智/和而泰// | E547: 0 | F547: 0 | G547: 1 | H547: 0 | I547: 0 | J547: 0 | K547: 0 | L547: 210 | M547: 2080 | N547: 730 | O547: 0 | P547: 0 | Q547: 80
A548: 一厂 | B548: 0011801593C | C548: =VLOOKUP(B:B,[6]配额0227!$A:$B,2,0) -> 室内电脑板-FR-4 | D548: =VLOOKUP(B:B,'[7]厂家配额 (新)'!$A$1:$C$65536,3,0) -> 领智/和而泰// | E548: 0 | F548: 0 | G548: 0 | H548: 0 | I548: 0 | J548: 0 | K548: 0 | L548: 0 | M548: 30 | N548: 0 | O548: 0 | P548: 0 | Q548: 0
A549: 一厂 | B549: 0011801593D | C549: =VLOOKUP(B:B,[6]配额0227!$A:$B,2,0) -> 室内电脑板-FR-4 | D549: =VLOOKUP(B:B,'[7]厂家配额 (新)'!$A$1:$C$65536,3,0) -> 领智/和而泰// | E549: 0 | F549: 0 | G549: 4 | H549: 0 | I549: 0 | J549: 0 | K549: 0 | L549: 0 | M549: 0 | N549: 280 | O549: 0 | P549: 0 | Q549: 0
A550: 一厂 | B550: 0011801609S | C550: =VLOOKUP(B:B,[6]配额0227!$A:$B,2,0) -> 变频外电脑板-FR-4379mm*230mm | D550: =VLOOKUP(B:B,'[7]厂家配额 (新)'!$A$1:$C$65536,3,0) -> 斑科 | E550: 0 | F550: 0 | G550: 0 | H550: 0 | I550: 4 | J550: 0 | K550: 0 | L550: 0 | M550: 0 | N550: 0 | O550: 0 | P550: 0 | Q550: 0
...
