Workbook

Sheet Sheet1
A1: 物料编码 | B1: 物料描述 | C1: 厂家 | D1: 4月需求 | E1: 5月需求 | F1: 6月需求 | G1: 7月需求
A2: 1579194 | B2: 电源线\X03120022\大南非插\1.5m\灰 | C2: =VLOOKUP(A2,[1]主控板线束!$A:$C,3,0) -> 浙江跃华电讯有限公司 | D2: 7869 | E2: 5679 | F2: 13681 | G2: 4758
A3: 1579673 | B3: 电源线\X03120024\日本插\2.55m\黑/白/黄绿 | C3: =VLOOKUP(A3,[1]主控板线束!$A:$C,3,0) -> 浙江跃华电讯有限公司 | D3: 5927 | E3: 7389 | F3: 9038 | G3: 9491
A4: 1878003 | B4: 电源线\X03120102\南非大三圆插\1.7\ | C4: =VLOOKUP(A4,[1]主控板线束!$A:$C,3,0) -> 浙江跃华电讯有限公司 | D4: 5497 | E4: 2134 | F4: 9622 | G4: 1734
A5: 1921724 | B5: 电源线\X03120131\英三方插\1.2\棕/蓝/黄绿 | C5: =VLOOKUP(A5,[1]主控板线束!$A:$C,3,0) -> 浙江跃华电讯有限公司 | D5: 1664 | E5: 0 | F5: 1248 | G5: 1248
A6: 1945508 | B6: 电源线\X03120145\日本插\1.95\灰 | C6: =VLOOKUP(A6,[1]主控板线束!$A:$C,3,0) -> 浙江跃华电讯有限公司 | D6: 3064 | E6: 2572 | F6: 3376 | G6: 4296
A7: 1996867 | B7: 电源线\X03120156\澳洲三插\1.7\灰 | C7: =VLOOKUP(A7,[1]主控板线束!$A:$C,3,0) -> 浙江跃华电讯有限公司 | D7: 216 | E7: 500 | F7: 700 | G7: 700
A8: 2122504 | B8: 电源线\X03120166\阿根廷插头\1.5\灰 | C8: =VLOOKUP(A8,[1]主控板线束!$A:$C,3,0) -> 浙江跃华电讯有限公司 | D8: 5781 | E8: 12391 | F8: 17701 | G8: 8280
A9: 2157399 | B9: 电源线\X03120170\印尼双圆插\2\灰色 | C9: =VLOOKUP(A9,[1]主控板线束!$A:$C,3,0) -> 浙江跃华电讯有限公司 | D9: 624 | E9: 2704 | F9: 0 | G9: 0
A10: 2272875 | B10: 电源线\X03120191\巴西插\1500\灰 | C10: =VLOOKUP(A10,[1]主控板线束!$A:$C,3,0) -> 浙江跃华电讯有限公司 | D10: 12513 | E10: 7053 | F10: 12276 | G10: 17289
A11: 2413766 | B11: 电源线\X03120203\阿根廷插\1.5\灰 | C11: =VLOOKUP(A11,[1]主控板线束!$A:$C,3,0) -> 浙江跃华电讯有限公司 | D11: 0 | E11: 0 | F11: 306 | G11: 0
A12: 2433998 | B12: 电源线\X03120209\美式三插\1700\黑色 | C12: =VLOOKUP(A12,[1]主控板线束!$A:$C,3,0) -> 浙江跃华电讯有限公司 | D12: 1596 | E12: 0 | F12: 318 | G12: 159
A13: 2185356 | B13: 连接管\X04030464\7.94×0.7×500\TP2M | C13: =VLOOKUP(A13,[1]压缩机蒸发器!$A:$C,3,0) -> 浙江同星科技股份有限公司 | D13: 6155 | E13: 4979 | F13: 10704 | G13: 8430
A14: 2350276 | B14: 翅片冷凝器部件\X10290158 | C14: =VLOOKUP(A14,[1]压缩机蒸发器!$A:$C,3,0) -> 浙江同星科技股份有限公司 | D14: 4057 | E14: 5481 | F14: 5164 | G14: 4348
A15: 2364970 | B15: 翅片冷凝器部件\X10290172 | C15: =VLOOKUP(A15,[1]压缩机蒸发器!$A:$C,3,0) -> 浙江同星科技股份有限公司 | D15: 17019 | E15: 12641 | F15: 21008 | G15: 18248
A16: 2434357 | B16: 翅片冷凝器部件\X102590247 | C16: =VLOOKUP(A16,[1]压缩机蒸发器!$A:$C,3,0) -> 浙江同星科技股份有限公司 | D16: 159 | E16: 477 | F16: 498 | G16: 1767
A17: 2436102 | B17: 连接管\X10290250\7×0.7×1500\TP2M | C17: =VLOOKUP(A17,[1]压缩机蒸发器!$A:$C,3,0) -> 浙江同星科技股份有限公司 | D17: 1289 | E17: 1320 | F17: 2100 | G17: 1700
A18: 2441880 | B18: 连接管\X10290253\8×0.7×1500\TP2M | C18: =VLOOKUP(A18,[1]压缩机蒸发器!$A:$C,3,0) -> 浙江同星科技股份有限公司 | D18: 1289 | E18: 1320 | F18: 2100 | G18: 1700
A19: 2454641 | B19: 翅片冷凝器部件\X10290271 | C19: =VLOOKUP(A19,[1]压缩机蒸发器!$A:$C,3,0) -> 浙江同星科技股份有限公司 | D19: 3080 | E19: 2479 | F19: 4565 | G19: 5871
A20: 2455277 | B20: 翅片冷凝器部件\X10290288 | C20: =VLOOKUP(A20,[1]压缩机蒸发器!$A:$C,3,0) -> 浙江同星科技股份有限公司 | D20: 4632 | E20: 3814 | F20: 6760 | G20: 9917
A21: 2468092 | B21: 翅片冷凝器部件\X10290301 | C21: =VLOOKUP(A21,[1]压缩机蒸发器!$A:$C,3,0) -> 浙江同星科技股份有限公司 | D21: 1660 | E21: 11598 | F21: 6726 | G21: 8872
A22: 2482746 | B22: 连接管\X10290320\8×0.7×1500\TP2M | C22: =VLOOKUP(A22,[1]压缩机蒸发器!$A:$C,3,0) -> 浙江同星科技股份有限公司 | D22: 3304 | E22: 3619 | F22: 3751 | G22: 4162
A23: 2486212 | B23: 翅片冷凝器部件\X10290329 | C23: =VLOOKUP(A23,[1]压缩机蒸发器!$A:$C,3,0) -> 浙江同星科技股份有限公司 | D23: 2337 | E23: 7661 | F23: 11677 | G23: 17612
A24: 20167145 | B24: 铜配管组件\N3050001231V01\70L\连接管组件 | C24: =VLOOKUP(A24,[1]压缩机蒸发器!$A:$C,3,0) -> 浙江同星科技股份有限公司 | D24: 12085 | E24: 4700 | F24: 5000 | G24: 6400
... A30: 2442947 | B30: 定速压缩机\RJSN82N01TZJ3 | C30: =VLOOKUP(A30,[1]压缩机蒸发器!$A:$C,3,0) -> 浙江美芝压缩机有限公司 | D30: 1115 | E30: 0 | F30: 318 | G30: 159
A31: 2241044 | B31: 主板组件\WDQY8014-PVW004\X01080676 | C31: =VLOOKUP(A31,[1]主控板线束!$A:$C,3,0) -> 浙江昌德成电器有限公司 | D31: 1259 | E31: 887 | F31: 0 | G31: 4318
A32: 2290154 | B32: 电源板组件\WF7S1245DW控制板\X01070439 | C32: =VLOOKUP(A32,[1]主控板线束!$A:$C,3,0) -> 浙江昌德成电器有限公司 | D32: 1365 | E32: 1365 | F32: 2501 | G32: 2157
A33: 2395517 | B33: 电源板组件\滚筒\X01070518 | C33: =VLOOKUP(A33,[1]主控板线束!$A:$C,3,0) -> 浙江昌德成电器有限公司 | D33: 318 | E33: 159 | F33: 159 | G33: 159
A34: 2410831 | B34: 控制板部件\X01081932\WG100R5 | C34: =VLOOKUP(A34,[1]主控板线束!$A:$C,3,0) -> 浙江昌德成电器有限公司 | D34: 100 | E34: 30 | F34: 60 | G34: 100
A35: 2415241 | B35: 控制板部件\X01080873\WDRM1114-SVE001-000 | C35: =VLOOKUP(A35,[1]主控板线束!$A:$C,3,0) -> 浙江昌德成电器有限公司 | D35: 161 | E35: 30 | F35: 412 | G35: 480
A36: 2416937 | B36: 控制板部件\X01081216\WDSE1114-SVB001-000 | C36: =VLOOKUP(A36,[1]主控板线束!$A:$C,3,0) -> 浙江昌德成电器有限公司 | D36: 318 | E36: 0 | F36: 0 | G36: 159
A37: 2416940 | B37: 控制板部件\X01081216\WFSE1114-SVB003-000 | C37: =VLOOKUP(A37,[1]主控板线束!$A:$C,3,0) -> 浙江昌德成电器有限公司 | D37: 318 | E37: 0 | F37: 0 | G37: 0
A38: 2428250 | B38: 显示板组件\WFSE1214\Hisense\X01081882 | C38: =VLOOKUP(A38,[1]主控板线束!$A:$C,3,0) -> 浙江昌德成电器有限公司 | D38: 1592 | E38: 0 | F38: 318 | G38: 159
A39: 2429449 | B39: 控制板部件\X01080904\WFMK7014-NVW005-000 | C39: =VLOOKUP(A39,[1]主控板线束!$A:$C,3,0) -> 浙江昌德成电器有限公司 | D39: 0 | E39: 0 | F39: 249 | G39: 0
A40: 2437888 | B40: 显示板组件\DHSE10-BVW109-000\Hisense | C40: =VLOOKUP(A40,[1]主控板线束!$A:$C,3,0) -> 浙江昌德成电器有限公司 | D40: 1115 | E40: 0 | F40: 318 | G40: 159
A41: 2443787 | B41: 电源板组件\滚筒\X01070588 | C41: =VLOOKUP(A41,[1]主控板线束!$A:$C,3,0) -> 浙江昌德成电器有限公司 | D41: 0 | E41: 159 | F41: 0 | G41: 159
A42: 2463143 | B42: 显示板部件\X01082300\WF80N1 | C42: =VLOOKUP(A42,[1]主控板线束!$A:$C,3,0) -> 浙江昌德成电器有限公司 | D42: 230 | E42: 262 | F42: 442 | G42: 654
... A315: 20218282 | B315: 驱动板组件\Hisense\N1360006880V01 | C315: =VLOOKUP(A315,[1]主控板线束!$A:$C,3,0) -> 上海绿联智能科技股份有限公司 | D315: 0 | E315: 1400 | F315: 0 | G315: 0
A316: 2364193 | B316: 定速压缩机\35Q0J3I | C316: =VLOOKUP(A316,[1]压缩机蒸发器!$A:$C,3,0) -> 青岛瑞智机电销售有限公司 | D316: 4057 | E316: 5481 | F316: 5164 | G316: 4348
A317: 2387001 | B317: 定速压缩机\35q073I | C317: =VLOOKUP(A317,[1]压缩机蒸发器!$A:$C,3,0) -> 青岛瑞智机电销售有限公司 | D317: 15763 | E317: 11729 | F317: 19781 | G317: 17744
...

Sheet Sheet2
A1: 物料编码 | B1: 物料描述 | C1: 厂家 | D1: 4月需求 | E1: 5月需求 | F1: 6月需求 | G1: 7月需求
A2: 2416141 | B2: 控制板部件\X01081787\WFQP1014-SVW001-000 | C2: =VLOOKUP(A2,[1]主控板线束!$A:$C,3,0) -> 深圳信扬国际经贸股份有限公司 | D2: 2688 | E2: 1344 | F2: 1848 | G2: 2184
A3: 2416216 | B3: 控制板部件\X01081787\WFQP8014-PVW103-000 | C3: =VLOOKUP(A3,[1]主控板线束!$A:$C,3,0) -> 深圳信扬国际经贸股份有限公司 | D3: 8090 | E3: 3546 | F3: 2908 | G3: 6564
A4: 2504046 | B4: 显示板部件\X01082635\WD1i1014-PVT001-001 | C4: =VLOOKUP(A4,[1]主控板线束!$A:$C,3,0) -> 青岛和而泰智能控制技术有限公司（转） | D4: 1696 | E4: 1908 | F4: 1272 | G4: 1272
A5: 2504047 | B5: 显示板部件\X01082635\WD1i1114-SVW001-000 | C5: =VLOOKUP(A5,[1]主控板线束!$A:$C,3,0) -> 青岛和而泰智能控制技术有限公司（转） | D5: 3360 | E5: 2856 | F5: 4872 | G5: 7728
A6: 2504049 | B6: 显示板部件\X01082635\WD1i1114-SVW001-001 | C6: =VLOOKUP(A6,[1]主控板线束!$A:$C,3,0) -> 青岛和而泰智能控制技术有限公司（转） | D6: 1680 | E6: 1176 | F6: 1680 | G6: 3360
A7: 20112792 | B7: 显示板组件\WD1i1114-LVW002-000\X01082635 | C7: =VLOOKUP(A7,[1]主控板线束!$A:$C,3,0) -> 青岛和而泰智能控制技术有限公司（转） | D7: 2331 | E7: 496 | F7: 900 | G7: 318
A8: 20112793 | B8: 显示板组件\法国\Hisense\X01082635V05 | C8: =VLOOKUP(A8,[1]主控板线束!$A:$C,3,0) -> 青岛和而泰智能控制技术有限公司（转） | D8: 672 | E8: 1642 | F8: 1082 | G8: 1678
A9: 20204793 | B9: 显示板组件\WF1i1214-LVK001-000\泰国\Hise | C9: 青岛和而泰智能控制技术有限公司 | D9: 0 | E9: 0 | F9: 209 | G9: 0
A10: 20239305 | B10: 显示板组件\DH1i70-EEW001-000\Hisense | C10: 青岛和而泰智能控制技术有限公司 | D10: 0 | E10: 0 | F10: 424 | G10: 1060
A11: 20239308 | B11: 显示板组件\DH080G2D-EEWA01\欧洲\Hisense | C11: 青岛和而泰智能控制技术有限公司 | D11: 0 | E11: 0 | F11: 3393 | G11: 2297
