Workbook

Sheet DIP计划
B1: 青岛工厂DIP计划（QR-QW-PMC-01-01-QD生产计划表V01）
B2: 工序 | C2: 成品编码 | D2: 整机工单号 | E2: 新系统工单号 | F2: 物料描述 | G2: 工单数量 | H2: 剩余数量 | I2: 拼板数 | J2: 上线时间 | K2: UPH | L2: 人力 | M2: 46142 | N2: =M2 -> 46142 | O2: =M2+1+3 -> 46146 | P2: =O2 -> 46146 | Q2: =O2+1 -> 46147 | R2: =Q2 -> 46147 | S2: =Q2+1 -> 46148 | T2: =S2 -> 46148 | U2: =T2+1 -> 46149 | V2: =U2 -> 46149 | W2: =U2+1 -> 46150 | X2: =W2 -> 46150 | Y2: =W2+1 -> 46151 | Z2: =Y2 -> 46151 | AA2: =Y2+1 -> 46152 | AB2: =AA2 -> 46152 | AC2: =AA2+1 -> 46153 | AD2: =AC2 -> 46153 | AE2: =AC2+1 -> 46154 | AF2: =AE2 -> 46154 | AG2: 已排数量 | AH2: 未排数量 | AI2: 备注 | AJ2: 定稿工单 | AK2: 客户 | AL2: 类型
B3: 生产时长 | M3: 8 | N3: 夜班 | O3: 12 | P3: 夜班 | Q3: 12 | R3: 夜班 | S3: 12 | T3: 夜班 | U3: 12 | V3: 夜班 | W3: 12 | X3: 夜班 | Y3: 12 | Z3: 夜班 | AA3: 12 | AB3: 夜班 | AC3: 12 | AD3: 夜班 | AE3: 12 | AF3: 夜班
B4: 开工线体 | M4: 9.5 | O4: 9.5 | P4: 1 | Q4: 9.5 | R4: 2 | S4: 9.5 | T4: 2 | U4: 9.5 | V4: 1 | W4: 9.5 | X4: 2 | Y4: 9.5 | Z4: 2 | AA4: 9.5 | AB4: 2 | AC4: 9.5 | AD4: 2 | AE4: 9.5 | AF4: 2
A5: =VLOOKUP(C5,'[1]青岛4 (2)'!$C:$D,2,0) -> 日立测出风 | B5: 包装 | C5: 10880036207 | D5: 110001302850 | E5: 110001302850 | F5: 697-C2504B G0020 1201684 H7A09158A/PV22& | G5: 750 | H5: 750 | I5: =VLOOKUP(C5,'[2]IE model 海尔产品'!$A$1:$D$65536,4,0) -> 1 | J5: {=INDEX($A$2:$AF$2,MIN(IF(M5:AF5<>0,COLUMN(M5:AF5))))} -> 46142 | K5: =VLOOKUP(C5,'[2]IE model 海尔产品'!$A$1:$H$65536,8,0) -> 90 | L5: =VLOOKUP(C5,'[2]IE model 海尔产品'!$A$1:$I$65536,9,0) -> 62 | M5: 750 | AG5: =SUM(M5:AF5) -> 750 | AH5: =+H5-AG5 -> 0 | AI5: =_xlfn.XLOOKUP(D5,'[3]青岛4 (2)'!$G:$G,'[3]青岛4 (2)'!$J:$J) -> 46141 | AJ5: =+H5-AI5 -> -45391 | AM5: =_xlfn.XLOOKUP(C5,'[4]4-30'!$F:$F,'[4]4-30'!$S:$S) -> #N/A
A6: =VLOOKUP(C6,'[1]青岛4 (2)'!$C:$D,2,0) -> #N/A | B6: 插件 | C6: 10400030197 | D6: 110001302880 | E6: 110001302881 | F6: 1886-C2512A-K 干洗衣机按键旋钮板 | G6: 90 | H6: 90 | I6: =VLOOKUP(C6,'[2]IE model 海尔产品'!$A$1:$D$65536,4,0) -> 0 | J6: {=INDEX($A$2:$AF$2,MIN(IF(M6:AF6<>0,COLUMN(M6:AF6))))} -> 46142 | K6: =VLOOKUP(C6,'[2]IE model 海尔产品'!$A$1:$H$65536,8,0) -> 1200 | L6: =VLOOKUP(C6,'[2]IE model 海尔产品'!$A$1:$I$65536,9,0) -> 12 | M6: 90 | AG6: =SUM(M6:AF6) -> 90 | AH6: =+H6-AG6 -> 0 | AJ6: =+H6-AI6 -> 90 | AM6: =_xlfn.XLOOKUP(C6,'[4]4-30'!$F:$F,'[4]4-30'!$S:$S) -> #N/A
A7: =VLOOKUP(C7,'[1]青岛4 (2)'!$C:$D,2,0) -> #N/A | B7: 插件 | C7: 10400034245 | D7: 110001302880 | E7: 110001302882 | F7: 1886-C2512F-X 20239594 7i干衣机通用板 新能效天青墨 | G7: 90 | H7: 90 | I7: =VLOOKUP(C7,'[2]IE model 海尔产品'!$A$1:$D$65536,4,0) -> 0 | J7: {=INDEX($A$2:$AF$2,MIN(IF(M7:AF7<>0,COLUMN(M7:AF7))))} -> 46142 | K7: =VLOOKUP(C7,'[2]IE model 海尔产品'!$A$1:$H$65536,8,0) -> 600 | L7: =VLOOKUP(C7,'[2]IE model 海尔产品'!$A$1:$I$65536,9,0) -> 30 | M7: 90 | AG7: =SUM(M7:AF7) -> 90 | AH7: =+H7-AG7 -> 0 | AJ7: =+H7-AI7 -> 90 | AM7: =_xlfn.XLOOKUP(C7,'[4]4-30'!$F:$F,'[4]4-30'!$S:$S) -> #N/A
A8: =VLOOKUP(C8,'[1]青岛4 (2)'!$C:$D,2,0) -> #N/A | B8: 插件 | C8: 10880030545 | D8: 110001302795 | E8: 110001302796 | F8: 201-A2378A-O HLP5602-GWM.01 | G8: 300 | H8: 300 | I8: =VLOOKUP(C8,'[2]IE model 海尔产品'!$A$1:$D$65536,4,0) -> 0 | J8: {=INDEX($A$2:$AF$2,MIN(IF(M8:AF8<>0,COLUMN(M8:AF8))))} -> 46142 | K8: =VLOOKUP(C8,'[2]IE model 海尔产品'!$A$1:$H$65536,8,0) -> 600 | L8: =VLOOKUP(C8,'[2]IE model 海尔产品'!$A$1:$I$65536,9,0) -> 12 | M8: 300 | AG8: =SUM(M8:AF8) -> 300 | AH8: =+H8-AG8 -> 0 | AM8: =_xlfn.XLOOKUP(C8,'[4]4-30'!$F:$F,'[4]4-30'!$S:$S) -> #N/A
A9: =VLOOKUP(C9,'[1]青岛4 (2)'!$C:$D,2,0) -> #N/A | B9: 插件 | C9: 10880031020 | D9: 110001302795 | E9: 110001302797 | F9: 201-A2379B-X 7S5602(天青墨) | G9: 300 | H9: 300 | I9: =VLOOKUP(C9,'[2]IE model 海尔产品'!$A$1:$D$65536,4,0) -> 0 | J9: {=INDEX($A$2:$AF$2,MIN(IF(M9:AF9<>0,COLUMN(M9:AF9))))} -> 46142 | K9: =VLOOKUP(C9,'[2]IE model 海尔产品'!$A$1:$H$65536,8,0) -> 600 | L9: =VLOOKUP(C9,'[2]IE model 海尔产品'!$A$1:$I$65536,9,0) -> 12 | M9: 300 | AG9: =SUM(M9:AF9) -> 300 | AH9: =+H9-AG9 -> 0 | AM9: =_xlfn.XLOOKUP(C9,'[4]4-30'!$F:$F,'[4]4-30'!$S:$S) -> #N/A
A10: =VLOOKUP(C10,'[1]青岛4 (2)'!$C:$D,2,0) -> #N/A | B10: 插件 | C10: 10880030545 | D10: 110001302790 | E10: 110001302791 | F10: 201-A2378A-O HLP5602-GWM.01 | G10: 180 | H10: 180 | I10: =VLOOKUP(C10,'[2]IE model 海尔产品'!$A$1:$D$65536,4,0) -> 0 | J10: {=INDEX($A$2:$AF$2,MIN(IF(M10:AF10<>0,COLUMN(M10:AF10))))} -> 46142 | K10: =VLOOKUP(C10,'[2]IE model 海尔产品'!$A$1:$H$65536,8,0) -> 600 | L10: =VLOOKUP(C10,'[2]IE model 海尔产品'!$A$1:$I$65536,9,0) -> 12 | M10: 180 | AG10: =SUM(M10:AF10) -> 180 | AH10: =+H10-AG10 -> 0 | AM10: =_xlfn.XLOOKUP(C10,'[4]4-30'!$F:$F,'[4]4-30'!$S:$S) -> #N/A
A11: =VLOOKUP(C11,'[1]青岛4 (2)'!$C:$D,2,0) -> #N/A | B11: 插件 | C11: 10880031020 | D11: 110001302790 | E11: 110001302792 | F11: 201-A2379B-X 7S5602(天青墨) | G11: 180 | H11: 180 | I11: =VLOOKUP(C11,'[2]IE model 海尔产品'!$A$1:$D$65536,4,0) -> 0 | J11: {=INDEX($A$2:$AF$2,MIN(IF(M11:AF11<>0,COLUMN(M11:AF11))))} -> 46142 | K11: =VLOOKUP(C11,'[2]IE model 海尔产品'!$A$1:$H$65536,8,0) -> 600 | L11: =VLOOKUP(C11,'[2]IE model 海尔产品'!$A$1:$I$65536,9,0) -> 12 | M11: 180 | AG11: =SUM(M11:AF11) -> 180 | AH11: =+H11-AG11 -> 0 | AM11: =_xlfn.XLOOKUP(C11,'[4]4-30'!$F:$F,'[4]4-30'!$S:$S) -> #N/A
A12: =VLOOKUP(C12,'[1]青岛4 (2)'!$C:$D,2,0) -> 海信家电7I | B12: 包装 | C12: 10880038810 | D12: 110001302880 | E12: 110001302880 | F12: 1886-C2512F G0020 20239594 7i干衣机面板 新能效天& | G12: 90 | H12: 90 | I12: =VLOOKUP(C12,'[2]IE model 海尔产品'!$A$1:$D$65536,4,0) -> 通用板:1*2 旋钮板:1*10 MIC板1*30 | J12: {=INDEX($A$2:$AF$2,MIN(IF(M12:AF12<>0,COLUMN(M12:AF12))))} -> 46146 | K12: =VLOOKUP(C12,'[2]IE model 海尔产品'!$A$1:$H$65536,8,0) -> 60 | L12: =VLOOKUP(C12,'[2]IE model 海尔产品'!$A$1:$I$65536,9,0) -> 58 | O12: 90 | AG12: =SUM(M12:AF12) -> 90 | AH12: =+H12-AG12 -> 0 | AI12: =_xlfn.XLOOKUP(D12,'[3]青岛4 (2)'!$G:$G,'[3]青岛4 (2)'!$J:$J) -> 46142 | AJ12: =+H12-AI12 -> -46052 | AM12: =_xlfn.XLOOKUP(C12,'[4]4-30'!$F:$F,'[4]4-30'!$S:$S) -> #N/A
A13: =VLOOKUP(C13,'[1]青岛4 (2)'!$C:$D,2,0) -> 海信家电 | B13: 包装 | C13: 10880031760 | D13: 110001302795 | E13: 110001302795 | F13: 201-A2381C-X 2297595 冼衣机面板(全球白) | G13: 300 | H13: 300 | I13: =VLOOKUP(C13,'[2]IE model 海尔产品'!$A$1:$D$65536,4,0) -> 通用板:1*4 按键旋钮板:1*3 | J13: {=INDEX($A$2:$AF$2,MIN(IF(M13:AF13<>0,COLUMN(M13:AF13))))} -> 46146 | K13: =VLOOKUP(C13,'[2]IE model 海尔产品'!$A$1:$H$65536,8,0) -> 60 | L13: =VLOOKUP(C13,'[2]IE model 海尔产品'!$A$1:$I$65536,9,0) -> 46 | O13: 300 | AG13: =SUM(M13:AF13) -> 300 | AH13: =+H13-AG13 -> 0 | AI13: =_xlfn.XLOOKUP(D13,'[3]青岛4 (2)'!$G:$G,'[3]青岛4 (2)'!$J:$J) -> 46142 | AM13: =_xlfn.XLOOKUP(C13,'[4]4-30'!$F:$F,'[4]4-30'!$S:$S) -> #N/A
A14: =VLOOKUP(C14,'[1]青岛4 (2)'!$C:$D,2,0) -> 海信家电 | B14: 包装 | C14: 10880031011 | D14: 110001302790 | E14: 110001302790 | F14: 201-A2381B-X HLP5602-GWM(天青墨) | G14: 180 | H14: 180 | I14: =VLOOKUP(C14,'[2]IE model 海尔产品'!$A$1:$D$65536,4,0) -> 通用板:1*4 按键旋钮板:1*3 | J14: {=INDEX($A$2:$AF$2,MIN(IF(M14:AF14<>0,COLUMN(M14:AF14))))} -> 46146 | K14: =VLOOKUP(C14,'[2]IE model 海尔产品'!$A$1:$H$65536,8,0) -> 60 | L14: =VLOOKUP(C14,'[2]IE model 海尔产品'!$A$1:$I$65536,9,0) -> 46 | O14: 180 | AG14: =SUM(M14:AF14) -> 180 | AH14: =+H14-AG14 -> 0 | AI14: =_xlfn.XLOOKUP(D14,'[3]青岛4 (2)'!$G:$G,'[3]青岛4 (2)'!$J:$J) -> 46142 | AM14: =_xlfn.XLOOKUP(C14,'[4]4-30'!$F:$F,'[4]4-30'!$S:$S) -> #N/A
A15: =VLOOKUP(C15,'[1]青岛4 (2)'!$C:$D,2,0) -> #N/A | B15: 插件 | C15: 10400030194 | D15: 110001266519 | E15: 110001266520 | F15: 1886-C2512A-X 20116662 干衣机通用板 | G15: 160 | H15: 160 | I15: =VLOOKUP(C15,'[2]IE model 海尔产品'!$A$1:$D$65536,4,0) -> 0 | J15: {=INDEX($A$2:$AF$2,MIN(IF(M15:AF15<>0,COLUMN(M15:AF15))))} -> 46146 | K15: =VLOOKUP(C15,'[2]IE model 海尔产品'!$A$1:$H$65536,8,0) -> 600 | L15: =VLOOKUP(C15,'[2]IE model 海尔产品'!$A$1:$I$65536,9,0) -> 30 | O15: 160 | AG15: =SUM(M15:AF15) -> 160 | AH15: =+H15-AG15 -> 0 | AJ15: =+H15-AI15 -> 160 | AM15: =_xlfn.XLOOKUP(C15,'[4]4-30'!$F:$F,'[4]4-30'!$S:$S) -> #N/A
A16: =VLOOKUP(C16,'[1]青岛4 (2)'!$C:$D,2,0) -> #N/A | B16: 插件 | C16: 10400031098 | D16: 110001307410 | E16: 110001307411 | F16: 697-C2504C-DRV H7A09502B/PV2229H | G16: 429 | H16: 429 | I16: =VLOOKUP(C16,'[2]IE model 海尔产品'!$A$1:$D$65536,4,0) -> #N/A | J16: {=INDEX($A$2:$AF$2,MIN(IF(M16:AF16<>0,COLUMN(M16:AF16))))} -> 46151 | K16: =VLOOKUP(C16,'[2]IE model 海尔产品'!$A$1:$H$65536,8,0) -> #N/A | L16: =VLOOKUP(C16,'[2]IE model 海尔产品'!$A$1:$I$65536,9,0) -> #N/A | Y16: 429 | AG16: =SUM(M16:AF16) -> 429 | AH16: =+H16-AG16 -> 0 | AM16: =_xlfn.XLOOKUP(C16,'[4]4-30'!$F:$F,'[4]4-30'!$S:$S) -> #N/A
A17: =VLOOKUP(C17,'[1]青岛4 (2)'!$C:$D,2,0) -> 日立测出风 | B17: 包装 | C17: 10880036493 | D17: 110001307420 | E17: 110001307420 | F17: 697-C2503E G0020 1220212 H7A09529B/PV22& | G17: 190 | H17: 190 | I17: =VLOOKUP(C17,'[2]IE model 海尔产品'!$A$1:$D$65536,4,0) -> 1 | J17: {=INDEX($A$2:$AF$2,MIN(IF(M17:AF17<>0,COLUMN(M17:AF17))))} -> 46151 | K17: =VLOOKUP(C17,'[2]IE model 海尔产品'!$A$1:$H$65536,8,0) -> 90 | L17: =VLOOKUP(C17,'[2]IE model 海尔产品'!$A$1:$I$65536,9,0) -> 62 | Y17: 190 | AG17: =SUM(M17:AF17) -> 190 | AH17: =+H17-AG17 -> 0 | AI17: =_xlfn.XLOOKUP(D17,'[3]青岛4 (2)'!$G:$G,'[3]青岛4 (2)'!$J:$J) -> 46151 | AJ17: =+H17-AI17 -> -45961 | AM17: =_xlfn.XLOOKUP(C17,'[4]4-30'!$F:$F,'[4]4-30'!$S:$S) -> #N/A
B18: 包装 | C18: 10880036503 | D18: 110001307192 | E18: 110001307192 | F18: 500268-C2501E G0020 1242656 H7A10566E-D& | G18: 250 | H18: 250 | I18: =VLOOKUP(C18,'[2]IE model 海尔产品'!$A$1:$D$65536,4,0) -> #N/A | J18: {=INDEX($A$2:$AF$2,MIN(IF(M18:AF18<>0,COLUMN(M18:AF18))))} -> 46151 | K18: =VLOOKUP(C18,'[2]IE model 海尔产品'!$A$1:$H$65536,8,0) -> #N/A | L18: =VLOOKUP(C18,'[2]IE model 海尔产品'!$A$1:$I$65536,9,0) -> #N/A | Y18: 100 | AA18: 150 | AG18: =SUM(M18:AF18) -> 250 | AH18: =+H18-AG18 -> 0 | AI18: =_xlfn.XLOOKUP(D18,'[3]青岛4 (2)'!$G:$G,'[3]青岛4 (2)'!$J:$J) -> 46151 | AM18: =_xlfn.XLOOKUP(C18,'[4]4-30'!$F:$F,'[4]4-30'!$S:$S) -> #N/A
A19: =VLOOKUP(C19,'[1]青岛4 (2)'!$C:$D,2,0) -> 日立测出风 | B19: 包装 | C19: 10880036479 | D19: 110001307410 | E19: 110001307410 | F19: 697-C2504C G0020 1201685 H7A09158B/PV22& | G19: 429 | H19: 429 | I19: =VLOOKUP(C19,'[2]IE model 海尔产品'!$A$1:$D$65536,4,0) -> 1 | J19: {=INDEX($A$2:$AF$2,MIN(IF(M19:AF19<>0,COLUMN(M19:AF19))))} -> 46152 | K19: =VLOOKUP(C19,'[2]IE model 海尔产品'!$A$1:$H$65536,8,0) -> 90 | L19: =VLOOKUP(C19,'[2]IE model 海尔产品'!$A$1:$I$65536,9,0) -> 62 | AA19: 429 | AG19: =SUM(M19:AF19) -> 429 | AH19: =+H19-AG19 -> 0 | AI19: =_xlfn.XLOOKUP(D19,'[3]青岛4 (2)'!$G:$G,'[3]青岛4 (2)'!$J:$J) -> 46151 | AM19: =_xlfn.XLOOKUP(C19,'[4]4-30'!$F:$F,'[4]4-30'!$S:$S) -> #N/A
A20: =VLOOKUP(C20,'[1]青岛4 (2)'!$C:$D,2,0) -> #N/A | B20: 测试 | C20: 10400029072 | D20: 110001307415 | E20: 110001307417 | F20: 500268-C2501A-C H7A09528C PE2306Q | G20: 98 | H20: 98 | I20: =VLOOKUP(C20,'[2]IE model 海尔产品'!$A$1:$D$65536,4,0) -> #N/A | J20: {=INDEX($A$2:$AF$2,MIN(IF(M20:AF20<>0,COLUMN(M20:AF20))))} -> #VALUE! | K20: =VLOOKUP(C20,'[2]IE model 海尔产品'!$A$1:$H$65536,8,0) -> #N/A | L20: =VLOOKUP(C20,'[2]IE model 海尔产品'!$A$1:$I$65536,9,0) -> #N/A | AG20: =SUM(M20:AF20) -> 0 | AH20: =+H20-AG20 -> 98 | AJ20: =+H20-AI20 -> 98 | AM20: =_xlfn.XLOOKUP(C20,'[4]4-30'!$F:$F,'[4]4-30'!$S:$S) -> #N/A
A21: =VLOOKUP(C21,'[1]青岛4 (2)'!$C:$D,2,0) -> #N/A | B21: 插件 | C21: 10400031101 | D21: 110001307415 | E21: 110001307416 | F21: 697-C2504D-DRV H7A09502G/PV2229H | G21: 98 | H21: 98 | I21: =VLOOKUP(C21,'[2]IE model 海尔产品'!$A$1:$D$65536,4,0) -> #N/A | J21: {=INDEX($A$2:$AF$2,MIN(IF(M21:AF21<>0,COLUMN(M21:AF21))))} -> #VALUE! | K21: =VLOOKUP(C21,'[2]IE model 海尔产品'!$A$1:$H$65536,8,0) -> #N/A | L21: =VLOOKUP(C21,'[2]IE model 海尔产品'!$A$1:$I$65536,9,0) -> #N/A | AG21: =SUM(M21:AF21) -> 0 | AH21: =+H21-AG21 -> 98 | AJ21: =+H21-AI21 -> 98 | AM21: =_xlfn.XLOOKUP(C21,'[4]4-30'!$F:$F,'[4]4-30'!$S:$S) -> #N/A
A22: =VLOOKUP(C22,'[1]青岛4 (2)'!$C:$D,2,0) -> 日立测出风 | B22: 包装 | C22: 10880036481 | D22: 110001307415 | E22: 110001307415 | F22: 697-C2504D G0020 1239203 H7A09158E/PV22& | G22: 98 | H22: 98 | I22: =VLOOKUP(C22,'[2]IE model 海尔产品'!$A$1:$D$65536,4,0) -> 1 | J22: {=INDEX($A$2:$AF$2,MIN(IF(M22:AF22<>0,COLUMN(M22:AF22))))} -> #VALUE! | K22: =VLOOKUP(C22,'[2]IE model 海尔产品'!$A$1:$H$65536,8,0) -> 90 | L22: =VLOOKUP(C22,'[2]IE model 海尔产品'!$A$1:$I$65536,9,0) -> 62 | AG22: =SUM(M22:AF22) -> 0 | AH22: =+H22-AG22 -> 98 | AI22: =_xlfn.XLOOKUP(D22,'[3]青岛4 (2)'!$G:$G,'[3]青岛4 (2)'!$J:$J) -> 46157 | AJ22: =+H22-AI22 -> -46059 | AM22: =_xlfn.XLOOKUP(C22,'[4]4-30'!$F:$F,'[4]4-30'!$S:$S) -> #N/A
A23: =VLOOKUP(C23,'[1]青岛4 (2)'!$C:$D,2,0) -> 海信家电 | B23: 包装 | C23: 10880031760 | D23: 110001292147 | E23: 110001292147 | F23: 201-A2381C-X 2297595 冼衣机面板(全球白) | G23: 430 | H23: 430 | I23: =VLOOKUP(C23,'[2]IE model 海尔产品'!$A$1:$D$65536,4,0) -> 通用板:1*4 按键旋钮板:1*3 | J23: {=INDEX($A$2:$AF$2,MIN(IF(M23:AF23<>0,COLUMN(M23:AF23))))} -> #VALUE! | K23: =VLOOKUP(C23,'[2]IE model 海尔产品'!$A$1:$H$65536,8,0) -> 60 | L23: =VLOOKUP(C23,'[2]IE model 海尔产品'!$A$1:$I$65536,9,0) -> 46 | AG23: =SUM(M23:AF23) -> 0 | AH23: =+H23-AG23 -> 430 | AI23: 齐套300齐套 | AJ23: =+H23-AI23 -> #VALUE! | AK23: 齐套300齐套 | AM23: =_xlfn.XLOOKUP(C23,'[4]4-30'!$F:$F,'[4]4-30'!$S:$S) -> #N/A
A24: =VLOOKUP(C24,'[1]青岛4 (2)'!$C:$D,2,0) -> #N/A | B24: 插件 | C24: 10880030545 | D24: 110001292147 | E24: 110001292148 | F24: 201-A2378A-O HLP5602-GWM.01 | G24: 430 | H24: 430 | I24: =VLOOKUP(C24,'[2]IE model 海尔产品'!$A$1:$D$65536,4,0) -> 0 | J24: {=INDEX($A$2:$AF$2,MIN(IF(M24:AF24<>0,COLUMN(M24:AF24))))} -> #VALUE! | K24: =VLOOKUP(C24,'[2]IE model 海尔产品'!$A$1:$H$65536,8,0) -> 600 | L24: =VLOOKUP(C24,'[2]IE model 海尔产品'!$A$1:$I$65536,9,0) -> 12 | AG24: =SUM(M24:AF24) -> 0 | AH24: =+H24-AG24 -> 430 | AI24: 齐套300齐套 | AJ24: =+H24-AI24 -> #VALUE! | AK24: 齐套300齐套 | AM24: =_xlfn.XLOOKUP(C24,'[4]4-30'!$F:$F,'[4]4-30'!$S:$S) -> #N/A
A25: =VLOOKUP(C25,'[1]青岛4 (2)'!$C:$D,2,0) -> #N/A | B25: 插件 | C25: 10880031020 | D25: 110001292147 | E25: 110001292149 | F25: 201-A2379B-X 7S5602(天青墨) | G25: 430 | H25: 430 | I25: =VLOOKUP(C25,'[2]IE model 海尔产品'!$A$1:$D$65536,4,0) -> 0 | J25: {=INDEX($A$2:$AF$2,MIN(IF(M25:AF25<>0,COLUMN(M25:AF25))))} -> #VALUE! | K25: =VLOOKUP(C25,'[2]IE model 海尔产品'!$A$1:$H$65536,8,0) -> 600 | L25: =VLOOKUP(C25,'[2]IE model 海尔产品'!$A$1:$I$65536,9,0) -> 12 | AG25: =SUM(M25:AF25) -> 0 | AH25: =+H25-AG25 -> 430 | AI25: 齐套300齐套 | AJ25: =+H25-AI25 -> #VALUE! | AK25: 齐套300齐套 | AM25: =_xlfn.XLOOKUP(C25,'[4]4-30'!$F:$F,'[4]4-30'!$S:$S) -> #N/A
A26: =VLOOKUP(C26,'[1]青岛4 (2)'!$C:$D,2,0) -> #N/A | B26: 海信DIPL01，拉长任宁宁 | M26: =SUM(M5:M25) -> 1890 | N26: =SUM(N5:N25) -> 0 | O26: =SUM(O5:O25) -> 730 | P26: =SUM(P5:P25) -> 0 | Q26: =SUM(Q5:Q25) -> 0 | R26: =SUM(R5:R25) -> 0 | S26: =SUM(S5:S25) -> 0 | T26: =SUM(T5:T25) -> 0 | ... AF26: =SUM(AF5:AF25) -> 0 | AJ26: =VLOOKUP(E26,[5]Data!$D:$D,1,0) -> #N/A | AK26: =VLOOKUP(AJ26,[5]Data!$D:$I,6,0) -> #N/A | AM26: =_xlfn.XLOOKUP(C26,'[4]4-30'!$F:$F,'[4]4-30'!$S:$S) -> 备注
A27: =VLOOKUP(C27,'[1]青岛4 (2)'!$C:$D,2,0) -> #N/A | B27: DIPL02 | C27: 10880033487 | D27: 110001283801 | E27: 110001283801 | F27: 500323-C24F6A-PC 0041801140 | G27: 600 | H27: 300 | I27: =VLOOKUP(C27,'[2]IE model 海尔产品'!$A$1:$D$65536,4,0) -> 1*3 | J27: {=INDEX($A$2:$AF$2,MIN(IF(M27:AF27<>0,COLUMN(M27:AF27))))} -> 46142 | K27: =VLOOKUP(C27,'[2]IE model 海尔产品'!$A$1:$H$65536,8,0) -> 360 | L27: =VLOOKUP(C27,'[2]IE model 海尔产品'!$A$1:$I$65536,9,0) -> 36 | M27: 300 | AG27: =SUM(M27:AF27) -> 300 | AH27: =+H27-AG27 -> 0 | AI27: 30号入库，可放节后 | AM27: =_xlfn.XLOOKUP(C27,'[4]4-30'!$F:$F,'[4]4-30'!$S:$S) -> #N/A
A28: =VLOOKUP(C28,'[1]青岛4 (2)'!$C:$D,2,0) -> #N/A | B28: DIPL02 | C28: 10880033329 | D28: 110001296370 | E28: 110001296370 | F28: 500323-C24A9A-PC 0011801490S | G28: 5000 | H28: 5000 | I28: =VLOOKUP(C28,'[2]IE model 海尔产品'!$A$1:$D$65536,4,0) -> 1*2 | J28: {=INDEX($A$2:$AF$2,MIN(IF(M28:AF28<>0,COLUMN(M28:AF28))))} -> 46142 | K28: =VLOOKUP(C28,'[2]IE model 海尔产品'!$A$1:$H$65536,8,0) -> 350 | L28: =VLOOKUP(C28,'[2]IE model 海尔产品'!$A$1:$I$65536,9,0) -> 33 | M28: 2500 | O28: 2500 | AG28: =SUM(M28:AF28) -> 5000 | AH28: =+H28-AG28 -> 0 | AI28: =VLOOKUP(E28,[6]Data!$D:$H,5,0) -> 46142 | AM28: =_xlfn.XLOOKUP(C28,'[4]4-30'!$F:$F,'[4]4-30'!$S:$S) -> #N/A
A29: =VLOOKUP(C29,'[1]青岛4 (2)'!$C:$D,2,0) -> #N/A | B29: DIPL02 | C29: 10880037377 | D29: 110001299917 | E29: 110001299917 | F29: 600766-A2504A-PC G0044 0011801490M | G29: 5800 | H29: 5800 | I29: =VLOOKUP(C29,'[2]IE model 海尔产品'!$A$1:$D$65536,4,0) -> 1*2 | J29: {=INDEX($A$2:$AF$2,MIN(IF(M29:AF29<>0,COLUMN(M29:AF29))))} -> 46146 | K29: =VLOOKUP(C29,'[2]IE model 海尔产品'!$A$1:$H$65536,8,0) -> 350 | L29: =VLOOKUP(C29,'[2]IE model 海尔产品'!$A$1:$I$65536,9,0) -> 33 | O29: 1600 | Q29: 4200 | AG29: =SUM(M29:AF29) -> 5800 | AH29: =+H29-AG29 -> 0 | AI29: =VLOOKUP(E29,[6]Data!$D:$H,5,0) -> 46148 | AM29: =_xlfn.XLOOKUP(C29,'[4]4-30'!$F:$F,'[4]4-30'!$S:$S) -> #N/A
A30: DIPL02 | B30: DIPL02 | C30: 10880033585 | D30: 110001311379 | E30: 110001311379 | F30: 500323-B24A6H-PC 0011801490Y | G30: 1000 | H30: 1000 | I30: =VLOOKUP(C30,'[2]IE model 海尔产品'!$A$1:$D$65536,4,0) -> 1*2 | J30: {=INDEX($A$2:$AF$2,MIN(IF(M30:AF30<>0,COLUMN(M30:AF30))))} -> 46148 | K30: =VLOOKUP(C30,'[2]IE model 海尔产品'!$A$1:$H$65536,8,0) -> 350 | L30: =VLOOKUP(C30,'[2]IE model 海尔产品'!$A$1:$I$65536,9,0) -> 33 | S30: 1000 | AG30: =SUM(M30:AF30) -> 1000 | AH30: =+H30-AG30 -> 0 | AI30: =VLOOKUP(E30,[6]Data!$D:$H,5,0) -> 46148 | AM30: =_xlfn.XLOOKUP(C30,'[4]4-30'!$F:$F,'[4]4-30'!$S:$S) -> #N/A
A31: DIPL02 | B31: DIPL02 | C31: 10880036434 | D31: 110001296286 | E31: 110001296286 | F31: 693-C2576B-PC G0044 0011801490BS | G31: 200 | H31: 200 | I31: =VLOOKUP(C31,'[2]IE model 海尔产品'!$A$1:$D$65536,4,0) -> #N/A | J31: {=INDEX($A$2:$AF$2,MIN(IF(M31:AF31<>0,COLUMN(M31:AF31))))} -> 46148 | K31: 350 | L31: =VLOOKUP(C31,'[2]IE model 海尔产品'!$A$1:$I$65536,9,0) -> #N/A | S31: 200 | AG31: =SUM(M31:AF31) -> 200 | AH31: =+H31-AG31 -> 0 | AI31: 46148 | AM31: =_xlfn.XLOOKUP(C31,'[4]4-30'!$F:$F,'[4]4-30'!$S:$S) -> 在制200--5/6入库
A32: DIPL02 | B32: DIPL02 | C32: 10880030608 | D32: 110001299839 | E32: 110001299839 | F32: 693-B23G7B-PC 0011801048AF | G32: 200 | H32: 200 | I32: =VLOOKUP(C32,'[2]IE model 海尔产品'!$A$1:$D$65536,4,0) -> 1*1 | J32: {=INDEX($A$2:$AF$2,MIN(IF(M32:AF32<>0,COLUMN(M32:AF32))))} -> 46148 | K32: =VLOOKUP(C32,'[2]IE model 海尔产品'!$A$1:$H$65536,8,0) -> 300 | L32: =VLOOKUP(C32,'[2]IE model 海尔产品'!$A$1:$I$65536,9,0) -> 38 | S32: 200 | AG32: =SUM(M32:AF32) -> 200 | AH32: =+H32-AG32 -> 0 | AI32: 46148 | AM32: =_xlfn.XLOOKUP(C32,'[4]4-30'!$F:$F,'[4]4-30'!$S:$S) -> 在制200--5/6入库
A33: DIPL02 | B33: DIPL02 | C33: 10880030977 | D33: 110001308387 | E33: 110001308387 | F33: 693-C23I2A-PC 0011801657 | G33: 200 | H33: 200 | I33: =VLOOKUP(C33,'[2]IE model 海尔产品'!$A$1:$D$65536,4,0) -> 1*2 | J33: {=INDEX($A$2:$AF$2,MIN(IF(M33:AF33<>0,COLUMN(M33:AF33))))} -> 46150 | K33: =VLOOKUP(C33,'[2]IE model 海尔产品'!$A$1:$H$65536,8,0) -> 60 | L33: =VLOOKUP(C33,'[2]IE model 海尔产品'!$A$1:$I$65536,9,0) -> 26 | W33: 200 | AG33: =SUM(M33:AF33) -> 200 | AH33: =+H33-AG33 -> 0 | AI33: 46153 | AM33: =_xlfn.XLOOKUP(C33,'[4]4-30'!$F:$F,'[4]4-30'!$S:$S) -> 在制200--5/11入库
A34: DIPL02 | B34: DIPL02 | C34: 10880030784 | D34: 110001288315 | E34: 110001288315 | F34: 693-C23I1A-PC 0011801652A | G34: 200 | H34: 200 | I34: =VLOOKUP(C34,'[2]IE model 海尔产品'!$A$1:$D$65536,4,0) -> 1*2 | J34: {=INDEX($A$2:$AF$2,MIN(IF(M34:AF34<>0,COLUMN(M34:AF34))))} -> 46150 | K34: =VLOOKUP(C34,'[2]IE model 海尔产品'!$A$1:$H$65536,8,0) -> 430 | L34: =VLOOKUP(C34,'[2]IE model 海尔产品'!$A$1:$I$65536,9,0) -> 30 | W34: 200 | AG34: =SUM(M34:AF34) -> 200 | AH34: =+H34-AG34 -> 0 | AI34: 46153 | AM34: =_xlfn.XLOOKUP(C34,'[4]4-30'!$F:$F,'[4]4-30'!$S:$S) -> 在制200--5/11入库
A35: DIPL02 | B35: DIPL02 | C35: 10880029957 | D35: 110001299831 | E35: 110001299831 | F35: 1323-C2306A-PC 0011801652 | G35: 2000 | H35: 2000 | I35: =VLOOKUP(C35,'[2]IE model 海尔产品'!$A$1:$D$65536,4,0) -> 1*2 | J35: {=INDEX($A$2:$AF$2,MIN(IF(M35:AF35<>0,COLUMN(M35:AF35))))} -> 46150 | K35: =VLOOKUP(C35,'[2]IE model 海尔产品'!$A$1:$H$65536,8,0) -> 430 | L35: =VLOOKUP(C35,'[2]IE model 海尔产品'!$A$1:$I$65536,9,0) -> 30 | W35: 1500 | Y35: 500 | AG35: =SUM(M35:AF35) -> 2000 | AH35: =+H35-AG35 -> 0 | AI35: 46153 | AM35: =_xlfn.XLOOKUP(C35,'[4]4-30'!$F:$F,'[4]4-30'!$S:$S) -> 在制2000--5/11入库
A36: DIPL02 | B36: DIPL02 | C36: 10880038446 | D36: 110001311099 | E36: 110001311099 | F36: 693-C2608B-PC G0044 0011801656D | G36: 250 | H36: 250 | I36: =VLOOKUP(C36,'[2]IE model 海尔产品'!$A$1:$D$65536,4,0) -> 1*2 | J36: {=INDEX($A$2:$AF$2,MIN(IF(M36:AF36<>0,COLUMN(M36:AF36))))} -> #VALUE! | K36: =VLOOKUP(C36,'[2]IE model 海尔产品'!$A$1:$H$65536,8,0) -> 300 | L36: =VLOOKUP(C36,'[2]IE model 海尔产品'!$A$1:$I$65536,9,0) -> 37 | AG36: =SUM(M36:AF36) -> 0 | AH36: =+H36-AG36 -> 250 | AI36: 46153 | AM36: =_xlfn.XLOOKUP(C36,'[4]4-30'!$F:$F,'[4]4-30'!$S:$S) -> 0
A37: DIPL02 | B37: DIPL02 | C37: 10880038782 | D37: 110001307361 | E37: 110001307361 | F37: 500323-C2491D-PC G0044 0011801656B | G37: 650 | H37: 650 | I37: =VLOOKUP(C37,'[2]IE model 海尔产品'!$A$1:$D$65536,4,0) -> 1*2 | J37: {=INDEX($A$2:$AF$2,MIN(IF(M37:AF37<>0,COLUMN(M37:AF37))))} -> #VALUE! | K37: =VLOOKUP(C37,'[2]IE model 海尔产品'!$A$1:$H$65536,8,0) -> 300 | L37: =VLOOKUP(C37,'[2]IE model 海尔产品'!$A$1:$I$65536,9,0) -> 37 | AG37: =SUM(M37:AF37) -> 0 | AH37: =+H37-AG37 -> 650 | AI37: 46153 | AM37: =_xlfn.XLOOKUP(C37,'[4]4-30'!$F:$F,'[4]4-30'!$S:$S) -> 0
A38: =VLOOKUP(C38,'[1]青岛4 (2)'!$C:$D,2,0) -> #N/A | B38: 海尔DIPL02，拉长张玲丽 | M38: =SUM(M27:M37) -> 2800 | N38: =SUM(N27:N37) -> 0 | O38: =SUM(O27:O37) -> 4100 | P38: =SUM(P27:P37) -> 0 | Q38: =SUM(Q27:Q37) -> 4200 | R38: =SUM(R27:R37) -> 0 | S38: =SUM(S27:S37) -> 1400 | T38: =SUM(T27:T37) -> 0 | ... AF38: =SUM(AF27:AF37) -> 0 | AJ38: =VLOOKUP(E38,[5]Data!$D:$D,1,0) -> #N/A | AK38: =VLOOKUP(AJ38,[5]Data!$D:$I,6,0) -> #N/A | AM38: =_xlfn.XLOOKUP(C38,'[4]4-30'!$F:$F,'[4]4-30'!$S:$S) -> 备注
A39: =VLOOKUP(C39,'[1]青岛4 (2)'!$C:$D,2,0) -> #N/A | B39: DIPL03 | C39: 10880030334 | D39: 110001285756 | E39: 110001285756 | F39: 693-C23B7A-PC 0151800228CA | G39: 1016 | H39: 1016 | I39: =VLOOKUP(C39,'[2]IE model 海尔产品'!$A$1:$D$65536,4,0) -> 1*2 | J39: {=INDEX($A$2:$AF$2,MIN(IF(M39:AF39<>0,COLUMN(M39:AF39))))} -> 46142 | K39: =VLOOKUP(C39,'[2]IE model 海尔产品'!$A$1:$H$65536,8,0) -> 260 | L39: =VLOOKUP(C39,'[2]IE model 海尔产品'!$A$1:$I$65536,9,0) -> 41 | M39: 1016 | AG39: =SUM(M39:AF39) -> 1016 | AH39: =+H39-AG39 -> 0 | AI39: 备库 | AM39: =_xlfn.XLOOKUP(C39,'[4]4-30'!$F:$F,'[4]4-30'!$S:$S) -> #N/A
A40: =VLOOKUP(C40,'[1]青岛4 (2)'!$C:$D,2,0) -> #N/A | B40: DIPL03 | C40: 10880020640 | D40: 110001308381 | E40: 110001308381 | F40: 693-B2201M-PC 0011801424Z | G40: 1200 | H40: 1200 | I40: =VLOOKUP(C40,'[2]IE model 海尔产品'!$A$1:$D$65536,4,0) -> 1*2 | J40: {=INDEX($A$2:$AF$2,MIN(IF(M40:AF40<>0,COLUMN(M40:AF40))))} -> 46142 | K40: =VLOOKUP(C40,'[2]IE model 海尔产品'!$A$1:$H$65536,8,0) -> 330 | L40: =VLOOKUP(C40,'[2]IE model 海尔产品'!$A$1:$I$65536,9,0) -> 35 | M40: 1200 | AG40: =SUM(M40:AF40) -> 1200 | AH40: =+H40-AG40 -> 0 | AI40: 46150 | AM40: =_xlfn.XLOOKUP(C40,'[4]4-30'!$F:$F,'[4]4-30'!$S:$S) -> 在制1200--5/8入库
...

Sheet 配料明细
A1: 下达日期 | B1: 完成插件 | C1: 物料编码 | D1: 整机工单 | E1: 订单 | F1: 物料描述 | G1: 数量 | H1: 上线 | I1: 配料日期 | J1: 备注
A2: 46129 | B2: =VLOOKUP(C2,[7]完成订单!$D:$D,1,0) -> 10880036366 | C2: 10880036366 | D2: 110001288423 | E2: 110001288423 | F2: 2189-B2505C G0020 2504029 | G2: 552 | H2: 46132 | I2: =A2 -> 46129 | J2: =VLOOKUP(D2,#REF!,4,0) -> #REF!
A3: 46129 | B3: =VLOOKUP(C3,[7]完成订单!$D:$D,1,0) -> 10400030958 | C3: 10400030958 | D3: 110001288423 | E3: 110001288424 | F3: 2189-B2505C-D 2504029 | G3: 552 | H3: 46132 | I3: =A3 -> 46129 | J3: =VLOOKUP(D3,#REF!,4,0) -> #REF!
A4: 46129 | B4: =VLOOKUP(C4,[7]完成订单!$D:$D,1,0) -> 10400033234 | C4: 10400033234 | D4: 110001288423 | E4: 110001288425 | F4: 2189-B2505A-KN 2489739 | G4: 552 | H4: 46131 | I4: =A4 -> 46129 | J4: =VLOOKUP(D4,#REF!,4,0) -> #REF!
A5: 46129 | B5: =VLOOKUP(C5,[7]完成订单!$D:$D,1,0) -> #N/A | C5: 10400030959 | D5: 110001288423 | E5: 110001288426 | F5: 2189-B2505C-D 2504029 | G5: 552 | H5: 46129 | I5: =A5 -> 46129 | J5: =VLOOKUP(D5,#REF!,4,0) -> #REF!
A6: 46129 | B6: =VLOOKUP(C6,[7]完成订单!$D:$D,1,0) -> 10880036058 | C6: 10880036058 | D6: 110001290288 | E6: 110001290288 | F6: 2189-B2505A G0020 2489739 | G6: 798 | H6: 46132 | I6: =A6 -> 46129 | J6: =VLOOKUP(D6,#REF!,4,0) -> #REF!
A7: 46129 | B7: =VLOOKUP(C7,[7]完成订单!$D:$D,1,0) -> 10400030543 | C7: 10400030543 | D7: 110001290288 | E7: 110001290289 | F7: 2189-B2505A-D 2489739 | G7: 798 | H7: 46132 | I7: =A7 -> 46129 | J7: =VLOOKUP(D7,#REF!,4,0) -> #REF!
A8: 46129 | B8: =VLOOKUP(C8,[7]完成订单!$D:$D,1,0) -> 10400033234 | C8: 10400033234 | D8: 110001290288 | E8: 110001290290 | F8: 2189-B2505A-KN 2489739 | G8: 798 | H8: 46131 | I8: =A8 -> 46129 | J8: =VLOOKUP(D8,#REF!,4,0) -> #REF!
A9: 46129 | B9: =VLOOKUP(C9,[7]完成订单!$D:$D,1,0) -> #N/A | C9: 10400030539 | D9: 110001290288 | E9: 110001290291 | F9: 2189-B2505A-D 2489739 | G9: 798 | H9: 46129 | I9: =A9 -> 46129 | J9: =VLOOKUP(D9,#REF!,4,0) -> #REF!
A10: 46129 | B10: =VLOOKUP(C10,[7]完成订单!$D:$D,1,0) -> 10880037659 | C10: 10880037659 | D10: 110001290362 | E10: 110001290362 | F10: 2189-B2505L G0020 20159285 | G10: 1398 | H10: 46132 | I10: =A10 -> 46129 | J10: =VLOOKUP(D10,#REF!,4,0) -> #REF!
A11: 46129 | B11: =VLOOKUP(C11,[7]完成订单!$D:$D,1,0) -> 10400032699 | C11: 10400032699 | D11: 110001290362 | E11: 110001290363 | F11: 2189-B2505L-D 20159285 | G11: 1398 | H11: 46132 | I11: =A11 -> 46129 | J11: =VLOOKUP(D11,#REF!,4,0) -> #REF!
A12: 46129 | B12: =VLOOKUP(C12,[7]完成订单!$D:$D,1,0) -> 10400033234 | C12: 10400033234 | D12: 110001290362 | E12: 110001290364 | F12: 2189-B2505A-KN 2489739 | G12: 1398 | H12: 46131 | I12: =A12 -> 46129 | J12: =VLOOKUP(D12,#REF!,4,0) -> #REF!
A13: 46129 | B13: =VLOOKUP(C13,[7]完成订单!$D:$D,1,0) -> #N/A | C13: 10400032700 | D13: 110001290362 | E13: 110001290365 | F13: 2189-B2505L-D 20159285 | G13: 1398 | H13: 46129 | I13: =A13 -> 46129 | J13: =VLOOKUP(D13,#REF!,4,0) -> #REF!
... A111: 46129 | B111: =VLOOKUP(C111,[7]完成订单!$D:$D,1,0) -> #N/A | C111: 10400031424 | D111: 110001308405 | E111: 110001308406 | F111: 693-C24Q3E-PC 0011801977G | G111: 600 | H111: 46131 | I111: =A111 -> 46129 | J111: =VLOOKUP(D111,#REF!,4,0) -> #REF!
A112: 46130 | B112: =VLOOKUP(C112,[7]完成订单!$D:$D,1,0) -> 10880032942 | C112: 10880032942 | D112: 110001267235 | E112: 110001267235 | F112: 2189-B2401F-PC 2397248 | G112: 680 | H112: 46135 | I112: 46130 | J112: =VLOOKUP(D112,#REF!,4,0) -> #REF!
A113: 46130 | B113: =VLOOKUP(C113,[7]完成订单!$D:$D,1,0) -> #N/A | C113: 10400026579 | D113: 110001267235 | E113: 110001267236 | F113: 贴片部件 2189-B2401F-PC 2397248 | G113: 680 | H113: 46133 | I113: 46130 | J113: =VLOOKUP(D113,#REF!,4,0) -> #REF!
A114: 46130 | B114: =VLOOKUP(C114,[7]完成订单!$D:$D,1,0) -> 10880036432 | C114: 10880036432 | D114: 110001271444 | E114: 110001271444 | F114: 693-B2548A-PC G0044 0011801922 | G114: 4000 | H114: 46131 | I114: 46130 | J114: =VLOOKUP(D114,#REF!,4,0) -> #REF!
A115: 46130 | B115: =VLOOKUP(C115,[7]完成订单!$D:$D,1,0) -> #N/A | C115: 10400031033 | D115: 110001271444 | E115: 110001271445 | F115: 693-B2548A-PC 0011801922 | G115: 4000 | H115: 46129 | I115: 46130 | J115: =VLOOKUP(D115,#REF!,4,0) -> #REF!
A116: 46130 | B116: =VLOOKUP(C116,[7]完成订单!$D:$D,1,0) -> 10880020048 | C116: 10880020048 | D116: 110001288251 | E116: 110001288251 | F116: 693-C2203A-PC 0011801327 | G116: 1100 | H116: 46134 | I116: 46130 | J116: =VLOOKUP(D116,#REF!,4,0) -> #REF!
A117: 46130 | B117: =VLOOKUP(C117,[7]完成订单!$D:$D,1,0) -> #N/A | C117: 10400019509 | D117: 110001288251 | E117: 110001288252 | F117: 693-C2203A-PC 0011801327 | G117: 1100 | H117: 46132 | I117: 46130 | J117: =VLOOKUP(D117,#REF!,4,0) -> #REF!
A118: 46130 | B118: =VLOOKUP(C118,[7]完成订单!$D:$D,1,0) -> 10880032943 | C118: 10880032943 | D118: 110001288341 | E118: 110001288341 | F118: 2189-B2401D-PC 2397172 | G118: 500 | H118: 46135 | I118: 46130 | J118: =VLOOKUP(D118,#REF!,4,0) -> #REF!
A119: 46130 | B119: =VLOOKUP(C119,[7]完成订单!$D:$D,1,0) -> #N/A | C119: 10400026577 | D119: 110001288341 | E119: 110001288342 | F119: 贴片部件 2189-B2401D-PC 2397172 | G119: 500 | H119: 46133 | I119: 46130 | J119: =VLOOKUP(D119,#REF!,4,0) -> #REF!
A120: 46130 | B120: =VLOOKUP(C120,[7]完成订单!$D:$D,1,0) -> 10880035984 | C120: 10880035984 | D120: 110001288413 | E120: 110001288413 | F120: 500493-B2407C-D G0020 2488431 | G120: 1500 | H120: 46135 | I120: 46130 | J120: =VLOOKUP(D120,#REF!,4,0) -> #REF!
A121: 46130 | B121: =VLOOKUP(C121,[7]完成订单!$D:$D,1,0) -> #N/A | C121: 10400030451 | D121: 110001288413 | E121: 110001288414 | F121: 500493-B2407C-D 2488431 | G121: 1500 | H121: 46133 | I121: 46130 | J121: =VLOOKUP(D121,#REF!,4,0) -> #REF!
A122: 46130 | B122: =VLOOKUP(C122,[7]完成订单!$D:$D,1,0) -> 10880036423 | C122: 10880036423 | D122: 110001288431 | E122: 110001288431 | F122: 693-C2532B-PC G0044 0011802020A | G122: 1500 | H122: 46133 | I122: 46130 | J122: =VLOOKUP(D122,#REF!,4,0) -> #REF!
A123: 46130 | B123: =VLOOKUP(C123,[7]完成订单!$D:$D,1,0) -> #N/A | C123: 10400031020 | D123: 110001288431 | E123: 110001288432 | F123: 693-C2532B-PC 0011802020A | G123: 1500 | H123: 46131 | I123: 46130 | J123: =VLOOKUP(D123,#REF!,4,0) -> #REF!
... A153: 46131 | B153: =VLOOKUP(C153,[7]完成订单!$D:$D,1,0) -> #N/A | C153: 10400027588 | D153: 110001303404 | E153: 110001303405 | F153: 500323-C24D2B-D 0021800616C | G153: 2000 | H153: 46132 | I153: 46131 | J153: =VLOOKUP(D153,#REF!,4,0) -> #REF!
A154: 46132 | B154: =VLOOKUP(C154,[7]完成订单!$D:$D,1,0) -> 10880037377 | C154: 10880037377 | D154: 110001279039 | E154: 110001279039 | F154: 600766-A2504A-PC G0044 0011801490M | G154: 7500 | H154: 46136 | I154: 46132 | J154: 7500 | K154: =+J154-G154 -> 0
A155: 46132 | B155: =VLOOKUP(C155,[7]完成订单!$D:$D,1,0) -> #N/A | C155: 10400032318 | D155: 110001279039 | E155: 110001279044 | F155: 600766-A2504A-PC 0011801490M | G155: 7500 | H155: 46134 | I155: 46132 | J155: 7500 | K155: =+J155-G155 -> 0
A156: 46132 | B156: =VLOOKUP(C156,[7]完成订单!$D:$D,1,0) -> 10880037369 | C156: 10880037369 | D156: 110001288509 | E156: 110001288509 | F156: 600766-A2506B-PC G0044 0011800977JHR | G156: 5000 | H156: 46132 | I156: 46132 | J156: 5000 | K156: =+J156-G156 -> 0
A157: 46132 | B157: =VLOOKUP(C157,[7]完成订单!$D:$D,1,0) -> #N/A | C157: 10400032312 | D157: 110001288509 | E157: 110001288510 | F157: 600766-A2506B-PC 0011800977JHR | G157: 5000 | H157: 46130 | I157: 46132 | J157: 5000 | K157: =+J157-G157 -> 0
A158: 46132 | B158: =VLOOKUP(C158,[7]完成订单!$D:$D,1,0) -> 10880037369 | C158: 10880037369 | D158: 110001297727 | E158: 110001297727 | F158: 600766-A2506B-PC G0044 0011800977JHR | G158: 10000 | H158: 46132 | I158: 46132 | J158: 10000 | K158: =+J158-G158 -> 0
A159: 46132 | B159: =VLOOKUP(C159,[7]完成订单!$D:$D,1,0) -> #N/A | C159: 10400032312 | D159: 110001297727 | E159: 110001297728 | F159: 600766-A2506B-PC 0011800977JHR | G159: 10000 | H159: 46130 | I159: 46132 | J159: 10000 | K159: =+J159-G159 -> 0
A160: 46132 | B160: =VLOOKUP(C160,[7]完成订单!$D:$D,1,0) -> 10880037368 | C160: 10880037368 | D160: 110001299911 | E160: 110001299911 | F160: 600766-A2506A-PC G0044 0011800977HHR | G160: 11550 | H160: 46132 | I160: 46132 | J160: 11550 | K160: =+J160-G160 -> 0
A161: 46132 | B161: =VLOOKUP(C161,[7]完成订单!$D:$D,1,0) -> #N/A | C161: 10400032311 | D161: 110001299911 | E161: 110001299912 | F161: 600766-A2506A-PC 0011800977HHR | G161: 11550 | H161: 46130 | I161: 46132 | J161: 11550 | K161: =+J161-G161 -> 0
A162: 46132 | B162: =VLOOKUP(C162,[7]完成订单!$D:$D,1,0) -> 10880033535 | C162: 10880033535 | D162: 110001271653 | E162: 110001271653 | F162: 500493-B2402E-D 2418237 | G162: 3000 | H162: 46135 | I162: 46132 | J162: 3000 | K162: =+J162-G162 -> 0
A163: 46132 | B163: =VLOOKUP(C163,[7]完成订单!$D:$D,1,0) -> #N/A | C163: 10400027323 | D163: 110001271653 | E163: 110001271654 | F163: 500493-B2402E-D 2418237 | G163: 3000 | H163: 46133 | I163: 46132 | J163: 3000 | K163: =+J163-G163 -> 0
A164: 46132 | B164: =VLOOKUP(C164,[7]完成订单!$D:$D,1,0) -> 10880037671 | C164: 10880037671 | D164: 110001271829 | E164: 110001271829 | F164: 693-B25D2B-PC G0044 0011801330AK | G164: 1000 | H164: 46134 | I164: 46132 | J164: 1000 | K164: =+J164-G164 -> 0
A165: 46132 | B165: =VLOOKUP(C165,[7]完成订单!$D:$D,1,0) -> #N/A | C165: 10400032721 | D165: 110001271829 | E165: 110001271830 | F165: 693-B25D2B-PC 0011801330AK | G165: 1000 | H165: 46132 | I165: 46132 | J165: 1000 | K165: =+J165-G165 -> 0
... A185: 46132 | B185: =VLOOKUP(C185,[7]完成订单!$D:$D,1,0) -> #N/A | C185: 10400024768 | D185: 110001296254 | E185: 110001296255 | F185: 693-C23I3A-PC 0011801656 | G185: 2000 | H185: 46132 | I185: 46132 | J185: 2000 | K185: =+J185-G185 -> 0
...

Sheet 返工工单
A1: 线体 | B1: 销售订单 | C1: 物料 | D1: 订单 | E1: 物料描述 | F1: 工单数量 | G1: 下达时间 | H1: 完工日期 | I1: 返工原因 | J1: 责任归属 | K1: 备注
A2: DIP03 | B2: 30007090 | C2: 10880018097 | D2: 990000024386 | E2: 693-B2201B-PC 0011801424B | F2: 2386 | G2: 44856 | I2: PM通知693-B2201A-PC成品库存从胶州代理处发回青岛2650套，再加合肥的2561套，工厂库存969，全部改制成693-B2201B-PC. | J2: 青岛事业部
A3: DIP03 | B3: 30007091 | C3: 10880018097 | D3: 990000024387 | E3: 693-B2201B-PC 0011801424B | F3: 264 | G3: 44856 | I3: PM通知693-B2201A-PC成品库存从胶州代理处发回青岛2650套，再加合肥的2561套，工厂库存969，全部改制成693-B2201B-PC. | J3: 青岛事业部
A4: DIP03 | B4: 30007093 | C4: 10880018097 | D4: 990000024388 | E4: 693-B2201B-PC 0011801424B | F4: 2231 | G4: 44856 | I4: PM通知693-B2201A-PC成品库存从胶州代理处发回青岛2650套，再加合肥的2561套，工厂库存969，全部改制成693-B2201B-PC. | J4: 青岛事业部
A5: DIP03 | B5: 30007101 | C5: 10880018097 | D5: 990000024480 | E5: 693-B2201B-PC 0011801424B | F5: 969 | G5: 44858 | I5: PM通知693-B2201A-PC成品库存从胶州代理处发回青岛2650套，再加合肥的2561套，工厂库存969，全部改制成693-B2201B-PC. | J5: 青岛事业部
A6: DIP03 | B6: 1204808 | C6: 10880017536 | D6: 990000024584 | E6: 693-A2180G-PC 0011800646L | F6: 14 | G6: 44865 | I6: 针对客户端反馈2180G存在停电补偿失效（自锁）异常，近期出货的返工，通过同研发与测试商讨，产品重新烧录程序。QE提供数量：6962 PCS. | J6: 青岛事业部
A7: DIP03 | B7: 1204809 | C7: 10880017536 | D7: 990000024585 | E7: 693-A2180G-PC 0011800646L | F7: 200 | G7: 44865 | I7: 针对客户端反馈2180G存在停电补偿失效（自锁）异常，近期出货的返工，通过同研发与测试商讨，产品重新烧录程序。QE提供数量：6962 PCS. | J7: 青岛事业部
A8: DIP03 | B8: 1211747 | C8: 10880017536 | D8: 990000024586 | E8: 693-A2180G-PC 0011800646L | F8: 1174 | G8: 44865 | I8: 针对客户端反馈2180G存在停电补偿失效（自锁）异常，近期出货的返工，通过同研发与测试商讨，产品重新烧录程序。QE提供数量：6962 PCS. | J8: 青岛事业部
A9: DIP03 | B9: 1219155 | C9: 10880017536 | D9: 990000024587 | E9: 693-A2180G-PC 0011800646L | F9: 989 | G9: 44865 | I9: 针对客户端反馈2180G存在停电补偿失效（自锁）异常，近期出货的返工，通过同研发与测试商讨，产品重新烧录程序。QE提供数量：6962 PCS. | J9: 青岛事业部
A10: DIP03 | B10: 1217877 | C10: 10880017532 | D10: 990000024588 | E10: 693-A2180C-PC 0011800646F | F10: 997 | G10: 44865 | I10: 针对客户端反馈2180C存在停电补偿失效（自锁）异常，近期出货的返工，通过同研发与测试商讨，产品重新烧录程序。QE提供数量：6962 PCS. | J10: 青岛事业部
A11: DIP03 | B11: 1217874 | C11: 10880017530 | D11: 990000024621 | E11: 693-A2180A-PC 0011800646A | F11: 1920 | G11: 44868 | I11: 针对客户端反馈2180C存在停电补偿失效（自锁）异常，近期出货的返工，通过同研发与测试商讨，产品重新烧录程序。QE提供数量：6962 PCS. | J11: 青岛事业部
A12: DIP03 | B12: 1217875 | C12: 10880017530 | D12: 990000024622 | E12: 693-A2180A-PC 0011800646A | F12: 2880 | G12: 44868 | I12: 针对客户端反馈2180C存在停电补偿失效（自锁）异常，近期出货的返工，通过同研发与测试商讨，产品重新烧录程序。QE提供数量：6962 PCS. | J12: 青岛事业部
A13: DIP03 | B13: 1217880 | C13: 10880017533 | D13: 990000024620 | E13: 693-A2180D-PC 0011800646M | F13: 5979 | G13: 44868 | I13: 针对客户端反馈2180C存在停电补偿失效（自锁）异常，近期出货的返工，通过同研发与测试商讨，产品重新烧录程序。QE提供数量：6962 PCS. | J13: 青岛事业部
... A22: DIP03 | B22: 1223070 | C22: 10880020230 | D22: 990000025063 | E22: 201-A2247A-PC PV023平台 1120129 | F22: 100 | G22: 44887 | I22: 201-A2247A-PC J1跳线打错位置（错打JP1），QE提供数量：100PCS. | J22: 青岛工厂
A23: DIP03 | B23: 1217956 | C23: 10880017535 | D23: 990000024190 | E23: 693-A2180F-PC 0011800646C | F23: 402 | G23: 44887 | H23: 44887 | I23: 研发建错BOM，需返插座 | J23: 研发
A24: DIP02 | B24: 1224353 | C24: 10880018850 | D24: 990000024999 | E24: 693-A2178I-PC 0011800612V | F24: 160 | G24: 44887 | H24: 44887 | I24: 612V（2178I）针座CN7存在错料不良，PCBA需返工处理，数量：4200PCS. | J24: 青岛工厂
A25: DIP02 | B25: 1224363 | C25: 10880018850 | D25: 990000025000 | E25: 693-A2178I-PC 0011800612V | F25: 683 | G25: 44887 | H25: 44887 | I25: 612V（2178I）针座CN7存在错料不良，PCBA需返工处理，数量：4200PCS. | J25: 青岛工厂
A26: DIP03 | B26: 1220657 | C26: 10880017949 | D26: 990000025128 | E26: 693-A2181B-PC 0011800537C | F26: 2000 | G26: 44891 | H26: 44891 | I26: 693-A2181B-PC 连锡半焊不良检查，QE提供数量：11760 PCS. | J26: 青岛工厂
A27: DIP03 | B27: 1220658 | C27: 10880017949 | D27: 990000025129 | E27: 693-A2181B-PC 0011800537C | F27: 1683 | G27: 44891 | H27: 44891 | I27: 693-A2181B-PC 连锡半焊不良检查，QE提供数量：11760 PCS. | J27: 青岛工厂
A28: DIP03 | B28: 1219153 | C28: 10880017526 | D28: 990000025145 | E28: 693-A2179D-PC 0011800630P | F28: 2985 | G28: 44891 | H28: 44891 | I28: 693-A2179D-PC研发BOM建错，C26风机电容要求2uf，BOM错误成1.2uf，返工更换风机电容。 | J28: 研发
A29: DIP03 | B29: 1217967 | C29: 10880017526 | D29: 990000025182 | E29: 693-A2179D-PC 0011800630P | F29: 1056 | G29: 44891 | H29: 44891 | I29: 693-A2179D-PC研发BOM建错，C26风机电容要求2uf，BOM错误成1.2uf，返工更换风机电容。 | J29: 研发
A30: DIP03 | B30: 30007266 | C30: 10880017536 | D30: 990000025311 | E30: 693-A2180G-PC 0011800646L | F30: 320 | G30: 44901 | I30: 为满足交付需求，今天用646D改制成646L 320PCS出货，需返工；返工数量：320pcs （需重新烧录EE程序） | J30: 青岛事业部
A31: DIP03 | B31: 1217967 | C31: 10880017526 | D31: 990000025272 | E31: 693-A2179D-PC 0011800630P | F31: 600 | G31: 44902 | H31: 44902 | I31: 因产品用错风机电容，需返工；返工数量：600pcs | J31: 青岛工厂
A32: DIP03 | B32: 30007278 | C32: 10880017516 | D32: 990000025459 | E32: 693-A2179A-PC 0011800630K | F32: 140 | G32: 44909 | I32: 因产品用错风机电容，多返了140 | J32: 青岛工厂
A33: DIP03 | B33: 1207740 | C33: 10880019434 | D33: 990000025130 | E33: 693-B2209A-PC-0011801425N | F33: 157 | G33: 44909 | H33: 44909 | I33: 更换电阻、保险器。数量：157 PCS. | J33: 青岛工厂
A34: DIP03 | B34: 1218793 | C34: 10880020678 | D34: 990000025402 | E34: 693-A2210D-PC 0011801372C | F34: 200 | G34: 44909 | H34: 44909 | I34: 因EE程序烧录错误，需重新烧录返工；返工数量：3795pcs （需重新烧录） | J34: 青岛工厂
A35: DIP03 | B35: 1218795 | C35: 10880020678 | D35: 990000025403 | E35: 693-A2210D-PC 0011801372C | F35: 400 | G35: 44909 | H35: 44909 | I35: 因EE程序烧录错误，需重新烧录返工；返工数量：3795pcs （需重新烧录） | J35: 青岛工厂
A36: DIP03 | B36: 1218796 | C36: 10880020678 | D36: 990000025404 | E36: 693-A2210D-PC 0011801372C | F36: 1997 | G36: 44909 | H36: 44909 | I36: 因EE程序烧录错误，需重新烧录返工；返工数量：3795pcs （需重新烧录） | J36: 青岛工厂
A37: DIP03 | B37: 30007278 | C37: 10880017516 | D37: 990000025273 | E37: 693-A2179A-PC 0011800630K | F37: 316 | G37: 44911 | H37: 44911 | I37: 因产品用错风机电容，需将630P改制为630K出货，需返工；返工数量：4041pcs （需重新烧录EE程序） | J37: 青岛事业部
A38: DIP03 | B38: 30007279 | C38: 10880017516 | D38: 990000025274 | E38: 693-A2179A-PC 0011800630K | F38: 2985 | G38: 44911 | H38: 44911 | I38: 因产品用错风机电容，需将630P改制为630K出货，需返工；返工数量：4041pcs （需重新烧录EE程序） | J38: 青岛事业部
A39: DIP03 | B39: 30007317 | C39: 10880017526 | D39: 990000025547 | E39: 693-A2179D-PC 0011800630P | F39: 140 | G39: 44917 | I39: 因产品用错风机电容，多返了140 | J39: 青岛工厂
A40: DIP01 | B40: 1219950 | C40: 10880019920 | D40: 990000025661 | E40: 201-A2182D-PC 1111442 | F40: 244 | G40: 44931 | I40: 客户端反馈201-A2182D-PC在客户端出现绝缘垫片破损不良，需重新高压测试返工；返工数量：244pcs | J40: 青岛工厂
A41: DIP02 | B41: 1224490 | C41: 10880018097 | D41: 990000026292 | E41: 693-B2201B-PC 0011801424B | F41: 4771 | G41: 44993 | I41: 693-B2201B-PC 0011801424B 在线更新E程序（校验和:90E0）,贴新程序产品标贴及外箱标贴（外箱标贴须备注新程序）。数量：5000 PCS. | J41: 青岛事业部
A42: DIP03 | B42: 30007278 | C42: 10880017516 | D42: 990000026351 | E42: 693-A2179A-PC 0011800630K | F42: 316 | G42: 44999 | I42: 693-A2179D-PC研发BOM建错，C26风机电容要求2uf，BOM错误成1.2uf，现返工更换CN502插座及产品标签，烧录0011800630K程序,返工成693-A2179A-PC 0011800630K产品消化 。数量：3078 PCS. | J42: 研发
A43: DIP03 | B43: 30007279 | C43: 10880017516 | D43: 990000026352 | E43: 693-A2179A-PC 0011800630K | F43: 2981 | G43: 44999 | I43: 693-A2179D-PC研发BOM建错，C26风机电容要求2uf，BOM错误成1.2uf，现返工更换CN502插座及产品标签，烧录0011800630K程序,返工成693-A2179A-PC 0011800630K产品消化 。数量：3078 PCS. | J43: 研发
A44: DIP03 | B44: 1237318 | C44: 10880022044 | D44: 990000026450 | E44: 693-B2286A-D 0021800442G | F44: 200 | G44: 45002 | I44: 693-B2286A-D 0021800442G 更换底壳总成，更换LD33返工流程，数量200pcs | J44: 青岛事业部
A45: DIP03 | B45: 1236064 | C45: 10880019434 | D45: 990000026498 | E45: 693-B2209A-PC-0011801425N | F45: 157 | G45: 45007 | H45: 45007 | I45: 合肥生产，青岛帮忙返工，更换电阻、保险器。数量：157 PCS. | J45: 青岛事业部
A46: DIP03 | B46: 1231929 | C46: 10880021311 | D46: 990000026499 | E46: 693-C2260B-PC 0011801256L | F46: 470 | G46: 45008 | I46: 由于物料未备案，现将693-B2286B-PC 0011801256L 更换C18,R44,IC3组合物料，目检包装出货,数量470pcs | J46: 青岛事业部
A47: DIP03 | B47: 1231930 | C47: 10880021015 | D47: 990000026576 | E47: 693-B2201N-PC-0011801424AE | F47: 1200 | G47: 45012 | I47: 693-B2201N-PC-0011801424AE 更换CN5,CN6线束物料，目检包装出货,数量3954pcs | J47: 青岛事业部
A48: DIP03 | B48: 1234724 | C48: 10880018096 | D48: 990000026575 | E48: 693-B2201A-PC 0011801424A | F48: 651 | G48: 45012 | H48: 45012 | I48: 693-B2201A-PC 0011801424A 更换CN5,CN6线束物料，目检包装出货,数量875pcs | J48: 品质 | K48: 供应商返工
...
